[19:54:14] INFO     [19:54:14] INFO     [19:54:14] INFO     [19:54:14] INFO     --- Logging error ---
Traceback (most recent call last):
  File "C:\Users\DELL\AppData\Roaming\Python\Python38\site-packages\rich\logging.py", line 170, in emit
    self.console.print(log_renderable)
  File "C:\Users\DELL\AppData\Roaming\Python\Python38\site-packages\rich\console.py", line 1720, in print
    self._buffer.extend(new_segments)
  File "C:\Users\DELL\AppData\Roaming\Python\Python38\site-packages\rich\console.py", line 864, in __exit__
    self._exit_buffer()
  File "C:\Users\DELL\AppData\Roaming\Python\Python38\site-packages\rich\console.py", line 822, in _exit_buffer
    self._check_buffer()
  File "C:\Users\DELL\AppData\Roaming\Python\Python38\site-packages\rich\console.py", line 2027, in _check_buffer
    legacy_windows_render(buffer, LegacyWindowsTerm(self.file))
  File "C:\Users\DELL\AppData\Roaming\Python\Python38\site-packages\rich\_windows_renderer.py", line 19, in legacy_windows_render
    term.write_text(text)
  File "C:\Users\DELL\AppData\Roaming\Python\Python38\site-packages\rich\_win32_console.py", line 403, in write_text
    self.write(text)
  File "C:\Users\DELL\anaconda3\envs\myenv\lib\encodings\cp1252.py", line 19, in encode
    return codecs.charmap_encode(input,self.errors,encoding_table)[0]
UnicodeEncodeError: 'charmap' codec can't encode character '\U0001f9ff' in position 0: character maps to <undefined>
Call stack:
  File "C:\Users\DELL\anaconda3\envs\myenv\lib\runpy.py", line 194, in _run_module_as_main
    return _run_code(code, main_globals, None,
  File "C:\Users\DELL\anaconda3\envs\myenv\lib\runpy.py", line 87, in _run_code
    exec(code, run_globals)
  File "C:\Users\DELL\anaconda3\envs\myenv\Scripts\fx.exe\__main__.py", line 7, in <module>
    sys.exit(entry())
  File "C:\Users\DELL\AppData\Roaming\Python\Python38\site-packages\openfl\interface\cli.py", line 212, in entry
    cli()
  File "C:\Users\DELL\AppData\Roaming\Python\Python38\site-packages\click\core.py", line 1137, in __call__
    return self.main(*args, **kwargs)
  File "C:\Users\DELL\AppData\Roaming\Python\Python38\site-packages\click\core.py", line 1062, in main
    rv = self.invoke(ctx)
  File "C:\Users\DELL\AppData\Roaming\Python\Python38\site-packages\click\core.py", line 1668, in invoke
    return _process_result(sub_ctx.command.invoke(sub_ctx))
  File "C:\Users\DELL\AppData\Roaming\Python\Python38\site-packages\click\core.py", line 1668, in invoke
    return _process_result(sub_ctx.command.invoke(sub_ctx))
  File "C:\Users\DELL\AppData\Roaming\Python\Python38\site-packages\click\core.py", line 1404, in invoke
    return ctx.invoke(self.callback, **ctx.params)
  File "C:\Users\DELL\AppData\Roaming\Python\Python38\site-packages\click\core.py", line 763, in invoke
    return __callback(*args, **kwargs)
  File "C:\Users\DELL\AppData\Roaming\Python\Python38\site-packages\openfl\interface\director.py", line 53, in start
    logger.info('\U0001f9ff Starting the Director Service.')
  File "C:\Users\DELL\anaconda3\envs\myenv\lib\logging\__init__.py", line 1446, in info
    self._log(INFO, msg, args, **kwargs)
  File "C:\Users\DELL\anaconda3\envs\myenv\lib\logging\__init__.py", line 1589, in _log
    self.handle(record)
  File "C:\Users\DELL\anaconda3\envs\myenv\lib\logging\__init__.py", line 1599, in handle
    self.callHandlers(record)
  File "C:\Users\DELL\anaconda3\envs\myenv\lib\logging\__init__.py", line 1661, in callHandlers
    hdlr.handle(record)
  File "C:\Users\DELL\anaconda3\envs\myenv\lib\logging\__init__.py", line 954, in handle
    self.emit(record)
  File "C:\Users\DELL\AppData\Roaming\Python\Python38\site-packages\rich\logging.py", line 172, in emit
    self.handleError(record)
Message: '\U0001f9ff Starting the Director Service.'
Arguments: ()
--- Logging error ---
Traceback (most recent call last):
  File "C:\Users\DELL\AppData\Roaming\Python\Python38\site-packages\rich\logging.py", line 170, in emit
    self.console.print(log_renderable)
  File "C:\Users\DELL\AppData\Roaming\Python\Python38\site-packages\rich\console.py", line 1720, in print
    self._buffer.extend(new_segments)
  File "C:\Users\DELL\AppData\Roaming\Python\Python38\site-packages\rich\console.py", line 864, in __exit__
    self._exit_buffer()
  File "C:\Users\DELL\AppData\Roaming\Python\Python38\site-packages\rich\console.py", line 822, in _exit_buffer
    self._check_buffer()
  File "C:\Users\DELL\AppData\Roaming\Python\Python38\site-packages\rich\console.py", line 2027, in _check_buffer
    legacy_windows_render(buffer, LegacyWindowsTerm(self.file))
  File "C:\Users\DELL\AppData\Roaming\Python\Python38\site-packages\rich\_windows_renderer.py", line 19, in legacy_windows_render
    term.write_text(text)
  File "C:\Users\DELL\AppData\Roaming\Python\Python38\site-packages\rich\_win32_console.py", line 403, in write_text
    self.write(text)
  File "C:\Users\DELL\anaconda3\envs\myenv\lib\encodings\cp1252.py", line 19, in encode
    return codecs.charmap_encode(input,self.errors,encoding_table)[0]
UnicodeEncodeError: 'charmap' codec can't encode character '\U0001f9ff' in position 0: character maps to <undefined>
Call stack:
  File "C:\Users\DELL\anaconda3\envs\myenv\lib\runpy.py", line 194, in _run_module_as_main
    return _run_code(code, main_globals, None,
  File "C:\Users\DELL\anaconda3\envs\myenv\lib\runpy.py", line 87, in _run_code
    exec(code, run_globals)
  File "C:\Users\DELL\anaconda3\envs\myenv\Scripts\fx.exe\__main__.py", line 7, in <module>
    sys.exit(entry())
  File "C:\Users\DELL\AppData\Roaming\Python\Python38\site-packages\openfl\interface\cli.py", line 212, in entry
    cli()
  File "C:\Users\DELL\AppData\Roaming\Python\Python38\site-packages\click\core.py", line 1137, in __call__
    return self.main(*args, **kwargs)
  File "C:\Users\DELL\AppData\Roaming\Python\Python38\site-packages\click\core.py", line 1062, in main
    rv = self.invoke(ctx)
  File "C:\Users\DELL\AppData\Roaming\Python\Python38\site-packages\click\core.py", line 1668, in invoke
    return _process_result(sub_ctx.command.invoke(sub_ctx))
  File "C:\Users\DELL\AppData\Roaming\Python\Python38\site-packages\click\core.py", line 1668, in invoke
    return _process_result(sub_ctx.command.invoke(sub_ctx))
  File "C:\Users\DELL\AppData\Roaming\Python\Python38\site-packages\click\core.py", line 1404, in invoke
    return ctx.invoke(self.callback, **ctx.params)
  File "C:\Users\DELL\AppData\Roaming\Python\Python38\site-packages\click\core.py", line 763, in invoke
    return __callback(*args, **kwargs)
  File "C:\Users\DELL\AppData\Roaming\Python\Python38\site-packages\openfl\interface\director.py", line 77, in start
    logger.info(
  File "C:\Users\DELL\anaconda3\envs\myenv\lib\logging\__init__.py", line 1446, in info
    self._log(INFO, msg, args, **kwargs)
  File "C:\Users\DELL\anaconda3\envs\myenv\lib\logging\__init__.py", line 1589, in _log
    self.handle(record)
  File "C:\Users\DELL\anaconda3\envs\myenv\lib\logging\__init__.py", line 1599, in handle
    self.callHandlers(record)
  File "C:\Users\DELL\anaconda3\envs\myenv\lib\logging\__init__.py", line 1661, in callHandlers
    hdlr.handle(record)
  File "C:\Users\DELL\anaconda3\envs\myenv\lib\logging\__init__.py", line 954, in handle
    self.emit(record)
  File "C:\Users\DELL\AppData\Roaming\Python\Python38\site-packages\rich\logging.py", line 172, in emit
    self.handleError(record)
Message: "Sample shape: ['8'], target shape: ['2']"
Arguments: ()
--- Logging error ---
Traceback (most recent call last):
  File "C:\Users\DELL\AppData\Roaming\Python\Python38\site-packages\rich\logging.py", line 170, in emit
    self.console.print(log_renderable)
  File "C:\Users\DELL\AppData\Roaming\Python\Python38\site-packages\rich\console.py", line 1720, in print
    self._buffer.extend(new_segments)
  File "C:\Users\DELL\AppData\Roaming\Python\Python38\site-packages\rich\console.py", line 864, in __exit__
    self._exit_buffer()
  File "C:\Users\DELL\AppData\Roaming\Python\Python38\site-packages\rich\console.py", line 822, in _exit_buffer
    self._check_buffer()
[19:54:14] INFO     [19:54:14] INFO       File "C:\Users\DELL\AppData\Roaming\Python\Python38\site-packages\rich\console.py", line 2027, in _check_buffer
    legacy_windows_render(buffer, LegacyWindowsTerm(self.file))
  File "C:\Users\DELL\AppData\Roaming\Python\Python38\site-packages\rich\_windows_renderer.py", line 19, in legacy_windows_render
    term.write_text(text)
  File "C:\Users\DELL\AppData\Roaming\Python\Python38\site-packages\rich\_win32_console.py", line 403, in write_text
    self.write(text)
  File "C:\Users\DELL\anaconda3\envs\myenv\lib\encodings\cp1252.py", line 19, in encode
    return codecs.charmap_encode(input,self.errors,encoding_table)[0]
UnicodeEncodeError: 'charmap' codec can't encode character '\U0001f9ff' in position 0: character maps to <undefined>
Call stack:
  File "C:\Users\DELL\anaconda3\envs\myenv\lib\runpy.py", line 194, in _run_module_as_main
    return _run_code(code, main_globals, None,
  File "C:\Users\DELL\anaconda3\envs\myenv\lib\runpy.py", line 87, in _run_code
    exec(code, run_globals)
  File "C:\Users\DELL\anaconda3\envs\myenv\Scripts\fx.exe\__main__.py", line 7, in <module>
    sys.exit(entry())
  File "C:\Users\DELL\AppData\Roaming\Python\Python38\site-packages\openfl\interface\cli.py", line 212, in entry
    cli()
  File "C:\Users\DELL\AppData\Roaming\Python\Python38\site-packages\click\core.py", line 1137, in __call__
    return self.main(*args, **kwargs)
  File "C:\Users\DELL\AppData\Roaming\Python\Python38\site-packages\click\core.py", line 1062, in main
    rv = self.invoke(ctx)
  File "C:\Users\DELL\AppData\Roaming\Python\Python38\site-packages\click\core.py", line 1668, in invoke
    return _process_result(sub_ctx.command.invoke(sub_ctx))
  File "C:\Users\DELL\AppData\Roaming\Python\Python38\site-packages\click\core.py", line 1668, in invoke
    return _process_result(sub_ctx.command.invoke(sub_ctx))
  File "C:\Users\DELL\AppData\Roaming\Python\Python38\site-packages\click\core.py", line 1404, in invoke
    return ctx.invoke(self.callback, **ctx.params)
  File "C:\Users\DELL\AppData\Roaming\Python\Python38\site-packages\click\core.py", line 763, in invoke
    return __callback(*args, **kwargs)
  File "C:\Users\DELL\AppData\Roaming\Python\Python38\site-packages\openfl\interface\director.py", line 104, in start
    director_server.start()
  File "C:\Users\DELL\AppData\Roaming\Python\Python38\site-packages\openfl\transport\grpc\director_server.py", line 94, in start
    loop.run_until_complete(self._run_server())
  File "C:\Users\DELL\anaconda3\envs\myenv\lib\asyncio\base_events.py", line 603, in run_until_complete
    self.run_forever()
  File "C:\Users\DELL\anaconda3\envs\myenv\lib\asyncio\windows_events.py", line 316, in run_forever
    super().run_forever()
  File "C:\Users\DELL\anaconda3\envs\myenv\lib\asyncio\base_events.py", line 570, in run_forever
    self._run_once()
  File "C:\Users\DELL\anaconda3\envs\myenv\lib\asyncio\base_events.py", line 1859, in _run_once
    handle._run()
  File "C:\Users\DELL\anaconda3\envs\myenv\lib\asyncio\events.py", line 81, in _run
    self._context.run(self._callback, *self._args)
  File "C:\Users\DELL\AppData\Roaming\Python\Python38\site-packages\openfl\transport\grpc\director_server.py", line 115, in _run_server
    logger.info(f'Starting server on {self.listen_uri}')
  File "C:\Users\DELL\anaconda3\envs\myenv\lib\logging\__init__.py", line 1446, in info
    self._log(INFO, msg, args, **kwargs)
  File "C:\Users\DELL\anaconda3\envs\myenv\lib\logging\__init__.py", line 1589, in _log
    self.handle(record)
  File "C:\Users\DELL\anaconda3\envs\myenv\lib\logging\__init__.py", line 1599, in handle
    self.callHandlers(record)
  File "C:\Users\DELL\anaconda3\envs\myenv\lib\logging\__init__.py", line 1661, in callHandlers
    hdlr.handle(record)
  File "C:\Users\DELL\anaconda3\envs\myenv\lib\logging\__init__.py", line 954, in handle
    self.emit(record)
  File "C:\Users\DELL\AppData\Roaming\Python\Python38\site-packages\rich\logging.py", line 172, in emit
    self.handleError(record)
Message: 'Starting server on localhost:50054'
Arguments: ()
--- Logging error ---
Traceback (most recent call last):
  File "C:\Users\DELL\AppData\Roaming\Python\Python38\site-packages\rich\logging.py", line 170, in emit
    self.console.print(log_renderable)
  File "C:\Users\DELL\AppData\Roaming\Python\Python38\site-packages\rich\console.py", line 1720, in print
    self._buffer.extend(new_segments)
  File "C:\Users\DELL\AppData\Roaming\Python\Python38\site-packages\rich\console.py", line 864, in __exit__
    self._exit_buffer()
  File "C:\Users\DELL\AppData\Roaming\Python\Python38\site-packages\rich\console.py", line 822, in _exit_buffer
    self._check_buffer()
  File "C:\Users\DELL\AppData\Roaming\Python\Python38\site-packages\rich\console.py", line 2027, in _check_buffer
    legacy_windows_render(buffer, LegacyWindowsTerm(self.file))
  File "C:\Users\DELL\AppData\Roaming\Python\Python38\site-packages\rich\_windows_renderer.py", line 19, in legacy_windows_render
    term.write_text(text)
  File "C:\Users\DELL\AppData\Roaming\Python\Python38\site-packages\rich\_win32_console.py", line 403, in write_text
    self.write(text)
  File "C:\Users\DELL\anaconda3\envs\myenv\lib\encodings\cp1252.py", line 19, in encode
    return codecs.charmap_encode(input,self.errors,encoding_table)[0]
UnicodeEncodeError: 'charmap' codec can't encode character '\U0001f9ff' in position 0: character maps to <undefined>
Call stack:
  File "C:\Users\DELL\anaconda3\envs\myenv\lib\runpy.py", line 194, in _run_module_as_main
    return _run_code(code, main_globals, None,
  File "C:\Users\DELL\anaconda3\envs\myenv\lib\runpy.py", line 87, in _run_code
    exec(code, run_globals)
  File "C:\Users\DELL\anaconda3\envs\myenv\Scripts\fx.exe\__main__.py", line 7, in <module>
    sys.exit(entry())
  File "C:\Users\DELL\AppData\Roaming\Python\Python38\site-packages\openfl\interface\cli.py", line 212, in entry
    cli()
  File "C:\Users\DELL\AppData\Roaming\Python\Python38\site-packages\click\core.py", line 1137, in __call__
    return self.main(*args, **kwargs)
  File "C:\Users\DELL\AppData\Roaming\Python\Python38\site-packages\click\core.py", line 1062, in main
    rv = self.invoke(ctx)
  File "C:\Users\DELL\AppData\Roaming\Python\Python38\site-packages\click\core.py", line 1668, in invoke
    return _process_result(sub_ctx.command.invoke(sub_ctx))
  File "C:\Users\DELL\AppData\Roaming\Python\Python38\site-packages\click\core.py", line 1668, in invoke
    return _process_result(sub_ctx.command.invoke(sub_ctx))
  File "C:\Users\DELL\AppData\Roaming\Python\Python38\site-packages\click\core.py", line 1404, in invoke
    return ctx.invoke(self.callback, **ctx.params)
  File "C:\Users\DELL\AppData\Roaming\Python\Python38\site-packages\click\core.py", line 763, in invoke
    return __callback(*args, **kwargs)
  File "C:\Users\DELL\AppData\Roaming\Python\Python38\site-packages\openfl\interface\director.py", line 104, in start
    director_server.start()
  File "C:\Users\DELL\AppData\Roaming\Python\Python38\site-packages\openfl\transport\grpc\director_server.py", line 94, in start
    loop.run_until_complete(self._run_server())
  File "C:\Users\DELL\anaconda3\envs\myenv\lib\asyncio\base_events.py", line 603, in run_until_complete
    self.run_forever()
  File "C:\Users\DELL\anaconda3\envs\myenv\lib\asyncio\windows_events.py", line 316, in run_forever
    super().run_forever()
  File "C:\Users\DELL\anaconda3\envs\myenv\lib\asyncio\base_events.py", line 570, in run_forever
    self._run_once()
  File "C:\Users\DELL\anaconda3\envs\myenv\lib\asyncio\base_events.py", line 1859, in _run_once
    handle._run()
  File "C:\Users\DELL\anaconda3\envs\myenv\lib\asyncio\events.py", line 81, in _run
    self._context.run(self._callback, *self._args)
  File "C:\Users\DELL\AppData\Roaming\Python\Python38\site-packages\openfl\transport\grpc\director_server.py", line 121, in UpdateShardInfo
    logger.info(f'UpdateShardInfo request has got: {request.shard_info}')
[19:54:14] INFO     [19:54:14] INFO       File "C:\Users\DELL\anaconda3\envs\myenv\lib\logging\__init__.py", line 1446, in info
    self._log(INFO, msg, args, **kwargs)
  File "C:\Users\DELL\anaconda3\envs\myenv\lib\logging\__init__.py", line 1589, in _log
    self.handle(record)
  File "C:\Users\DELL\anaconda3\envs\myenv\lib\logging\__init__.py", line 1599, in handle
    self.callHandlers(record)
  File "C:\Users\DELL\anaconda3\envs\myenv\lib\logging\__init__.py", line 1661, in callHandlers
    hdlr.handle(record)
  File "C:\Users\DELL\anaconda3\envs\myenv\lib\logging\__init__.py", line 954, in handle
    self.emit(record)
  File "C:\Users\DELL\AppData\Roaming\Python\Python38\site-packages\rich\logging.py", line 172, in emit
    self.handleError(record)
Message: 'UpdateShardInfo request has got: node_info {\n  name: "envoy_1"\n}\nshard_description: "FL_Chain dataset, shard number 1 out of 1"\nsample_shape: "8"\ntarget_shape: "2"\n'
Arguments: ()
--- Logging error ---
Traceback (most recent call last):
  File "C:\Users\DELL\AppData\Roaming\Python\Python38\site-packages\rich\logging.py", line 170, in emit
    self.console.print(log_renderable)
  File "C:\Users\DELL\AppData\Roaming\Python\Python38\site-packages\rich\console.py", line 1720, in print
    self._buffer.extend(new_segments)
  File "C:\Users\DELL\AppData\Roaming\Python\Python38\site-packages\rich\console.py", line 864, in __exit__
    self._exit_buffer()
  File "C:\Users\DELL\AppData\Roaming\Python\Python38\site-packages\rich\console.py", line 822, in _exit_buffer
    self._check_buffer()
  File "C:\Users\DELL\AppData\Roaming\Python\Python38\site-packages\rich\console.py", line 2027, in _check_buffer
    legacy_windows_render(buffer, LegacyWindowsTerm(self.file))
  File "C:\Users\DELL\AppData\Roaming\Python\Python38\site-packages\rich\_windows_renderer.py", line 19, in legacy_windows_render
    term.write_text(text)
  File "C:\Users\DELL\AppData\Roaming\Python\Python38\site-packages\rich\_win32_console.py", line 403, in write_text
    self.write(text)
  File "C:\Users\DELL\anaconda3\envs\myenv\lib\encodings\cp1252.py", line 19, in encode
    return codecs.charmap_encode(input,self.errors,encoding_table)[0]
UnicodeEncodeError: 'charmap' codec can't encode character '\U0001f9ff' in position 0: character maps to <undefined>
Call stack:
  File "C:\Users\DELL\anaconda3\envs\myenv\lib\runpy.py", line 194, in _run_module_as_main
    return _run_code(code, main_globals, None,
  File "C:\Users\DELL\anaconda3\envs\myenv\lib\runpy.py", line 87, in _run_code
    exec(code, run_globals)
  File "C:\Users\DELL\anaconda3\envs\myenv\Scripts\fx.exe\__main__.py", line 7, in <module>
    sys.exit(entry())
  File "C:\Users\DELL\AppData\Roaming\Python\Python38\site-packages\openfl\interface\cli.py", line 212, in entry
    cli()
  File "C:\Users\DELL\AppData\Roaming\Python\Python38\site-packages\click\core.py", line 1137, in __call__
    return self.main(*args, **kwargs)
  File "C:\Users\DELL\AppData\Roaming\Python\Python38\site-packages\click\core.py", line 1062, in main
    rv = self.invoke(ctx)
  File "C:\Users\DELL\AppData\Roaming\Python\Python38\site-packages\click\core.py", line 1668, in invoke
    return _process_result(sub_ctx.command.invoke(sub_ctx))
  File "C:\Users\DELL\AppData\Roaming\Python\Python38\site-packages\click\core.py", line 1668, in invoke
    return _process_result(sub_ctx.command.invoke(sub_ctx))
  File "C:\Users\DELL\AppData\Roaming\Python\Python38\site-packages\click\core.py", line 1404, in invoke
    return ctx.invoke(self.callback, **ctx.params)
  File "C:\Users\DELL\AppData\Roaming\Python\Python38\site-packages\click\core.py", line 763, in invoke
    return __callback(*args, **kwargs)
  File "C:\Users\DELL\AppData\Roaming\Python\Python38\site-packages\openfl\interface\director.py", line 104, in start
    director_server.start()
  File "C:\Users\DELL\AppData\Roaming\Python\Python38\site-packages\openfl\transport\grpc\director_server.py", line 94, in start
    loop.run_until_complete(self._run_server())
  File "C:\Users\DELL\anaconda3\envs\myenv\lib\asyncio\base_events.py", line 603, in run_until_complete
    self.run_forever()
  File "C:\Users\DELL\anaconda3\envs\myenv\lib\asyncio\windows_events.py", line 316, in run_forever
    super().run_forever()
  File "C:\Users\DELL\anaconda3\envs\myenv\lib\asyncio\base_events.py", line 570, in run_forever
    self._run_once()
  File "C:\Users\DELL\anaconda3\envs\myenv\lib\asyncio\base_events.py", line 1859, in _run_once
    handle._run()
  File "C:\Users\DELL\anaconda3\envs\myenv\lib\asyncio\events.py", line 81, in _run
    self._context.run(self._callback, *self._args)
  File "C:\Users\DELL\AppData\Roaming\Python\Python38\site-packages\openfl\transport\grpc\director_server.py", line 126, in UpdateShardInfo
    is_accepted = self.director.acknowledge_shard(dict_shard_info)
  File "C:\Users\DELL\AppData\Roaming\Python\Python38\site-packages\openfl\component\director\director.py", line 56, in acknowledge_shard
    logger.info('Request was accepted')
  File "C:\Users\DELL\anaconda3\envs\myenv\lib\logging\__init__.py", line 1446, in info
    self._log(INFO, msg, args, **kwargs)
  File "C:\Users\DELL\anaconda3\envs\myenv\lib\logging\__init__.py", line 1589, in _log
    self.handle(record)
  File "C:\Users\DELL\anaconda3\envs\myenv\lib\logging\__init__.py", line 1599, in handle
    self.callHandlers(record)
  File "C:\Users\DELL\anaconda3\envs\myenv\lib\logging\__init__.py", line 1661, in callHandlers
    hdlr.handle(record)
  File "C:\Users\DELL\anaconda3\envs\myenv\lib\logging\__init__.py", line 954, in handle
    self.emit(record)
  File "C:\Users\DELL\AppData\Roaming\Python\Python38\site-packages\rich\logging.py", line 172, in emit
    self.handleError(record)
Message: 'Request was accepted'
Arguments: ()
--- Logging error ---
Traceback (most recent call last):
  File "C:\Users\DELL\AppData\Roaming\Python\Python38\site-packages\rich\logging.py", line 170, in emit
    self.console.print(log_renderable)
  File "C:\Users\DELL\AppData\Roaming\Python\Python38\site-packages\rich\console.py", line 1720, in print
    self._buffer.extend(new_segments)
  File "C:\Users\DELL\AppData\Roaming\Python\Python38\site-packages\rich\console.py", line 864, in __exit__
    self._exit_buffer()
  File "C:\Users\DELL\AppData\Roaming\Python\Python38\site-packages\rich\console.py", line 822, in _exit_buffer
    self._check_buffer()
  File "C:\Users\DELL\AppData\Roaming\Python\Python38\site-packages\rich\console.py", line 2027, in _check_buffer
    legacy_windows_render(buffer, LegacyWindowsTerm(self.file))
  File "C:\Users\DELL\AppData\Roaming\Python\Python38\site-packages\rich\_windows_renderer.py", line 19, in legacy_windows_render
    term.write_text(text)
  File "C:\Users\DELL\AppData\Roaming\Python\Python38\site-packages\rich\_win32_console.py", line 403, in write_text
    self.write(text)
  File "C:\Users\DELL\anaconda3\envs\myenv\lib\encodings\cp1252.py", line 19, in encode
    return codecs.charmap_encode(input,self.errors,encoding_table)[0]
UnicodeEncodeError: 'charmap' codec can't encode character '\U0001f9ff' in position 0: character maps to <undefined>
Call stack:
  File "C:\Users\DELL\anaconda3\envs\myenv\lib\runpy.py", line 194, in _run_module_as_main
    return _run_code(code, main_globals, None,
  File "C:\Users\DELL\anaconda3\envs\myenv\lib\runpy.py", line 87, in _run_code
    exec(code, run_globals)
  File "C:\Users\DELL\anaconda3\envs\myenv\Scripts\fx.exe\__main__.py", line 7, in <module>
    sys.exit(entry())
  File "C:\Users\DELL\AppData\Roaming\Python\Python38\site-packages\openfl\interface\cli.py", line 212, in entry
    cli()
  File "C:\Users\DELL\AppData\Roaming\Python\Python38\site-packages\click\core.py", line 1137, in __call__
    return self.main(*args, **kwargs)
  File "C:\Users\DELL\AppData\Roaming\Python\Python38\site-packages\click\core.py", line 1062, in main
    rv = self.invoke(ctx)
  File "C:\Users\DELL\AppData\Roaming\Python\Python38\site-packages\click\core.py", line 1668, in invoke
    return _process_result(sub_ctx.command.invoke(sub_ctx))
[19:54:14] INFO       File "C:\Users\DELL\AppData\Roaming\Python\Python38\site-packages\click\core.py", line 1668, in invoke
    return _process_result(sub_ctx.command.invoke(sub_ctx))
  File "C:\Users\DELL\AppData\Roaming\Python\Python38\site-packages\click\core.py", line 1404, in invoke
    return ctx.invoke(self.callback, **ctx.params)
  File "C:\Users\DELL\AppData\Roaming\Python\Python38\site-packages\click\core.py", line 763, in invoke
    return __callback(*args, **kwargs)
  File "C:\Users\DELL\AppData\Roaming\Python\Python38\site-packages\openfl\interface\director.py", line 104, in start
    director_server.start()
  File "C:\Users\DELL\AppData\Roaming\Python\Python38\site-packages\openfl\transport\grpc\director_server.py", line 94, in start
    loop.run_until_complete(self._run_server())
  File "C:\Users\DELL\anaconda3\envs\myenv\lib\asyncio\base_events.py", line 603, in run_until_complete
    self.run_forever()
  File "C:\Users\DELL\anaconda3\envs\myenv\lib\asyncio\windows_events.py", line 316, in run_forever
    super().run_forever()
  File "C:\Users\DELL\anaconda3\envs\myenv\lib\asyncio\base_events.py", line 570, in run_forever
    self._run_once()
  File "C:\Users\DELL\anaconda3\envs\myenv\lib\asyncio\base_events.py", line 1859, in _run_once
    handle._run()
  File "C:\Users\DELL\anaconda3\envs\myenv\lib\asyncio\events.py", line 81, in _run
    self._context.run(self._callback, *self._args)
  File "C:\Users\DELL\AppData\Roaming\Python\Python38\site-packages\openfl\transport\grpc\director_server.py", line 204, in WaitExperiment
    logger.info('Request WaitExperiment has got!')
  File "C:\Users\DELL\anaconda3\envs\myenv\lib\logging\__init__.py", line 1446, in info
    self._log(INFO, msg, args, **kwargs)
  File "C:\Users\DELL\anaconda3\envs\myenv\lib\logging\__init__.py", line 1589, in _log
    self.handle(record)
  File "C:\Users\DELL\anaconda3\envs\myenv\lib\logging\__init__.py", line 1599, in handle
    self.callHandlers(record)
  File "C:\Users\DELL\anaconda3\envs\myenv\lib\logging\__init__.py", line 1661, in callHandlers
    hdlr.handle(record)
  File "C:\Users\DELL\anaconda3\envs\myenv\lib\logging\__init__.py", line 954, in handle
    self.emit(record)
  File "C:\Users\DELL\AppData\Roaming\Python\Python38\site-packages\rich\logging.py", line 172, in emit
    self.handleError(record)
Message: 'Request WaitExperiment has got!'
Arguments: ()
--- Logging error ---
Traceback (most recent call last):
  File "C:\Users\DELL\AppData\Roaming\Python\Python38\site-packages\rich\logging.py", line 170, in emit
    self.console.print(log_renderable)
  File "C:\Users\DELL\AppData\Roaming\Python\Python38\site-packages\rich\console.py", line 1720, in print
    self._buffer.extend(new_segments)
  File "C:\Users\DELL\AppData\Roaming\Python\Python38\site-packages\rich\console.py", line 864, in __exit__
    self._exit_buffer()
  File "C:\Users\DELL\AppData\Roaming\Python\Python38\site-packages\rich\console.py", line 822, in _exit_buffer
    self._check_buffer()
  File "C:\Users\DELL\AppData\Roaming\Python\Python38\site-packages\rich\console.py", line 2027, in _check_buffer
    legacy_windows_render(buffer, LegacyWindowsTerm(self.file))
  File "C:\Users\DELL\AppData\Roaming\Python\Python38\site-packages\rich\_windows_renderer.py", line 19, in legacy_windows_render
    term.write_text(text)
  File "C:\Users\DELL\AppData\Roaming\Python\Python38\site-packages\rich\_win32_console.py", line 403, in write_text
    self.write(text)
  File "C:\Users\DELL\anaconda3\envs\myenv\lib\encodings\cp1252.py", line 19, in encode
    return codecs.charmap_encode(input,self.errors,encoding_table)[0]
UnicodeEncodeError: 'charmap' codec can't encode character '\U0001f9ff' in position 0: character maps to <undefined>
Call stack:
  File "C:\Users\DELL\anaconda3\envs\myenv\lib\runpy.py", line 194, in _run_module_as_main
    return _run_code(code, main_globals, None,
  File "C:\Users\DELL\anaconda3\envs\myenv\lib\runpy.py", line 87, in _run_code
    exec(code, run_globals)
  File "C:\Users\DELL\anaconda3\envs\myenv\Scripts\fx.exe\__main__.py", line 7, in <module>
    sys.exit(entry())
  File "C:\Users\DELL\AppData\Roaming\Python\Python38\site-packages\openfl\interface\cli.py", line 212, in entry
    cli()
  File "C:\Users\DELL\AppData\Roaming\Python\Python38\site-packages\click\core.py", line 1137, in __call__
    return self.main(*args, **kwargs)
  File "C:\Users\DELL\AppData\Roaming\Python\Python38\site-packages\click\core.py", line 1062, in main
    rv = self.invoke(ctx)
  File "C:\Users\DELL\AppData\Roaming\Python\Python38\site-packages\click\core.py", line 1668, in invoke
    return _process_result(sub_ctx.command.invoke(sub_ctx))
  File "C:\Users\DELL\AppData\Roaming\Python\Python38\site-packages\click\core.py", line 1668, in invoke
    return _process_result(sub_ctx.command.invoke(sub_ctx))
  File "C:\Users\DELL\AppData\Roaming\Python\Python38\site-packages\click\core.py", line 1404, in invoke
    return ctx.invoke(self.callback, **ctx.params)
  File "C:\Users\DELL\AppData\Roaming\Python\Python38\site-packages\click\core.py", line 763, in invoke
    return __callback(*args, **kwargs)
  File "C:\Users\DELL\AppData\Roaming\Python\Python38\site-packages\openfl\interface\director.py", line 104, in start
    director_server.start()
  File "C:\Users\DELL\AppData\Roaming\Python\Python38\site-packages\openfl\transport\grpc\director_server.py", line 94, in start
    loop.run_until_complete(self._run_server())
  File "C:\Users\DELL\anaconda3\envs\myenv\lib\asyncio\base_events.py", line 603, in run_until_complete
    self.run_forever()
  File "C:\Users\DELL\anaconda3\envs\myenv\lib\asyncio\windows_events.py", line 316, in run_forever
    super().run_forever()
  File "C:\Users\DELL\anaconda3\envs\myenv\lib\asyncio\base_events.py", line 570, in run_forever
    self._run_once()
  File "C:\Users\DELL\anaconda3\envs\myenv\lib\asyncio\base_events.py", line 1859, in _run_once
    handle._run()
  File "C:\Users\DELL\anaconda3\envs\myenv\lib\asyncio\events.py", line 81, in _run
    self._context.run(self._callback, *self._args)
  File "C:\Users\DELL\AppData\Roaming\Python\Python38\site-packages\openfl\transport\grpc\director_server.py", line 206, in WaitExperiment
    logger.info(msg)
  File "C:\Users\DELL\anaconda3\envs\myenv\lib\logging\__init__.py", line 1446, in info
    self._log(INFO, msg, args, **kwargs)
  File "C:\Users\DELL\anaconda3\envs\myenv\lib\logging\__init__.py", line 1589, in _log
    self.handle(record)
  File "C:\Users\DELL\anaconda3\envs\myenv\lib\logging\__init__.py", line 1599, in handle
    self.callHandlers(record)
  File "C:\Users\DELL\anaconda3\envs\myenv\lib\logging\__init__.py", line 1661, in callHandlers
    hdlr.handle(record)
  File "C:\Users\DELL\anaconda3\envs\myenv\lib\logging\__init__.py", line 954, in handle
    self.emit(record)
  File "C:\Users\DELL\AppData\Roaming\Python\Python38\site-packages\rich\logging.py", line 172, in emit
    self.handleError(record)
Message: collaborator_name: "envoy_1"

Arguments: ()
--- Logging error ---
Traceback (most recent call last):
  File "C:\Users\DELL\AppData\Roaming\Python\Python38\site-packages\rich\logging.py", line 170, in emit
    self.console.print(log_renderable)
  File "C:\Users\DELL\AppData\Roaming\Python\Python38\site-packages\rich\console.py", line 1720, in print
    self._buffer.extend(new_segments)
  File "C:\Users\DELL\AppData\Roaming\Python\Python38\site-packages\rich\console.py", line 864, in __exit__
    self._exit_buffer()
  File "C:\Users\DELL\AppData\Roaming\Python\Python38\site-packages\rich\console.py", line 822, in _exit_buffer
    self._check_buffer()
  File "C:\Users\DELL\AppData\Roaming\Python\Python38\site-packages\rich\console.py", line 2027, in _check_buffer
    legacy_windows_render(buffer, LegacyWindowsTerm(self.file))
  File "C:\Users\DELL\AppData\Roaming\Python\Python38\site-packages\rich\_windows_renderer.py", line 19, in legacy_windows_render
    term.write_text(text)
[19:54:14] INFO     [19:54:14] INFO       File "C:\Users\DELL\AppData\Roaming\Python\Python38\site-packages\rich\_win32_console.py", line 403, in write_text
    self.write(text)
  File "C:\Users\DELL\anaconda3\envs\myenv\lib\encodings\cp1252.py", line 19, in encode
    return codecs.charmap_encode(input,self.errors,encoding_table)[0]
UnicodeEncodeError: 'charmap' codec can't encode character '\U0001f9ff' in position 0: character maps to <undefined>
Call stack:
  File "C:\Users\DELL\anaconda3\envs\myenv\lib\runpy.py", line 194, in _run_module_as_main
    return _run_code(code, main_globals, None,
  File "C:\Users\DELL\anaconda3\envs\myenv\lib\runpy.py", line 87, in _run_code
    exec(code, run_globals)
  File "C:\Users\DELL\anaconda3\envs\myenv\Scripts\fx.exe\__main__.py", line 7, in <module>
    sys.exit(entry())
  File "C:\Users\DELL\AppData\Roaming\Python\Python38\site-packages\openfl\interface\cli.py", line 212, in entry
    cli()
  File "C:\Users\DELL\AppData\Roaming\Python\Python38\site-packages\click\core.py", line 1137, in __call__
    return self.main(*args, **kwargs)
  File "C:\Users\DELL\AppData\Roaming\Python\Python38\site-packages\click\core.py", line 1062, in main
    rv = self.invoke(ctx)
  File "C:\Users\DELL\AppData\Roaming\Python\Python38\site-packages\click\core.py", line 1668, in invoke
    return _process_result(sub_ctx.command.invoke(sub_ctx))
  File "C:\Users\DELL\AppData\Roaming\Python\Python38\site-packages\click\core.py", line 1668, in invoke
    return _process_result(sub_ctx.command.invoke(sub_ctx))
  File "C:\Users\DELL\AppData\Roaming\Python\Python38\site-packages\click\core.py", line 1404, in invoke
    return ctx.invoke(self.callback, **ctx.params)
  File "C:\Users\DELL\AppData\Roaming\Python\Python38\site-packages\click\core.py", line 763, in invoke
    return __callback(*args, **kwargs)
  File "C:\Users\DELL\AppData\Roaming\Python\Python38\site-packages\openfl\interface\director.py", line 104, in start
    director_server.start()
  File "C:\Users\DELL\AppData\Roaming\Python\Python38\site-packages\openfl\transport\grpc\director_server.py", line 94, in start
    loop.run_until_complete(self._run_server())
  File "C:\Users\DELL\anaconda3\envs\myenv\lib\asyncio\base_events.py", line 603, in run_until_complete
    self.run_forever()
  File "C:\Users\DELL\anaconda3\envs\myenv\lib\asyncio\windows_events.py", line 316, in run_forever
    super().run_forever()
  File "C:\Users\DELL\anaconda3\envs\myenv\lib\asyncio\base_events.py", line 570, in run_forever
    self._run_once()
  File "C:\Users\DELL\anaconda3\envs\myenv\lib\asyncio\base_events.py", line 1859, in _run_once
    handle._run()
  File "C:\Users\DELL\anaconda3\envs\myenv\lib\asyncio\events.py", line 81, in _run
    self._context.run(self._callback, *self._args)
  File "C:\Users\DELL\AppData\Roaming\Python\Python38\site-packages\openfl\transport\grpc\director_server.py", line 214, in GetDatasetInfo
    logger.info('Request GetDatasetInfo has got!')
  File "C:\Users\DELL\anaconda3\envs\myenv\lib\logging\__init__.py", line 1446, in info
    self._log(INFO, msg, args, **kwargs)
  File "C:\Users\DELL\anaconda3\envs\myenv\lib\logging\__init__.py", line 1589, in _log
    self.handle(record)
  File "C:\Users\DELL\anaconda3\envs\myenv\lib\logging\__init__.py", line 1599, in handle
    self.callHandlers(record)
  File "C:\Users\DELL\anaconda3\envs\myenv\lib\logging\__init__.py", line 1661, in callHandlers
    hdlr.handle(record)
  File "C:\Users\DELL\anaconda3\envs\myenv\lib\logging\__init__.py", line 954, in handle
    self.emit(record)
  File "C:\Users\DELL\AppData\Roaming\Python\Python38\site-packages\rich\logging.py", line 172, in emit
    self.handleError(record)
Message: 'Request GetDatasetInfo has got!'
Arguments: ()
--- Logging error ---
Traceback (most recent call last):
  File "C:\Users\DELL\AppData\Roaming\Python\Python38\site-packages\rich\logging.py", line 170, in emit
    self.console.print(log_renderable)
  File "C:\Users\DELL\AppData\Roaming\Python\Python38\site-packages\rich\console.py", line 1720, in print
    self._buffer.extend(new_segments)
  File "C:\Users\DELL\AppData\Roaming\Python\Python38\site-packages\rich\console.py", line 864, in __exit__
    self._exit_buffer()
  File "C:\Users\DELL\AppData\Roaming\Python\Python38\site-packages\rich\console.py", line 822, in _exit_buffer
    self._check_buffer()
  File "C:\Users\DELL\AppData\Roaming\Python\Python38\site-packages\rich\console.py", line 2027, in _check_buffer
    legacy_windows_render(buffer, LegacyWindowsTerm(self.file))
  File "C:\Users\DELL\AppData\Roaming\Python\Python38\site-packages\rich\_windows_renderer.py", line 19, in legacy_windows_render
    term.write_text(text)
  File "C:\Users\DELL\AppData\Roaming\Python\Python38\site-packages\rich\_win32_console.py", line 403, in write_text
    self.write(text)
  File "C:\Users\DELL\anaconda3\envs\myenv\lib\encodings\cp1252.py", line 19, in encode
    return codecs.charmap_encode(input,self.errors,encoding_table)[0]
UnicodeEncodeError: 'charmap' codec can't encode character '\U0001f9ff' in position 0: character maps to <undefined>
Call stack:
  File "C:\Users\DELL\anaconda3\envs\myenv\lib\runpy.py", line 194, in _run_module_as_main
    return _run_code(code, main_globals, None,
  File "C:\Users\DELL\anaconda3\envs\myenv\lib\runpy.py", line 87, in _run_code
    exec(code, run_globals)
  File "C:\Users\DELL\anaconda3\envs\myenv\Scripts\fx.exe\__main__.py", line 7, in <module>
    sys.exit(entry())
  File "C:\Users\DELL\AppData\Roaming\Python\Python38\site-packages\openfl\interface\cli.py", line 212, in entry
    cli()
  File "C:\Users\DELL\AppData\Roaming\Python\Python38\site-packages\click\core.py", line 1137, in __call__
    return self.main(*args, **kwargs)
  File "C:\Users\DELL\AppData\Roaming\Python\Python38\site-packages\click\core.py", line 1062, in main
    rv = self.invoke(ctx)
  File "C:\Users\DELL\AppData\Roaming\Python\Python38\site-packages\click\core.py", line 1668, in invoke
    return _process_result(sub_ctx.command.invoke(sub_ctx))
  File "C:\Users\DELL\AppData\Roaming\Python\Python38\site-packages\click\core.py", line 1668, in invoke
    return _process_result(sub_ctx.command.invoke(sub_ctx))
  File "C:\Users\DELL\AppData\Roaming\Python\Python38\site-packages\click\core.py", line 1404, in invoke
    return ctx.invoke(self.callback, **ctx.params)
  File "C:\Users\DELL\AppData\Roaming\Python\Python38\site-packages\click\core.py", line 763, in invoke
    return __callback(*args, **kwargs)
  File "C:\Users\DELL\AppData\Roaming\Python\Python38\site-packages\openfl\interface\director.py", line 104, in start
    director_server.start()
  File "C:\Users\DELL\AppData\Roaming\Python\Python38\site-packages\openfl\transport\grpc\director_server.py", line 94, in start
    loop.run_until_complete(self._run_server())
  File "C:\Users\DELL\anaconda3\envs\myenv\lib\asyncio\base_events.py", line 603, in run_until_complete
    self.run_forever()
  File "C:\Users\DELL\anaconda3\envs\myenv\lib\asyncio\windows_events.py", line 316, in run_forever
    super().run_forever()
  File "C:\Users\DELL\anaconda3\envs\myenv\lib\asyncio\base_events.py", line 570, in run_forever
    self._run_once()
  File "C:\Users\DELL\anaconda3\envs\myenv\lib\asyncio\base_events.py", line 1859, in _run_once
    handle._run()
  File "C:\Users\DELL\anaconda3\envs\myenv\lib\asyncio\events.py", line 81, in _run
    self._context.run(self._callback, *self._args)
  File "C:\Users\DELL\AppData\Roaming\Python\Python38\site-packages\openfl\transport\grpc\director_server.py", line 283, in GetEnvoys
    envoy_infos = self.director.get_envoys()
  File "C:\Users\DELL\AppData\Roaming\Python\Python38\site-packages\openfl\component\director\director.py", line 207, in get_envoys
    logger.info(f'Shard registry: {self._shard_registry}')
  File "C:\Users\DELL\anaconda3\envs\myenv\lib\logging\__init__.py", line 1446, in info
    self._log(INFO, msg, args, **kwargs)
  File "C:\Users\DELL\anaconda3\envs\myenv\lib\logging\__init__.py", line 1589, in _log
    self.handle(record)
[19:54:14] INFO     [19:54:14] INFO       File "C:\Users\DELL\anaconda3\envs\myenv\lib\logging\__init__.py", line 1599, in handle
    self.callHandlers(record)
  File "C:\Users\DELL\anaconda3\envs\myenv\lib\logging\__init__.py", line 1661, in callHandlers
    hdlr.handle(record)
  File "C:\Users\DELL\anaconda3\envs\myenv\lib\logging\__init__.py", line 954, in handle
    self.emit(record)
  File "C:\Users\DELL\AppData\Roaming\Python\Python38\site-packages\rich\logging.py", line 172, in emit
    self.handleError(record)
Message: "Shard registry: {'envoy_1': {'shard_info': {'node_info': {'name': 'envoy_1'}, 'shard_description': 'FL_Chain dataset, shard number 1 out of 1', 'sample_shape': ['8'], 'target_shape': ['2']}, 'is_online': True, 'is_experiment_running': False, 'valid_duration': 120, 'last_updated': 1692294859.98775}}"
Arguments: ()
--- Logging error ---
Traceback (most recent call last):
  File "C:\Users\DELL\AppData\Roaming\Python\Python38\site-packages\rich\logging.py", line 170, in emit
    self.console.print(log_renderable)
  File "C:\Users\DELL\AppData\Roaming\Python\Python38\site-packages\rich\console.py", line 1720, in print
    self._buffer.extend(new_segments)
  File "C:\Users\DELL\AppData\Roaming\Python\Python38\site-packages\rich\console.py", line 864, in __exit__
    self._exit_buffer()
  File "C:\Users\DELL\AppData\Roaming\Python\Python38\site-packages\rich\console.py", line 822, in _exit_buffer
    self._check_buffer()
  File "C:\Users\DELL\AppData\Roaming\Python\Python38\site-packages\rich\console.py", line 2027, in _check_buffer
    legacy_windows_render(buffer, LegacyWindowsTerm(self.file))
  File "C:\Users\DELL\AppData\Roaming\Python\Python38\site-packages\rich\_windows_renderer.py", line 19, in legacy_windows_render
    term.write_text(text)
  File "C:\Users\DELL\AppData\Roaming\Python\Python38\site-packages\rich\_win32_console.py", line 403, in write_text
    self.write(text)
  File "C:\Users\DELL\anaconda3\envs\myenv\lib\encodings\cp1252.py", line 19, in encode
    return codecs.charmap_encode(input,self.errors,encoding_table)[0]
UnicodeEncodeError: 'charmap' codec can't encode character '\U0001f9ff' in position 0: character maps to <undefined>
Call stack:
  File "C:\Users\DELL\anaconda3\envs\myenv\lib\runpy.py", line 194, in _run_module_as_main
    return _run_code(code, main_globals, None,
  File "C:\Users\DELL\anaconda3\envs\myenv\lib\runpy.py", line 87, in _run_code
    exec(code, run_globals)
  File "C:\Users\DELL\anaconda3\envs\myenv\Scripts\fx.exe\__main__.py", line 7, in <module>
    sys.exit(entry())
  File "C:\Users\DELL\AppData\Roaming\Python\Python38\site-packages\openfl\interface\cli.py", line 212, in entry
    cli()
  File "C:\Users\DELL\AppData\Roaming\Python\Python38\site-packages\click\core.py", line 1137, in __call__
    return self.main(*args, **kwargs)
  File "C:\Users\DELL\AppData\Roaming\Python\Python38\site-packages\click\core.py", line 1062, in main
    rv = self.invoke(ctx)
  File "C:\Users\DELL\AppData\Roaming\Python\Python38\site-packages\click\core.py", line 1668, in invoke
    return _process_result(sub_ctx.command.invoke(sub_ctx))
  File "C:\Users\DELL\AppData\Roaming\Python\Python38\site-packages\click\core.py", line 1668, in invoke
    return _process_result(sub_ctx.command.invoke(sub_ctx))
  File "C:\Users\DELL\AppData\Roaming\Python\Python38\site-packages\click\core.py", line 1404, in invoke
    return ctx.invoke(self.callback, **ctx.params)
  File "C:\Users\DELL\AppData\Roaming\Python\Python38\site-packages\click\core.py", line 763, in invoke
    return __callback(*args, **kwargs)
  File "C:\Users\DELL\AppData\Roaming\Python\Python38\site-packages\openfl\interface\director.py", line 104, in start
    director_server.start()
  File "C:\Users\DELL\AppData\Roaming\Python\Python38\site-packages\openfl\transport\grpc\director_server.py", line 94, in start
    loop.run_until_complete(self._run_server())
  File "C:\Users\DELL\anaconda3\envs\myenv\lib\asyncio\base_events.py", line 603, in run_until_complete
    self.run_forever()
  File "C:\Users\DELL\anaconda3\envs\myenv\lib\asyncio\windows_events.py", line 316, in run_forever
    super().run_forever()
  File "C:\Users\DELL\anaconda3\envs\myenv\lib\asyncio\base_events.py", line 570, in run_forever
    self._run_once()
  File "C:\Users\DELL\anaconda3\envs\myenv\lib\asyncio\base_events.py", line 1859, in _run_once
    handle._run()
  File "C:\Users\DELL\anaconda3\envs\myenv\lib\asyncio\events.py", line 81, in _run
    self._context.run(self._callback, *self._args)
  File "C:\Users\DELL\AppData\Roaming\Python\Python38\site-packages\openfl\transport\grpc\director_server.py", line 133, in SetNewExperiment
    logger.info(f'SetNewExperiment request has got {stream}')
  File "C:\Users\DELL\anaconda3\envs\myenv\lib\logging\__init__.py", line 1446, in info
    self._log(INFO, msg, args, **kwargs)
  File "C:\Users\DELL\anaconda3\envs\myenv\lib\logging\__init__.py", line 1589, in _log
    self.handle(record)
  File "C:\Users\DELL\anaconda3\envs\myenv\lib\logging\__init__.py", line 1599, in handle
    self.callHandlers(record)
  File "C:\Users\DELL\anaconda3\envs\myenv\lib\logging\__init__.py", line 1661, in callHandlers
    hdlr.handle(record)
  File "C:\Users\DELL\anaconda3\envs\myenv\lib\logging\__init__.py", line 954, in handle
    self.emit(record)
  File "C:\Users\DELL\AppData\Roaming\Python\Python38\site-packages\rich\logging.py", line 172, in emit
    self.handleError(record)
Message: 'SetNewExperiment request has got <grpc._cython.cygrpc._MessageReceiver object at 0x00000164C05145E0>'
Arguments: ()
--- Logging error ---
Traceback (most recent call last):
  File "C:\Users\DELL\AppData\Roaming\Python\Python38\site-packages\rich\logging.py", line 170, in emit
    self.console.print(log_renderable)
  File "C:\Users\DELL\AppData\Roaming\Python\Python38\site-packages\rich\console.py", line 1720, in print
    self._buffer.extend(new_segments)
  File "C:\Users\DELL\AppData\Roaming\Python\Python38\site-packages\rich\console.py", line 864, in __exit__
    self._exit_buffer()
  File "C:\Users\DELL\AppData\Roaming\Python\Python38\site-packages\rich\console.py", line 822, in _exit_buffer
    self._check_buffer()
  File "C:\Users\DELL\AppData\Roaming\Python\Python38\site-packages\rich\console.py", line 2027, in _check_buffer
    legacy_windows_render(buffer, LegacyWindowsTerm(self.file))
  File "C:\Users\DELL\AppData\Roaming\Python\Python38\site-packages\rich\_windows_renderer.py", line 19, in legacy_windows_render
    term.write_text(text)
  File "C:\Users\DELL\AppData\Roaming\Python\Python38\site-packages\rich\_win32_console.py", line 403, in write_text
    self.write(text)
  File "C:\Users\DELL\anaconda3\envs\myenv\lib\encodings\cp1252.py", line 19, in encode
    return codecs.charmap_encode(input,self.errors,encoding_table)[0]
UnicodeEncodeError: 'charmap' codec can't encode character '\U0001f9ff' in position 0: character maps to <undefined>
Call stack:
  File "C:\Users\DELL\anaconda3\envs\myenv\lib\runpy.py", line 194, in _run_module_as_main
    return _run_code(code, main_globals, None,
  File "C:\Users\DELL\anaconda3\envs\myenv\lib\runpy.py", line 87, in _run_code
    exec(code, run_globals)
  File "C:\Users\DELL\anaconda3\envs\myenv\Scripts\fx.exe\__main__.py", line 7, in <module>
    sys.exit(entry())
  File "C:\Users\DELL\AppData\Roaming\Python\Python38\site-packages\openfl\interface\cli.py", line 212, in entry
    cli()
  File "C:\Users\DELL\AppData\Roaming\Python\Python38\site-packages\click\core.py", line 1137, in __call__
    return self.main(*args, **kwargs)
  File "C:\Users\DELL\AppData\Roaming\Python\Python38\site-packages\click\core.py", line 1062, in main
    rv = self.invoke(ctx)
  File "C:\Users\DELL\AppData\Roaming\Python\Python38\site-packages\click\core.py", line 1668, in invoke
    return _process_result(sub_ctx.command.invoke(sub_ctx))
  File "C:\Users\DELL\AppData\Roaming\Python\Python38\site-packages\click\core.py", line 1668, in invoke
    return _process_result(sub_ctx.command.invoke(sub_ctx))
[19:54:14] INFO       File "C:\Users\DELL\AppData\Roaming\Python\Python38\site-packages\click\core.py", line 1404, in invoke
    return ctx.invoke(self.callback, **ctx.params)
  File "C:\Users\DELL\AppData\Roaming\Python\Python38\site-packages\click\core.py", line 763, in invoke
    return __callback(*args, **kwargs)
  File "C:\Users\DELL\AppData\Roaming\Python\Python38\site-packages\openfl\interface\director.py", line 104, in start
    director_server.start()
  File "C:\Users\DELL\AppData\Roaming\Python\Python38\site-packages\openfl\transport\grpc\director_server.py", line 94, in start
    loop.run_until_complete(self._run_server())
  File "C:\Users\DELL\anaconda3\envs\myenv\lib\asyncio\base_events.py", line 603, in run_until_complete
    self.run_forever()
  File "C:\Users\DELL\anaconda3\envs\myenv\lib\asyncio\windows_events.py", line 316, in run_forever
    super().run_forever()
  File "C:\Users\DELL\anaconda3\envs\myenv\lib\asyncio\base_events.py", line 570, in run_forever
    self._run_once()
  File "C:\Users\DELL\anaconda3\envs\myenv\lib\asyncio\base_events.py", line 1859, in _run_once
    handle._run()
  File "C:\Users\DELL\anaconda3\envs\myenv\lib\asyncio\events.py", line 81, in _run
    self._context.run(self._callback, *self._args)
  File "C:\Users\DELL\AppData\Roaming\Python\Python38\site-packages\openfl\transport\grpc\director_server.py", line 158, in SetNewExperiment
    logger.info('Send response')
  File "C:\Users\DELL\anaconda3\envs\myenv\lib\logging\__init__.py", line 1446, in info
    self._log(INFO, msg, args, **kwargs)
  File "C:\Users\DELL\anaconda3\envs\myenv\lib\logging\__init__.py", line 1589, in _log
    self.handle(record)
  File "C:\Users\DELL\anaconda3\envs\myenv\lib\logging\__init__.py", line 1599, in handle
    self.callHandlers(record)
  File "C:\Users\DELL\anaconda3\envs\myenv\lib\logging\__init__.py", line 1661, in callHandlers
    hdlr.handle(record)
  File "C:\Users\DELL\anaconda3\envs\myenv\lib\logging\__init__.py", line 954, in handle
    self.emit(record)
  File "C:\Users\DELL\AppData\Roaming\Python\Python38\site-packages\rich\logging.py", line 172, in emit
    self.handleError(record)
Message: 'Send response'
Arguments: ()
--- Logging error ---
Traceback (most recent call last):
  File "C:\Users\DELL\AppData\Roaming\Python\Python38\site-packages\rich\logging.py", line 170, in emit
    self.console.print(log_renderable)
  File "C:\Users\DELL\AppData\Roaming\Python\Python38\site-packages\rich\console.py", line 1720, in print
    self._buffer.extend(new_segments)
  File "C:\Users\DELL\AppData\Roaming\Python\Python38\site-packages\rich\console.py", line 864, in __exit__
    self._exit_buffer()
  File "C:\Users\DELL\AppData\Roaming\Python\Python38\site-packages\rich\console.py", line 822, in _exit_buffer
    self._check_buffer()
  File "C:\Users\DELL\AppData\Roaming\Python\Python38\site-packages\rich\console.py", line 2027, in _check_buffer
    legacy_windows_render(buffer, LegacyWindowsTerm(self.file))
  File "C:\Users\DELL\AppData\Roaming\Python\Python38\site-packages\rich\_windows_renderer.py", line 19, in legacy_windows_render
    term.write_text(text)
  File "C:\Users\DELL\AppData\Roaming\Python\Python38\site-packages\rich\_win32_console.py", line 403, in write_text
    self.write(text)
  File "C:\Users\DELL\anaconda3\envs\myenv\lib\encodings\cp1252.py", line 19, in encode
    return codecs.charmap_encode(input,self.errors,encoding_table)[0]
UnicodeEncodeError: 'charmap' codec can't encode character '\U0001f9ff' in position 0: character maps to <undefined>
Call stack:
  File "C:\Users\DELL\anaconda3\envs\myenv\lib\runpy.py", line 194, in _run_module_as_main
    return _run_code(code, main_globals, None,
  File "C:\Users\DELL\anaconda3\envs\myenv\lib\runpy.py", line 87, in _run_code
    exec(code, run_globals)
  File "C:\Users\DELL\anaconda3\envs\myenv\Scripts\fx.exe\__main__.py", line 7, in <module>
    sys.exit(entry())
  File "C:\Users\DELL\AppData\Roaming\Python\Python38\site-packages\openfl\interface\cli.py", line 212, in entry
    cli()
  File "C:\Users\DELL\AppData\Roaming\Python\Python38\site-packages\click\core.py", line 1137, in __call__
    return self.main(*args, **kwargs)
  File "C:\Users\DELL\AppData\Roaming\Python\Python38\site-packages\click\core.py", line 1062, in main
    rv = self.invoke(ctx)
  File "C:\Users\DELL\AppData\Roaming\Python\Python38\site-packages\click\core.py", line 1668, in invoke
    return _process_result(sub_ctx.command.invoke(sub_ctx))
  File "C:\Users\DELL\AppData\Roaming\Python\Python38\site-packages\click\core.py", line 1668, in invoke
    return _process_result(sub_ctx.command.invoke(sub_ctx))
  File "C:\Users\DELL\AppData\Roaming\Python\Python38\site-packages\click\core.py", line 1404, in invoke
    return ctx.invoke(self.callback, **ctx.params)
  File "C:\Users\DELL\AppData\Roaming\Python\Python38\site-packages\click\core.py", line 763, in invoke
    return __callback(*args, **kwargs)
  File "C:\Users\DELL\AppData\Roaming\Python\Python38\site-packages\openfl\interface\director.py", line 104, in start
    director_server.start()
  File "C:\Users\DELL\AppData\Roaming\Python\Python38\site-packages\openfl\transport\grpc\director_server.py", line 94, in start
    loop.run_until_complete(self._run_server())
  File "C:\Users\DELL\anaconda3\envs\myenv\lib\asyncio\base_events.py", line 603, in run_until_complete
    self.run_forever()
  File "C:\Users\DELL\anaconda3\envs\myenv\lib\asyncio\windows_events.py", line 316, in run_forever
    super().run_forever()
  File "C:\Users\DELL\anaconda3\envs\myenv\lib\asyncio\base_events.py", line 570, in run_forever
    self._run_once()
  File "C:\Users\DELL\anaconda3\envs\myenv\lib\asyncio\base_events.py", line 1859, in _run_once
    handle._run()
  File "C:\Users\DELL\anaconda3\envs\myenv\lib\asyncio\events.py", line 81, in _run
    self._context.run(self._callback, *self._args)
  File "C:\Users\DELL\AppData\Roaming\Python\Python38\site-packages\openfl\transport\grpc\director_server.py", line 226, in GetMetricStream
    logger.info(f'Request GetMetricStream for {request.experiment_name} experiment has got!')
  File "C:\Users\DELL\anaconda3\envs\myenv\lib\logging\__init__.py", line 1446, in info
    self._log(INFO, msg, args, **kwargs)
  File "C:\Users\DELL\anaconda3\envs\myenv\lib\logging\__init__.py", line 1589, in _log
    self.handle(record)
  File "C:\Users\DELL\anaconda3\envs\myenv\lib\logging\__init__.py", line 1599, in handle
    self.callHandlers(record)
  File "C:\Users\DELL\anaconda3\envs\myenv\lib\logging\__init__.py", line 1661, in callHandlers
    hdlr.handle(record)
  File "C:\Users\DELL\anaconda3\envs\myenv\lib\logging\__init__.py", line 954, in handle
    self.emit(record)
  File "C:\Users\DELL\AppData\Roaming\Python\Python38\site-packages\rich\logging.py", line 172, in emit
    self.handleError(record)
Message: 'Request GetMetricStream for AdaboostF_Fl_Chain experiment has got!'
Arguments: ()
--- Logging error ---
Traceback (most recent call last):
  File "C:\Users\DELL\AppData\Roaming\Python\Python38\site-packages\rich\logging.py", line 170, in emit
    self.console.print(log_renderable)
  File "C:\Users\DELL\AppData\Roaming\Python\Python38\site-packages\rich\console.py", line 1720, in print
    self._buffer.extend(new_segments)
  File "C:\Users\DELL\AppData\Roaming\Python\Python38\site-packages\rich\console.py", line 864, in __exit__
    self._exit_buffer()
  File "C:\Users\DELL\AppData\Roaming\Python\Python38\site-packages\rich\console.py", line 822, in _exit_buffer
    self._check_buffer()
  File "C:\Users\DELL\AppData\Roaming\Python\Python38\site-packages\rich\console.py", line 2027, in _check_buffer
    legacy_windows_render(buffer, LegacyWindowsTerm(self.file))
  File "C:\Users\DELL\AppData\Roaming\Python\Python38\site-packages\rich\_windows_renderer.py", line 19, in legacy_windows_render
    term.write_text(text)
  File "C:\Users\DELL\AppData\Roaming\Python\Python38\site-packages\rich\_win32_console.py", line 403, in write_text
    self.write(text)
[19:54:14] INFO     [19:54:14] INFO       File "C:\Users\DELL\anaconda3\envs\myenv\lib\encodings\cp1252.py", line 19, in encode
    return codecs.charmap_encode(input,self.errors,encoding_table)[0]
UnicodeEncodeError: 'charmap' codec can't encode character '\U0001f9ff' in position 0: character maps to <undefined>
Call stack:
  File "C:\Users\DELL\anaconda3\envs\myenv\lib\runpy.py", line 194, in _run_module_as_main
    return _run_code(code, main_globals, None,
  File "C:\Users\DELL\anaconda3\envs\myenv\lib\runpy.py", line 87, in _run_code
    exec(code, run_globals)
  File "C:\Users\DELL\anaconda3\envs\myenv\Scripts\fx.exe\__main__.py", line 7, in <module>
    sys.exit(entry())
  File "C:\Users\DELL\AppData\Roaming\Python\Python38\site-packages\openfl\interface\cli.py", line 212, in entry
    cli()
  File "C:\Users\DELL\AppData\Roaming\Python\Python38\site-packages\click\core.py", line 1137, in __call__
    return self.main(*args, **kwargs)
  File "C:\Users\DELL\AppData\Roaming\Python\Python38\site-packages\click\core.py", line 1062, in main
    rv = self.invoke(ctx)
  File "C:\Users\DELL\AppData\Roaming\Python\Python38\site-packages\click\core.py", line 1668, in invoke
    return _process_result(sub_ctx.command.invoke(sub_ctx))
  File "C:\Users\DELL\AppData\Roaming\Python\Python38\site-packages\click\core.py", line 1668, in invoke
    return _process_result(sub_ctx.command.invoke(sub_ctx))
  File "C:\Users\DELL\AppData\Roaming\Python\Python38\site-packages\click\core.py", line 1404, in invoke
    return ctx.invoke(self.callback, **ctx.params)
  File "C:\Users\DELL\AppData\Roaming\Python\Python38\site-packages\click\core.py", line 763, in invoke
    return __callback(*args, **kwargs)
  File "C:\Users\DELL\AppData\Roaming\Python\Python38\site-packages\openfl\interface\director.py", line 104, in start
    director_server.start()
  File "C:\Users\DELL\AppData\Roaming\Python\Python38\site-packages\openfl\transport\grpc\director_server.py", line 94, in start
    loop.run_until_complete(self._run_server())
  File "C:\Users\DELL\anaconda3\envs\myenv\lib\asyncio\base_events.py", line 603, in run_until_complete
    self.run_forever()
  File "C:\Users\DELL\anaconda3\envs\myenv\lib\asyncio\windows_events.py", line 316, in run_forever
    super().run_forever()
  File "C:\Users\DELL\anaconda3\envs\myenv\lib\asyncio\base_events.py", line 570, in run_forever
    self._run_once()
  File "C:\Users\DELL\anaconda3\envs\myenv\lib\asyncio\base_events.py", line 1859, in _run_once
    handle._run()
  File "C:\Users\DELL\anaconda3\envs\myenv\lib\asyncio\events.py", line 81, in _run
    self._context.run(self._callback, *self._args)
  File "C:\Users\DELL\AppData\Roaming\Python\Python38\site-packages\openfl\component\director\experiment.py", line 68, in start
    logger.info(f'New experiment {self.name} for '
  File "C:\Users\DELL\anaconda3\envs\myenv\lib\logging\__init__.py", line 1446, in info
    self._log(INFO, msg, args, **kwargs)
  File "C:\Users\DELL\anaconda3\envs\myenv\lib\logging\__init__.py", line 1589, in _log
    self.handle(record)
  File "C:\Users\DELL\anaconda3\envs\myenv\lib\logging\__init__.py", line 1599, in handle
    self.callHandlers(record)
  File "C:\Users\DELL\anaconda3\envs\myenv\lib\logging\__init__.py", line 1661, in callHandlers
    hdlr.handle(record)
  File "C:\Users\DELL\anaconda3\envs\myenv\lib\logging\__init__.py", line 954, in handle
    self.emit(record)
  File "C:\Users\DELL\AppData\Roaming\Python\Python38\site-packages\rich\logging.py", line 172, in emit
    self.handleError(record)
Message: "New experiment AdaboostF_Fl_Chain for collaborators ['envoy_1']"
Arguments: ()
--- Logging error ---
Traceback (most recent call last):
  File "C:\Users\DELL\AppData\Roaming\Python\Python38\site-packages\rich\logging.py", line 170, in emit
    self.console.print(log_renderable)
  File "C:\Users\DELL\AppData\Roaming\Python\Python38\site-packages\rich\console.py", line 1720, in print
    self._buffer.extend(new_segments)
  File "C:\Users\DELL\AppData\Roaming\Python\Python38\site-packages\rich\console.py", line 864, in __exit__
    self._exit_buffer()
  File "C:\Users\DELL\AppData\Roaming\Python\Python38\site-packages\rich\console.py", line 822, in _exit_buffer
    self._check_buffer()
  File "C:\Users\DELL\AppData\Roaming\Python\Python38\site-packages\rich\console.py", line 2027, in _check_buffer
    legacy_windows_render(buffer, LegacyWindowsTerm(self.file))
  File "C:\Users\DELL\AppData\Roaming\Python\Python38\site-packages\rich\_windows_renderer.py", line 19, in legacy_windows_render
    term.write_text(text)
  File "C:\Users\DELL\AppData\Roaming\Python\Python38\site-packages\rich\_win32_console.py", line 403, in write_text
    self.write(text)
  File "C:\Users\DELL\anaconda3\envs\myenv\lib\encodings\cp1252.py", line 19, in encode
    return codecs.charmap_encode(input,self.errors,encoding_table)[0]
UnicodeEncodeError: 'charmap' codec can't encode character '\U0001f9ff' in position 0: character maps to <undefined>
Call stack:
  File "C:\Users\DELL\anaconda3\envs\myenv\lib\runpy.py", line 194, in _run_module_as_main
    return _run_code(code, main_globals, None,
  File "C:\Users\DELL\anaconda3\envs\myenv\lib\runpy.py", line 87, in _run_code
    exec(code, run_globals)
  File "C:\Users\DELL\anaconda3\envs\myenv\Scripts\fx.exe\__main__.py", line 7, in <module>
    sys.exit(entry())
  File "C:\Users\DELL\AppData\Roaming\Python\Python38\site-packages\openfl\interface\cli.py", line 212, in entry
    cli()
  File "C:\Users\DELL\AppData\Roaming\Python\Python38\site-packages\click\core.py", line 1137, in __call__
    return self.main(*args, **kwargs)
  File "C:\Users\DELL\AppData\Roaming\Python\Python38\site-packages\click\core.py", line 1062, in main
    rv = self.invoke(ctx)
  File "C:\Users\DELL\AppData\Roaming\Python\Python38\site-packages\click\core.py", line 1668, in invoke
    return _process_result(sub_ctx.command.invoke(sub_ctx))
  File "C:\Users\DELL\AppData\Roaming\Python\Python38\site-packages\click\core.py", line 1668, in invoke
    return _process_result(sub_ctx.command.invoke(sub_ctx))
  File "C:\Users\DELL\AppData\Roaming\Python\Python38\site-packages\click\core.py", line 1404, in invoke
    return ctx.invoke(self.callback, **ctx.params)
  File "C:\Users\DELL\AppData\Roaming\Python\Python38\site-packages\click\core.py", line 763, in invoke
    return __callback(*args, **kwargs)
  File "C:\Users\DELL\AppData\Roaming\Python\Python38\site-packages\openfl\interface\director.py", line 104, in start
    director_server.start()
  File "C:\Users\DELL\AppData\Roaming\Python\Python38\site-packages\openfl\transport\grpc\director_server.py", line 94, in start
    loop.run_until_complete(self._run_server())
  File "C:\Users\DELL\anaconda3\envs\myenv\lib\asyncio\base_events.py", line 603, in run_until_complete
    self.run_forever()
  File "C:\Users\DELL\anaconda3\envs\myenv\lib\asyncio\windows_events.py", line 316, in run_forever
    super().run_forever()
  File "C:\Users\DELL\anaconda3\envs\myenv\lib\asyncio\base_events.py", line 570, in run_forever
    self._run_once()
  File "C:\Users\DELL\anaconda3\envs\myenv\lib\asyncio\base_events.py", line 1859, in _run_once
    handle._run()
  File "C:\Users\DELL\anaconda3\envs\myenv\lib\asyncio\events.py", line 81, in _run
    self._context.run(self._callback, *self._args)
  File "C:\Users\DELL\AppData\Roaming\Python\Python38\site-packages\openfl\component\director\experiment.py", line 72, in start
    aggregator_grpc_server = self._create_aggregator_grpc_server(
  File "C:\Users\DELL\AppData\Roaming\Python\Python38\site-packages\openfl\component\director\experiment.py", line 95, in _create_aggregator_grpc_server
    plan = Plan.parse(plan_config_path=Path(self.plan_path))
  File "C:\Users\DELL\AppData\Roaming\Python\Python38\site-packages\openfl\federated\plan\plan.py", line 140, in parse
    plan.resolve()
  File "C:\Users\DELL\AppData\Roaming\Python\Python38\site-packages\openfl\federated\plan\plan.py", line 242, in resolve
    self.federation_uuid = f'{self.name}_{self.hash[:8]}'
[19:54:14] INFO       File "C:\Users\DELL\AppData\Roaming\Python\Python38\site-packages\openfl\federated\plan\plan.py", line 235, in hash
    Plan.logger.info(f'FL-Plan hash is [blue]{self.hash_.hexdigest()}[/]',
  File "C:\Users\DELL\anaconda3\envs\myenv\lib\logging\__init__.py", line 1446, in info
    self._log(INFO, msg, args, **kwargs)
  File "C:\Users\DELL\anaconda3\envs\myenv\lib\logging\__init__.py", line 1589, in _log
    self.handle(record)
  File "C:\Users\DELL\anaconda3\envs\myenv\lib\logging\__init__.py", line 1599, in handle
    self.callHandlers(record)
  File "C:\Users\DELL\anaconda3\envs\myenv\lib\logging\__init__.py", line 1661, in callHandlers
    hdlr.handle(record)
  File "C:\Users\DELL\anaconda3\envs\myenv\lib\logging\__init__.py", line 954, in handle
    self.emit(record)
  File "C:\Users\DELL\AppData\Roaming\Python\Python38\site-packages\rich\logging.py", line 172, in emit
    self.handleError(record)
Message: 'FL-Plan hash is [blue]898d64eceeeb69f08cabd43927fd2ded03db109487f53e5b4b1d39d42f79b6836cfbf9c098ef545290993b8a434e8349[/]'
Arguments: ()
--- Logging error ---
Traceback (most recent call last):
  File "C:\Users\DELL\AppData\Roaming\Python\Python38\site-packages\rich\logging.py", line 170, in emit
    self.console.print(log_renderable)
  File "C:\Users\DELL\AppData\Roaming\Python\Python38\site-packages\rich\console.py", line 1720, in print
    self._buffer.extend(new_segments)
  File "C:\Users\DELL\AppData\Roaming\Python\Python38\site-packages\rich\console.py", line 864, in __exit__
    self._exit_buffer()
  File "C:\Users\DELL\AppData\Roaming\Python\Python38\site-packages\rich\console.py", line 822, in _exit_buffer
    self._check_buffer()
  File "C:\Users\DELL\AppData\Roaming\Python\Python38\site-packages\rich\console.py", line 2027, in _check_buffer
    legacy_windows_render(buffer, LegacyWindowsTerm(self.file))
  File "C:\Users\DELL\AppData\Roaming\Python\Python38\site-packages\rich\_windows_renderer.py", line 19, in legacy_windows_render
    term.write_text(text)
  File "C:\Users\DELL\AppData\Roaming\Python\Python38\site-packages\rich\_win32_console.py", line 403, in write_text
    self.write(text)
  File "C:\Users\DELL\anaconda3\envs\myenv\lib\encodings\cp1252.py", line 19, in encode
    return codecs.charmap_encode(input,self.errors,encoding_table)[0]
UnicodeEncodeError: 'charmap' codec can't encode character '\U0001f9ff' in position 0: character maps to <undefined>
Call stack:
  File "C:\Users\DELL\anaconda3\envs\myenv\lib\runpy.py", line 194, in _run_module_as_main
    return _run_code(code, main_globals, None,
  File "C:\Users\DELL\anaconda3\envs\myenv\lib\runpy.py", line 87, in _run_code
    exec(code, run_globals)
  File "C:\Users\DELL\anaconda3\envs\myenv\Scripts\fx.exe\__main__.py", line 7, in <module>
    sys.exit(entry())
  File "C:\Users\DELL\AppData\Roaming\Python\Python38\site-packages\openfl\interface\cli.py", line 212, in entry
    cli()
  File "C:\Users\DELL\AppData\Roaming\Python\Python38\site-packages\click\core.py", line 1137, in __call__
    return self.main(*args, **kwargs)
  File "C:\Users\DELL\AppData\Roaming\Python\Python38\site-packages\click\core.py", line 1062, in main
    rv = self.invoke(ctx)
  File "C:\Users\DELL\AppData\Roaming\Python\Python38\site-packages\click\core.py", line 1668, in invoke
    return _process_result(sub_ctx.command.invoke(sub_ctx))
  File "C:\Users\DELL\AppData\Roaming\Python\Python38\site-packages\click\core.py", line 1668, in invoke
    return _process_result(sub_ctx.command.invoke(sub_ctx))
  File "C:\Users\DELL\AppData\Roaming\Python\Python38\site-packages\click\core.py", line 1404, in invoke
    return ctx.invoke(self.callback, **ctx.params)
  File "C:\Users\DELL\AppData\Roaming\Python\Python38\site-packages\click\core.py", line 763, in invoke
    return __callback(*args, **kwargs)
  File "C:\Users\DELL\AppData\Roaming\Python\Python38\site-packages\openfl\interface\director.py", line 104, in start
    director_server.start()
  File "C:\Users\DELL\AppData\Roaming\Python\Python38\site-packages\openfl\transport\grpc\director_server.py", line 94, in start
    loop.run_until_complete(self._run_server())
  File "C:\Users\DELL\anaconda3\envs\myenv\lib\asyncio\base_events.py", line 603, in run_until_complete
    self.run_forever()
  File "C:\Users\DELL\anaconda3\envs\myenv\lib\asyncio\windows_events.py", line 316, in run_forever
    super().run_forever()
  File "C:\Users\DELL\anaconda3\envs\myenv\lib\asyncio\base_events.py", line 570, in run_forever
    self._run_once()
  File "C:\Users\DELL\anaconda3\envs\myenv\lib\asyncio\base_events.py", line 1859, in _run_once
    handle._run()
  File "C:\Users\DELL\anaconda3\envs\myenv\lib\asyncio\events.py", line 81, in _run
    self._context.run(self._callback, *self._args)
  File "C:\Users\DELL\AppData\Roaming\Python\Python38\site-packages\openfl\component\director\experiment.py", line 72, in start
    aggregator_grpc_server = self._create_aggregator_grpc_server(
  File "C:\Users\DELL\AppData\Roaming\Python\Python38\site-packages\openfl\component\director\experiment.py", line 95, in _create_aggregator_grpc_server
    plan = Plan.parse(plan_config_path=Path(self.plan_path))
  File "C:\Users\DELL\AppData\Roaming\Python\Python38\site-packages\openfl\federated\plan\plan.py", line 140, in parse
    plan.resolve()
  File "C:\Users\DELL\AppData\Roaming\Python\Python38\site-packages\openfl\federated\plan\plan.py", line 253, in resolve
    self.hash[:8], 16
  File "C:\Users\DELL\AppData\Roaming\Python\Python38\site-packages\openfl\federated\plan\plan.py", line 235, in hash
    Plan.logger.info(f'FL-Plan hash is [blue]{self.hash_.hexdigest()}[/]',
  File "C:\Users\DELL\anaconda3\envs\myenv\lib\logging\__init__.py", line 1446, in info
    self._log(INFO, msg, args, **kwargs)
  File "C:\Users\DELL\anaconda3\envs\myenv\lib\logging\__init__.py", line 1589, in _log
    self.handle(record)
  File "C:\Users\DELL\anaconda3\envs\myenv\lib\logging\__init__.py", line 1599, in handle
    self.callHandlers(record)
  File "C:\Users\DELL\anaconda3\envs\myenv\lib\logging\__init__.py", line 1661, in callHandlers
    hdlr.handle(record)
  File "C:\Users\DELL\anaconda3\envs\myenv\lib\logging\__init__.py", line 954, in handle
    self.emit(record)
  File "C:\Users\DELL\AppData\Roaming\Python\Python38\site-packages\rich\logging.py", line 172, in emit
    self.handleError(record)
Message: 'FL-Plan hash is [blue]898d64eceeeb69f08cabd43927fd2ded03db109487f53e5b4b1d39d42f79b6836cfbf9c098ef545290993b8a434e8349[/]'
Arguments: ()
--- Logging error ---
Traceback (most recent call last):
  File "C:\Users\DELL\AppData\Roaming\Python\Python38\site-packages\rich\logging.py", line 170, in emit
    self.console.print(log_renderable)
  File "C:\Users\DELL\AppData\Roaming\Python\Python38\site-packages\rich\console.py", line 1720, in print
    self._buffer.extend(new_segments)
  File "C:\Users\DELL\AppData\Roaming\Python\Python38\site-packages\rich\console.py", line 864, in __exit__
    self._exit_buffer()
  File "C:\Users\DELL\AppData\Roaming\Python\Python38\site-packages\rich\console.py", line 822, in _exit_buffer
    self._check_buffer()
  File "C:\Users\DELL\AppData\Roaming\Python\Python38\site-packages\rich\console.py", line 2027, in _check_buffer
    legacy_windows_render(buffer, LegacyWindowsTerm(self.file))
  File "C:\Users\DELL\AppData\Roaming\Python\Python38\site-packages\rich\_windows_renderer.py", line 19, in legacy_windows_render
    term.write_text(text)
  File "C:\Users\DELL\AppData\Roaming\Python\Python38\site-packages\rich\_win32_console.py", line 403, in write_text
    self.write(text)
  File "C:\Users\DELL\anaconda3\envs\myenv\lib\encodings\cp1252.py", line 19, in encode
    return codecs.charmap_encode(input,self.errors,encoding_table)[0]
UnicodeEncodeError: 'charmap' codec can't encode character '\U0001f9ff' in position 0: character maps to <undefined>
Call stack:
  File "C:\Users\DELL\anaconda3\envs\myenv\lib\runpy.py", line 194, in _run_module_as_main
    return _run_code(code, main_globals, None,
[19:54:14] INFO       File "C:\Users\DELL\anaconda3\envs\myenv\lib\runpy.py", line 87, in _run_code
    exec(code, run_globals)
  File "C:\Users\DELL\anaconda3\envs\myenv\Scripts\fx.exe\__main__.py", line 7, in <module>
    sys.exit(entry())
  File "C:\Users\DELL\AppData\Roaming\Python\Python38\site-packages\openfl\interface\cli.py", line 212, in entry
    cli()
  File "C:\Users\DELL\AppData\Roaming\Python\Python38\site-packages\click\core.py", line 1137, in __call__
    return self.main(*args, **kwargs)
  File "C:\Users\DELL\AppData\Roaming\Python\Python38\site-packages\click\core.py", line 1062, in main
    rv = self.invoke(ctx)
  File "C:\Users\DELL\AppData\Roaming\Python\Python38\site-packages\click\core.py", line 1668, in invoke
    return _process_result(sub_ctx.command.invoke(sub_ctx))
  File "C:\Users\DELL\AppData\Roaming\Python\Python38\site-packages\click\core.py", line 1668, in invoke
    return _process_result(sub_ctx.command.invoke(sub_ctx))
  File "C:\Users\DELL\AppData\Roaming\Python\Python38\site-packages\click\core.py", line 1404, in invoke
    return ctx.invoke(self.callback, **ctx.params)
  File "C:\Users\DELL\AppData\Roaming\Python\Python38\site-packages\click\core.py", line 763, in invoke
    return __callback(*args, **kwargs)
  File "C:\Users\DELL\AppData\Roaming\Python\Python38\site-packages\openfl\interface\director.py", line 104, in start
    director_server.start()
  File "C:\Users\DELL\AppData\Roaming\Python\Python38\site-packages\openfl\transport\grpc\director_server.py", line 94, in start
    loop.run_until_complete(self._run_server())
  File "C:\Users\DELL\anaconda3\envs\myenv\lib\asyncio\base_events.py", line 603, in run_until_complete
    self.run_forever()
  File "C:\Users\DELL\anaconda3\envs\myenv\lib\asyncio\windows_events.py", line 316, in run_forever
    super().run_forever()
  File "C:\Users\DELL\anaconda3\envs\myenv\lib\asyncio\base_events.py", line 570, in run_forever
    self._run_once()
  File "C:\Users\DELL\anaconda3\envs\myenv\lib\asyncio\base_events.py", line 1859, in _run_once
    handle._run()
  File "C:\Users\DELL\anaconda3\envs\myenv\lib\asyncio\events.py", line 81, in _run
    self._context.run(self._callback, *self._args)
  File "C:\Users\DELL\AppData\Roaming\Python\Python38\site-packages\openfl\component\director\experiment.py", line 72, in start
    aggregator_grpc_server = self._create_aggregator_grpc_server(
  File "C:\Users\DELL\AppData\Roaming\Python\Python38\site-packages\openfl\component\director\experiment.py", line 95, in _create_aggregator_grpc_server
    plan = Plan.parse(plan_config_path=Path(self.plan_path))
  File "C:\Users\DELL\AppData\Roaming\Python\Python38\site-packages\openfl\federated\plan\plan.py", line 142, in parse
    Plan.logger.info(
  File "C:\Users\DELL\anaconda3\envs\myenv\lib\logging\__init__.py", line 1446, in info
    self._log(INFO, msg, args, **kwargs)
  File "C:\Users\DELL\anaconda3\envs\myenv\lib\logging\__init__.py", line 1589, in _log
    self.handle(record)
  File "C:\Users\DELL\anaconda3\envs\myenv\lib\logging\__init__.py", line 1599, in handle
    self.callHandlers(record)
  File "C:\Users\DELL\anaconda3\envs\myenv\lib\logging\__init__.py", line 1661, in callHandlers
    hdlr.handle(record)
  File "C:\Users\DELL\anaconda3\envs\myenv\lib\logging\__init__.py", line 954, in handle
    self.emit(record)
  File "C:\Users\DELL\AppData\Roaming\Python\Python38\site-packages\rich\logging.py", line 172, in emit
    self.handleError(record)
Message: 'Parsing Federated Learning Plan : [green]SUCCESS[/] : [blue]plan\\plan.yaml[/].'
Arguments: ()
--- Logging error ---
Traceback (most recent call last):
  File "C:\Users\DELL\AppData\Roaming\Python\Python38\site-packages\rich\logging.py", line 170, in emit
    self.console.print(log_renderable)
  File "C:\Users\DELL\AppData\Roaming\Python\Python38\site-packages\rich\console.py", line 1720, in print
    self._buffer.extend(new_segments)
  File "C:\Users\DELL\AppData\Roaming\Python\Python38\site-packages\rich\console.py", line 864, in __exit__
    self._exit_buffer()
  File "C:\Users\DELL\AppData\Roaming\Python\Python38\site-packages\rich\console.py", line 822, in _exit_buffer
    self._check_buffer()
  File "C:\Users\DELL\AppData\Roaming\Python\Python38\site-packages\rich\console.py", line 2027, in _check_buffer
    legacy_windows_render(buffer, LegacyWindowsTerm(self.file))
  File "C:\Users\DELL\AppData\Roaming\Python\Python38\site-packages\rich\_windows_renderer.py", line 19, in legacy_windows_render
    term.write_text(text)
  File "C:\Users\DELL\AppData\Roaming\Python\Python38\site-packages\rich\_win32_console.py", line 403, in write_text
    self.write(text)
  File "C:\Users\DELL\anaconda3\envs\myenv\lib\encodings\cp1252.py", line 19, in encode
    return codecs.charmap_encode(input,self.errors,encoding_table)[0]
UnicodeEncodeError: 'charmap' codec can't encode character '\U0001f9ff' in position 0: character maps to <undefined>
Call stack:
  File "C:\Users\DELL\anaconda3\envs\myenv\lib\runpy.py", line 194, in _run_module_as_main
    return _run_code(code, main_globals, None,
  File "C:\Users\DELL\anaconda3\envs\myenv\lib\runpy.py", line 87, in _run_code
    exec(code, run_globals)
  File "C:\Users\DELL\anaconda3\envs\myenv\Scripts\fx.exe\__main__.py", line 7, in <module>
    sys.exit(entry())
  File "C:\Users\DELL\AppData\Roaming\Python\Python38\site-packages\openfl\interface\cli.py", line 212, in entry
    cli()
  File "C:\Users\DELL\AppData\Roaming\Python\Python38\site-packages\click\core.py", line 1137, in __call__
    return self.main(*args, **kwargs)
  File "C:\Users\DELL\AppData\Roaming\Python\Python38\site-packages\click\core.py", line 1062, in main
    rv = self.invoke(ctx)
  File "C:\Users\DELL\AppData\Roaming\Python\Python38\site-packages\click\core.py", line 1668, in invoke
    return _process_result(sub_ctx.command.invoke(sub_ctx))
  File "C:\Users\DELL\AppData\Roaming\Python\Python38\site-packages\click\core.py", line 1668, in invoke
    return _process_result(sub_ctx.command.invoke(sub_ctx))
  File "C:\Users\DELL\AppData\Roaming\Python\Python38\site-packages\click\core.py", line 1404, in invoke
    return ctx.invoke(self.callback, **ctx.params)
  File "C:\Users\DELL\AppData\Roaming\Python\Python38\site-packages\click\core.py", line 763, in invoke
    return __callback(*args, **kwargs)
  File "C:\Users\DELL\AppData\Roaming\Python\Python38\site-packages\openfl\interface\director.py", line 104, in start
    director_server.start()
  File "C:\Users\DELL\AppData\Roaming\Python\Python38\site-packages\openfl\transport\grpc\director_server.py", line 94, in start
    loop.run_until_complete(self._run_server())
  File "C:\Users\DELL\anaconda3\envs\myenv\lib\asyncio\base_events.py", line 603, in run_until_complete
    self.run_forever()
  File "C:\Users\DELL\anaconda3\envs\myenv\lib\asyncio\windows_events.py", line 316, in run_forever
    super().run_forever()
  File "C:\Users\DELL\anaconda3\envs\myenv\lib\asyncio\base_events.py", line 570, in run_forever
    self._run_once()
  File "C:\Users\DELL\anaconda3\envs\myenv\lib\asyncio\base_events.py", line 1859, in _run_once
    handle._run()
  File "C:\Users\DELL\anaconda3\envs\myenv\lib\asyncio\events.py", line 81, in _run
    self._context.run(self._callback, *self._args)
  File "C:\Users\DELL\AppData\Roaming\Python\Python38\site-packages\openfl\component\director\experiment.py", line 72, in start
    aggregator_grpc_server = self._create_aggregator_grpc_server(
  File "C:\Users\DELL\AppData\Roaming\Python\Python38\site-packages\openfl\component\director\experiment.py", line 95, in _create_aggregator_grpc_server
    plan = Plan.parse(plan_config_path=Path(self.plan_path))
  File "C:\Users\DELL\AppData\Roaming\Python\Python38\site-packages\openfl\federated\plan\plan.py", line 146, in parse
    Plan.logger.info(dump(plan.config))
  File "C:\Users\DELL\anaconda3\envs\myenv\lib\logging\__init__.py", line 1446, in info
    self._log(INFO, msg, args, **kwargs)
[19:54:14] INFO     [19:54:14] INFO       File "C:\Users\DELL\anaconda3\envs\myenv\lib\logging\__init__.py", line 1589, in _log
    self.handle(record)
  File "C:\Users\DELL\anaconda3\envs\myenv\lib\logging\__init__.py", line 1599, in handle
    self.callHandlers(record)
  File "C:\Users\DELL\anaconda3\envs\myenv\lib\logging\__init__.py", line 1661, in callHandlers
    hdlr.handle(record)
  File "C:\Users\DELL\anaconda3\envs\myenv\lib\logging\__init__.py", line 954, in handle
    self.emit(record)
  File "C:\Users\DELL\AppData\Roaming\Python\Python38\site-packages\rich\logging.py", line 172, in emit
    self.handleError(record)
Message: 'aggregator:\n  settings:\n    assigner: openfl.component.assigner.AdaBoostAssigner\n    best_state_path: save/best.pbuf\n    db_store_rounds: 1\n    init_state_path: save/init.pbuf\n    last_state_path: save/last.pbuf\n    nn: false\n    rounds_to_train: 300\n    write_logs: false\n  template: openfl.component.aggregator.Aggregator\napi_layer:\n  required_plugin_components:\n    serializer_plugin: openfl.plugins.interface_serializer.dill_serializer.DillSerializer\n  settings:\n    aggregation_function_interface_file: aggregation_function_obj.pkl\n    dataloader_interface_file: loader_obj.pkl\n    model_interface_file: model_obj.pkl\n    task_assigner_file: task_assigner_obj.pkl\n    tasks_interface_file: tasks_obj.pkl\nassigner:\n  settings:\n    task_groups:\n    - name: train_and_validate\n      percentage: 1.0\n      tasks:\n      - 1_train\n      - 2_weak_learners_validate\n      - 3_adaboost_update\n      - 4_adaboost_validate\n  template: openfl.component.assigner.AdaBoostAssigner\ncollaborator:\n  settings:\n    db_store_rounds: 2\n    delta_updates: false\n    device_assignment_policy: CPU_ONLY\n    nn: false\n    opt_treatment: CONTINUE_GLOBAL\n  template: openfl.component.collaborator.Collaborator\ncompression_pipeline:\n  settings:\n    nn: false\n  template: openfl.pipelines.GenericPipeline\nnetwork:\n  settings:\n    agg_addr: localhost\n    agg_port: 57791\n    cert_folder: cert\n    client_reconnect_interval: 5\n    disable_client_auth: false\n    hash_salt: auto\n    tls: false\n  template: openfl.federation.Network\ntask_runner:\n  required_plugin_components:\n    framework_adapters: openfl.plugins.frameworks_adapters.generic_adapter.GenericAdapter\n  settings: {}\n  template: openfl.federated.task.runner_generic.GenericTaskRunner\ntasks:\n  1_train:\n    aggregation_type: openfl.interface.aggregation_functions.AggregateRandomForest\n    function: train_adaboost\n    kwargs:\n      apply: global\n      data: train\n      retrieve: weak_learner\n  2_weak_learners_validate:\n    aggregation_type: openfl.interface.aggregation_functions.AggregateAdaboost\n    function: validate_weak_learners\n    kwargs:\n      apply: global\n      data: train\n      retrieve: model\n    n_classes: 2\n  3_adaboost_update:\n    aggregation_type: openfl.interface.aggregation_functions.WeightedAverage\n    function: adaboost_update\n    kwargs:\n      apply: global\n      retrieve: adaboost_coeff\n  4_adaboost_validate:\n    aggregation_type: openfl.interface.aggregation_functions.WeightedAverage\n    function: validate_adaboost\n    kwargs:\n      apply: local\n      data: test\n      retrieve: adaboost\n  settings: {}\n'
Arguments: ()
--- Logging error ---
Traceback (most recent call last):
  File "C:\Users\DELL\AppData\Roaming\Python\Python38\site-packages\rich\logging.py", line 170, in emit
    self.console.print(log_renderable)
  File "C:\Users\DELL\AppData\Roaming\Python\Python38\site-packages\rich\console.py", line 1720, in print
    self._buffer.extend(new_segments)
  File "C:\Users\DELL\AppData\Roaming\Python\Python38\site-packages\rich\console.py", line 864, in __exit__
    self._exit_buffer()
  File "C:\Users\DELL\AppData\Roaming\Python\Python38\site-packages\rich\console.py", line 822, in _exit_buffer
    self._check_buffer()
  File "C:\Users\DELL\AppData\Roaming\Python\Python38\site-packages\rich\console.py", line 2027, in _check_buffer
    legacy_windows_render(buffer, LegacyWindowsTerm(self.file))
  File "C:\Users\DELL\AppData\Roaming\Python\Python38\site-packages\rich\_windows_renderer.py", line 19, in legacy_windows_render
    term.write_text(text)
  File "C:\Users\DELL\AppData\Roaming\Python\Python38\site-packages\rich\_win32_console.py", line 403, in write_text
    self.write(text)
  File "C:\Users\DELL\anaconda3\envs\myenv\lib\encodings\cp1252.py", line 19, in encode
    return codecs.charmap_encode(input,self.errors,encoding_table)[0]
UnicodeEncodeError: 'charmap' codec can't encode character '\U0001f9ff' in position 0: character maps to <undefined>
Call stack:
  File "C:\Users\DELL\anaconda3\envs\myenv\lib\runpy.py", line 194, in _run_module_as_main
    return _run_code(code, main_globals, None,
  File "C:\Users\DELL\anaconda3\envs\myenv\lib\runpy.py", line 87, in _run_code
    exec(code, run_globals)
  File "C:\Users\DELL\anaconda3\envs\myenv\Scripts\fx.exe\__main__.py", line 7, in <module>
    sys.exit(entry())
  File "C:\Users\DELL\AppData\Roaming\Python\Python38\site-packages\openfl\interface\cli.py", line 212, in entry
    cli()
  File "C:\Users\DELL\AppData\Roaming\Python\Python38\site-packages\click\core.py", line 1137, in __call__
    return self.main(*args, **kwargs)
  File "C:\Users\DELL\AppData\Roaming\Python\Python38\site-packages\click\core.py", line 1062, in main
    rv = self.invoke(ctx)
  File "C:\Users\DELL\AppData\Roaming\Python\Python38\site-packages\click\core.py", line 1668, in invoke
    return _process_result(sub_ctx.command.invoke(sub_ctx))
  File "C:\Users\DELL\AppData\Roaming\Python\Python38\site-packages\click\core.py", line 1668, in invoke
    return _process_result(sub_ctx.command.invoke(sub_ctx))
  File "C:\Users\DELL\AppData\Roaming\Python\Python38\site-packages\click\core.py", line 1404, in invoke
    return ctx.invoke(self.callback, **ctx.params)
  File "C:\Users\DELL\AppData\Roaming\Python\Python38\site-packages\click\core.py", line 763, in invoke
    return __callback(*args, **kwargs)
  File "C:\Users\DELL\AppData\Roaming\Python\Python38\site-packages\openfl\interface\director.py", line 104, in start
    director_server.start()
  File "C:\Users\DELL\AppData\Roaming\Python\Python38\site-packages\openfl\transport\grpc\director_server.py", line 94, in start
    loop.run_until_complete(self._run_server())
  File "C:\Users\DELL\anaconda3\envs\myenv\lib\asyncio\base_events.py", line 603, in run_until_complete
    self.run_forever()
  File "C:\Users\DELL\anaconda3\envs\myenv\lib\asyncio\windows_events.py", line 316, in run_forever
    super().run_forever()
  File "C:\Users\DELL\anaconda3\envs\myenv\lib\asyncio\base_events.py", line 570, in run_forever
    self._run_once()
  File "C:\Users\DELL\anaconda3\envs\myenv\lib\asyncio\base_events.py", line 1859, in _run_once
    handle._run()
  File "C:\Users\DELL\anaconda3\envs\myenv\lib\asyncio\events.py", line 81, in _run
    self._context.run(self._callback, *self._args)
  File "C:\Users\DELL\AppData\Roaming\Python\Python38\site-packages\openfl\component\director\experiment.py", line 72, in start
    aggregator_grpc_server = self._create_aggregator_grpc_server(
  File "C:\Users\DELL\AppData\Roaming\Python\Python38\site-packages\openfl\component\director\experiment.py", line 98, in _create_aggregator_grpc_server
    logger.info('\U0001f9ff Starting the Aggregator Service.')
  File "C:\Users\DELL\anaconda3\envs\myenv\lib\logging\__init__.py", line 1446, in info
    self._log(INFO, msg, args, **kwargs)
  File "C:\Users\DELL\anaconda3\envs\myenv\lib\logging\__init__.py", line 1589, in _log
    self.handle(record)
  File "C:\Users\DELL\anaconda3\envs\myenv\lib\logging\__init__.py", line 1599, in handle
    self.callHandlers(record)
  File "C:\Users\DELL\anaconda3\envs\myenv\lib\logging\__init__.py", line 1661, in callHandlers
    hdlr.handle(record)
  File "C:\Users\DELL\anaconda3\envs\myenv\lib\logging\__init__.py", line 954, in handle
    self.emit(record)
[19:54:14] INFO       File "C:\Users\DELL\AppData\Roaming\Python\Python38\site-packages\rich\logging.py", line 172, in emit
    self.handleError(record)
Message: '\U0001f9ff Starting the Aggregator Service.'
Arguments: ()
--- Logging error ---
Traceback (most recent call last):
  File "C:\Users\DELL\AppData\Roaming\Python\Python38\site-packages\rich\logging.py", line 170, in emit
    self.console.print(log_renderable)
  File "C:\Users\DELL\AppData\Roaming\Python\Python38\site-packages\rich\console.py", line 1720, in print
    self._buffer.extend(new_segments)
  File "C:\Users\DELL\AppData\Roaming\Python\Python38\site-packages\rich\console.py", line 864, in __exit__
    self._exit_buffer()
  File "C:\Users\DELL\AppData\Roaming\Python\Python38\site-packages\rich\console.py", line 822, in _exit_buffer
    self._check_buffer()
  File "C:\Users\DELL\AppData\Roaming\Python\Python38\site-packages\rich\console.py", line 2027, in _check_buffer
    legacy_windows_render(buffer, LegacyWindowsTerm(self.file))
  File "C:\Users\DELL\AppData\Roaming\Python\Python38\site-packages\rich\_windows_renderer.py", line 19, in legacy_windows_render
    term.write_text(text)
  File "C:\Users\DELL\AppData\Roaming\Python\Python38\site-packages\rich\_win32_console.py", line 403, in write_text
    self.write(text)
  File "C:\Users\DELL\anaconda3\envs\myenv\lib\encodings\cp1252.py", line 19, in encode
    return codecs.charmap_encode(input,self.errors,encoding_table)[0]
UnicodeEncodeError: 'charmap' codec can't encode character '\U0001f9ff' in position 0: character maps to <undefined>
Call stack:
  File "C:\Users\DELL\anaconda3\envs\myenv\lib\runpy.py", line 194, in _run_module_as_main
    return _run_code(code, main_globals, None,
  File "C:\Users\DELL\anaconda3\envs\myenv\lib\runpy.py", line 87, in _run_code
    exec(code, run_globals)
  File "C:\Users\DELL\anaconda3\envs\myenv\Scripts\fx.exe\__main__.py", line 7, in <module>
    sys.exit(entry())
  File "C:\Users\DELL\AppData\Roaming\Python\Python38\site-packages\openfl\interface\cli.py", line 212, in entry
    cli()
  File "C:\Users\DELL\AppData\Roaming\Python\Python38\site-packages\click\core.py", line 1137, in __call__
    return self.main(*args, **kwargs)
  File "C:\Users\DELL\AppData\Roaming\Python\Python38\site-packages\click\core.py", line 1062, in main
    rv = self.invoke(ctx)
  File "C:\Users\DELL\AppData\Roaming\Python\Python38\site-packages\click\core.py", line 1668, in invoke
    return _process_result(sub_ctx.command.invoke(sub_ctx))
  File "C:\Users\DELL\AppData\Roaming\Python\Python38\site-packages\click\core.py", line 1668, in invoke
    return _process_result(sub_ctx.command.invoke(sub_ctx))
  File "C:\Users\DELL\AppData\Roaming\Python\Python38\site-packages\click\core.py", line 1404, in invoke
    return ctx.invoke(self.callback, **ctx.params)
  File "C:\Users\DELL\AppData\Roaming\Python\Python38\site-packages\click\core.py", line 763, in invoke
    return __callback(*args, **kwargs)
  File "C:\Users\DELL\AppData\Roaming\Python\Python38\site-packages\openfl\interface\director.py", line 104, in start
    director_server.start()
  File "C:\Users\DELL\AppData\Roaming\Python\Python38\site-packages\openfl\transport\grpc\director_server.py", line 94, in start
    loop.run_until_complete(self._run_server())
  File "C:\Users\DELL\anaconda3\envs\myenv\lib\asyncio\base_events.py", line 603, in run_until_complete
    self.run_forever()
  File "C:\Users\DELL\anaconda3\envs\myenv\lib\asyncio\windows_events.py", line 316, in run_forever
    super().run_forever()
  File "C:\Users\DELL\anaconda3\envs\myenv\lib\asyncio\base_events.py", line 570, in run_forever
    self._run_once()
  File "C:\Users\DELL\anaconda3\envs\myenv\lib\asyncio\base_events.py", line 1859, in _run_once
    handle._run()
  File "C:\Users\DELL\anaconda3\envs\myenv\lib\asyncio\events.py", line 81, in _run
    self._context.run(self._callback, *self._args)
  File "C:\Users\DELL\AppData\Roaming\Python\Python38\site-packages\openfl\component\director\experiment.py", line 72, in start
    aggregator_grpc_server = self._create_aggregator_grpc_server(
  File "C:\Users\DELL\AppData\Roaming\Python\Python38\site-packages\openfl\component\director\experiment.py", line 99, in _create_aggregator_grpc_server
    aggregator_grpc_server = plan.interactive_api_get_server(
  File "C:\Users\DELL\AppData\Roaming\Python\Python38\site-packages\openfl\federated\plan\plan.py", line 566, in interactive_api_get_server
    server_args['aggregator'] = self.get_aggregator(tensor_dict)
  File "C:\Users\DELL\AppData\Roaming\Python\Python38\site-packages\openfl\federated\plan\plan.py", line 324, in get_aggregator
    defaults[SETTINGS]['assigner'] = self.get_assigner(nn)
  File "C:\Users\DELL\AppData\Roaming\Python\Python38\site-packages\openfl\federated\plan\plan.py", line 261, in get_assigner
    aggregation_functions_by_task = self.restore_object('aggregation_function_obj.pkl')
  File "C:\Users\DELL\AppData\Roaming\Python\Python38\site-packages\openfl\federated\plan\plan.py", line 598, in restore_object
    serializer_plugin = self.get_serializer_plugin()
  File "C:\Users\DELL\AppData\Roaming\Python\Python38\site-packages\openfl\federated\plan\plan.py", line 593, in get_serializer_plugin
    self.serializer_ = Plan.build(serializer_plugin, kwargs)
  File "C:\Users\DELL\AppData\Roaming\Python\Python38\site-packages\openfl\federated\plan\plan.py", line 171, in build
    Plan.logger.info(f'Building [red]\U0001f846[/] Object [red]{class_name}[/] '
  File "C:\Users\DELL\anaconda3\envs\myenv\lib\logging\__init__.py", line 1446, in info
    self._log(INFO, msg, args, **kwargs)
  File "C:\Users\DELL\anaconda3\envs\myenv\lib\logging\__init__.py", line 1589, in _log
    self.handle(record)
  File "C:\Users\DELL\anaconda3\envs\myenv\lib\logging\__init__.py", line 1599, in handle
    self.callHandlers(record)
  File "C:\Users\DELL\anaconda3\envs\myenv\lib\logging\__init__.py", line 1661, in callHandlers
    hdlr.handle(record)
  File "C:\Users\DELL\anaconda3\envs\myenv\lib\logging\__init__.py", line 954, in handle
    self.emit(record)
  File "C:\Users\DELL\AppData\Roaming\Python\Python38\site-packages\rich\logging.py", line 172, in emit
    self.handleError(record)
Message: 'Building [red]\U0001f846[/] Object [red]DillSerializer[/] from [red]openfl.plugins.interface_serializer.dill_serializer[/] Module.'
Arguments: ()
--- Logging error ---
Traceback (most recent call last):
  File "C:\Users\DELL\AppData\Roaming\Python\Python38\site-packages\rich\logging.py", line 170, in emit
    self.console.print(log_renderable)
  File "C:\Users\DELL\AppData\Roaming\Python\Python38\site-packages\rich\console.py", line 1720, in print
    self._buffer.extend(new_segments)
  File "C:\Users\DELL\AppData\Roaming\Python\Python38\site-packages\rich\console.py", line 864, in __exit__
    self._exit_buffer()
  File "C:\Users\DELL\AppData\Roaming\Python\Python38\site-packages\rich\console.py", line 822, in _exit_buffer
    self._check_buffer()
  File "C:\Users\DELL\AppData\Roaming\Python\Python38\site-packages\rich\console.py", line 2027, in _check_buffer
    legacy_windows_render(buffer, LegacyWindowsTerm(self.file))
  File "C:\Users\DELL\AppData\Roaming\Python\Python38\site-packages\rich\_windows_renderer.py", line 19, in legacy_windows_render
    term.write_text(text)
  File "C:\Users\DELL\AppData\Roaming\Python\Python38\site-packages\rich\_win32_console.py", line 403, in write_text
    self.write(text)
  File "C:\Users\DELL\anaconda3\envs\myenv\lib\encodings\cp1252.py", line 19, in encode
    return codecs.charmap_encode(input,self.errors,encoding_table)[0]
UnicodeEncodeError: 'charmap' codec can't encode character '\U0001f9ff' in position 0: character maps to <undefined>
Call stack:
  File "C:\Users\DELL\anaconda3\envs\myenv\lib\runpy.py", line 194, in _run_module_as_main
    return _run_code(code, main_globals, None,
  File "C:\Users\DELL\anaconda3\envs\myenv\lib\runpy.py", line 87, in _run_code
    exec(code, run_globals)
[19:54:14] INFO     [19:54:14] INFO       File "C:\Users\DELL\anaconda3\envs\myenv\Scripts\fx.exe\__main__.py", line 7, in <module>
    sys.exit(entry())
  File "C:\Users\DELL\AppData\Roaming\Python\Python38\site-packages\openfl\interface\cli.py", line 212, in entry
    cli()
  File "C:\Users\DELL\AppData\Roaming\Python\Python38\site-packages\click\core.py", line 1137, in __call__
    return self.main(*args, **kwargs)
  File "C:\Users\DELL\AppData\Roaming\Python\Python38\site-packages\click\core.py", line 1062, in main
    rv = self.invoke(ctx)
  File "C:\Users\DELL\AppData\Roaming\Python\Python38\site-packages\click\core.py", line 1668, in invoke
    return _process_result(sub_ctx.command.invoke(sub_ctx))
  File "C:\Users\DELL\AppData\Roaming\Python\Python38\site-packages\click\core.py", line 1668, in invoke
    return _process_result(sub_ctx.command.invoke(sub_ctx))
  File "C:\Users\DELL\AppData\Roaming\Python\Python38\site-packages\click\core.py", line 1404, in invoke
    return ctx.invoke(self.callback, **ctx.params)
  File "C:\Users\DELL\AppData\Roaming\Python\Python38\site-packages\click\core.py", line 763, in invoke
    return __callback(*args, **kwargs)
  File "C:\Users\DELL\AppData\Roaming\Python\Python38\site-packages\openfl\interface\director.py", line 104, in start
    director_server.start()
  File "C:\Users\DELL\AppData\Roaming\Python\Python38\site-packages\openfl\transport\grpc\director_server.py", line 94, in start
    loop.run_until_complete(self._run_server())
  File "C:\Users\DELL\anaconda3\envs\myenv\lib\asyncio\base_events.py", line 603, in run_until_complete
    self.run_forever()
  File "C:\Users\DELL\anaconda3\envs\myenv\lib\asyncio\windows_events.py", line 316, in run_forever
    super().run_forever()
  File "C:\Users\DELL\anaconda3\envs\myenv\lib\asyncio\base_events.py", line 570, in run_forever
    self._run_once()
  File "C:\Users\DELL\anaconda3\envs\myenv\lib\asyncio\base_events.py", line 1859, in _run_once
    handle._run()
  File "C:\Users\DELL\anaconda3\envs\myenv\lib\asyncio\events.py", line 81, in _run
    self._context.run(self._callback, *self._args)
  File "C:\Users\DELL\AppData\Roaming\Python\Python38\site-packages\openfl\component\director\experiment.py", line 72, in start
    aggregator_grpc_server = self._create_aggregator_grpc_server(
  File "C:\Users\DELL\AppData\Roaming\Python\Python38\site-packages\openfl\component\director\experiment.py", line 99, in _create_aggregator_grpc_server
    aggregator_grpc_server = plan.interactive_api_get_server(
  File "C:\Users\DELL\AppData\Roaming\Python\Python38\site-packages\openfl\federated\plan\plan.py", line 566, in interactive_api_get_server
    server_args['aggregator'] = self.get_aggregator(tensor_dict)
  File "C:\Users\DELL\AppData\Roaming\Python\Python38\site-packages\openfl\federated\plan\plan.py", line 324, in get_aggregator
    defaults[SETTINGS]['assigner'] = self.get_assigner(nn)
  File "C:\Users\DELL\AppData\Roaming\Python\Python38\site-packages\openfl\federated\plan\plan.py", line 288, in get_assigner
    self.assigner_ = Plan.build(**defaults)
  File "C:\Users\DELL\AppData\Roaming\Python\Python38\site-packages\openfl\federated\plan\plan.py", line 171, in build
    Plan.logger.info(f'Building [red]\U0001f846[/] Object [red]{class_name}[/] '
  File "C:\Users\DELL\anaconda3\envs\myenv\lib\logging\__init__.py", line 1446, in info
    self._log(INFO, msg, args, **kwargs)
  File "C:\Users\DELL\anaconda3\envs\myenv\lib\logging\__init__.py", line 1589, in _log
    self.handle(record)
  File "C:\Users\DELL\anaconda3\envs\myenv\lib\logging\__init__.py", line 1599, in handle
    self.callHandlers(record)
  File "C:\Users\DELL\anaconda3\envs\myenv\lib\logging\__init__.py", line 1661, in callHandlers
    hdlr.handle(record)
  File "C:\Users\DELL\anaconda3\envs\myenv\lib\logging\__init__.py", line 954, in handle
    self.emit(record)
  File "C:\Users\DELL\AppData\Roaming\Python\Python38\site-packages\rich\logging.py", line 172, in emit
    self.handleError(record)
Message: 'Building [red]\U0001f846[/] Object [red]AdaBoostAssigner[/] from [red]openfl.component.assigner[/] Module.'
Arguments: ()
--- Logging error ---
Traceback (most recent call last):
  File "C:\Users\DELL\AppData\Roaming\Python\Python38\site-packages\rich\logging.py", line 170, in emit
    self.console.print(log_renderable)
  File "C:\Users\DELL\AppData\Roaming\Python\Python38\site-packages\rich\console.py", line 1720, in print
    self._buffer.extend(new_segments)
  File "C:\Users\DELL\AppData\Roaming\Python\Python38\site-packages\rich\console.py", line 864, in __exit__
    self._exit_buffer()
  File "C:\Users\DELL\AppData\Roaming\Python\Python38\site-packages\rich\console.py", line 822, in _exit_buffer
    self._check_buffer()
  File "C:\Users\DELL\AppData\Roaming\Python\Python38\site-packages\rich\console.py", line 2027, in _check_buffer
    legacy_windows_render(buffer, LegacyWindowsTerm(self.file))
  File "C:\Users\DELL\AppData\Roaming\Python\Python38\site-packages\rich\_windows_renderer.py", line 19, in legacy_windows_render
    term.write_text(text)
  File "C:\Users\DELL\AppData\Roaming\Python\Python38\site-packages\rich\_win32_console.py", line 403, in write_text
    self.write(text)
  File "C:\Users\DELL\anaconda3\envs\myenv\lib\encodings\cp1252.py", line 19, in encode
    return codecs.charmap_encode(input,self.errors,encoding_table)[0]
UnicodeEncodeError: 'charmap' codec can't encode character '\U0001f9ff' in position 0: character maps to <undefined>
Call stack:
  File "C:\Users\DELL\anaconda3\envs\myenv\lib\runpy.py", line 194, in _run_module_as_main
    return _run_code(code, main_globals, None,
  File "C:\Users\DELL\anaconda3\envs\myenv\lib\runpy.py", line 87, in _run_code
    exec(code, run_globals)
  File "C:\Users\DELL\anaconda3\envs\myenv\Scripts\fx.exe\__main__.py", line 7, in <module>
    sys.exit(entry())
  File "C:\Users\DELL\AppData\Roaming\Python\Python38\site-packages\openfl\interface\cli.py", line 212, in entry
    cli()
  File "C:\Users\DELL\AppData\Roaming\Python\Python38\site-packages\click\core.py", line 1137, in __call__
    return self.main(*args, **kwargs)
  File "C:\Users\DELL\AppData\Roaming\Python\Python38\site-packages\click\core.py", line 1062, in main
    rv = self.invoke(ctx)
  File "C:\Users\DELL\AppData\Roaming\Python\Python38\site-packages\click\core.py", line 1668, in invoke
    return _process_result(sub_ctx.command.invoke(sub_ctx))
  File "C:\Users\DELL\AppData\Roaming\Python\Python38\site-packages\click\core.py", line 1668, in invoke
    return _process_result(sub_ctx.command.invoke(sub_ctx))
  File "C:\Users\DELL\AppData\Roaming\Python\Python38\site-packages\click\core.py", line 1404, in invoke
    return ctx.invoke(self.callback, **ctx.params)
  File "C:\Users\DELL\AppData\Roaming\Python\Python38\site-packages\click\core.py", line 763, in invoke
    return __callback(*args, **kwargs)
  File "C:\Users\DELL\AppData\Roaming\Python\Python38\site-packages\openfl\interface\director.py", line 104, in start
    director_server.start()
  File "C:\Users\DELL\AppData\Roaming\Python\Python38\site-packages\openfl\transport\grpc\director_server.py", line 94, in start
    loop.run_until_complete(self._run_server())
  File "C:\Users\DELL\anaconda3\envs\myenv\lib\asyncio\base_events.py", line 603, in run_until_complete
    self.run_forever()
  File "C:\Users\DELL\anaconda3\envs\myenv\lib\asyncio\windows_events.py", line 316, in run_forever
    super().run_forever()
  File "C:\Users\DELL\anaconda3\envs\myenv\lib\asyncio\base_events.py", line 570, in run_forever
    self._run_once()
  File "C:\Users\DELL\anaconda3\envs\myenv\lib\asyncio\base_events.py", line 1859, in _run_once
    handle._run()
  File "C:\Users\DELL\anaconda3\envs\myenv\lib\asyncio\events.py", line 81, in _run
    self._context.run(self._callback, *self._args)
  File "C:\Users\DELL\AppData\Roaming\Python\Python38\site-packages\openfl\component\director\experiment.py", line 72, in start
    aggregator_grpc_server = self._create_aggregator_grpc_server(
[19:54:14] INFO       File "C:\Users\DELL\AppData\Roaming\Python\Python38\site-packages\openfl\component\director\experiment.py", line 99, in _create_aggregator_grpc_server
    aggregator_grpc_server = plan.interactive_api_get_server(
  File "C:\Users\DELL\AppData\Roaming\Python\Python38\site-packages\openfl\federated\plan\plan.py", line 566, in interactive_api_get_server
    server_args['aggregator'] = self.get_aggregator(tensor_dict)
  File "C:\Users\DELL\AppData\Roaming\Python\Python38\site-packages\openfl\federated\plan\plan.py", line 325, in get_aggregator
    defaults[SETTINGS]['compression_pipeline'] = self.get_tensor_pipe()
  File "C:\Users\DELL\AppData\Roaming\Python\Python38\site-packages\openfl\federated\plan\plan.py", line 353, in get_tensor_pipe
    self.pipe_ = Plan.build(**defaults)
  File "C:\Users\DELL\AppData\Roaming\Python\Python38\site-packages\openfl\federated\plan\plan.py", line 171, in build
    Plan.logger.info(f'Building [red]\U0001f846[/] Object [red]{class_name}[/] '
  File "C:\Users\DELL\anaconda3\envs\myenv\lib\logging\__init__.py", line 1446, in info
    self._log(INFO, msg, args, **kwargs)
  File "C:\Users\DELL\anaconda3\envs\myenv\lib\logging\__init__.py", line 1589, in _log
    self.handle(record)
  File "C:\Users\DELL\anaconda3\envs\myenv\lib\logging\__init__.py", line 1599, in handle
    self.callHandlers(record)
  File "C:\Users\DELL\anaconda3\envs\myenv\lib\logging\__init__.py", line 1661, in callHandlers
    hdlr.handle(record)
  File "C:\Users\DELL\anaconda3\envs\myenv\lib\logging\__init__.py", line 954, in handle
    self.emit(record)
  File "C:\Users\DELL\AppData\Roaming\Python\Python38\site-packages\rich\logging.py", line 172, in emit
    self.handleError(record)
Message: 'Building [red]\U0001f846[/] Object [red]GenericPipeline[/] from [red]openfl.pipelines[/] Module.'
Arguments: ()
--- Logging error ---
Traceback (most recent call last):
  File "C:\Users\DELL\AppData\Roaming\Python\Python38\site-packages\rich\logging.py", line 170, in emit
    self.console.print(log_renderable)
  File "C:\Users\DELL\AppData\Roaming\Python\Python38\site-packages\rich\console.py", line 1720, in print
    self._buffer.extend(new_segments)
  File "C:\Users\DELL\AppData\Roaming\Python\Python38\site-packages\rich\console.py", line 864, in __exit__
    self._exit_buffer()
  File "C:\Users\DELL\AppData\Roaming\Python\Python38\site-packages\rich\console.py", line 822, in _exit_buffer
    self._check_buffer()
  File "C:\Users\DELL\AppData\Roaming\Python\Python38\site-packages\rich\console.py", line 2027, in _check_buffer
    legacy_windows_render(buffer, LegacyWindowsTerm(self.file))
  File "C:\Users\DELL\AppData\Roaming\Python\Python38\site-packages\rich\_windows_renderer.py", line 19, in legacy_windows_render
    term.write_text(text)
  File "C:\Users\DELL\AppData\Roaming\Python\Python38\site-packages\rich\_win32_console.py", line 403, in write_text
    self.write(text)
  File "C:\Users\DELL\anaconda3\envs\myenv\lib\encodings\cp1252.py", line 19, in encode
    return codecs.charmap_encode(input,self.errors,encoding_table)[0]
UnicodeEncodeError: 'charmap' codec can't encode character '\U0001f9ff' in position 0: character maps to <undefined>
Call stack:
  File "C:\Users\DELL\anaconda3\envs\myenv\lib\runpy.py", line 194, in _run_module_as_main
    return _run_code(code, main_globals, None,
  File "C:\Users\DELL\anaconda3\envs\myenv\lib\runpy.py", line 87, in _run_code
    exec(code, run_globals)
  File "C:\Users\DELL\anaconda3\envs\myenv\Scripts\fx.exe\__main__.py", line 7, in <module>
    sys.exit(entry())
  File "C:\Users\DELL\AppData\Roaming\Python\Python38\site-packages\openfl\interface\cli.py", line 212, in entry
    cli()
  File "C:\Users\DELL\AppData\Roaming\Python\Python38\site-packages\click\core.py", line 1137, in __call__
    return self.main(*args, **kwargs)
  File "C:\Users\DELL\AppData\Roaming\Python\Python38\site-packages\click\core.py", line 1062, in main
    rv = self.invoke(ctx)
  File "C:\Users\DELL\AppData\Roaming\Python\Python38\site-packages\click\core.py", line 1668, in invoke
    return _process_result(sub_ctx.command.invoke(sub_ctx))
  File "C:\Users\DELL\AppData\Roaming\Python\Python38\site-packages\click\core.py", line 1668, in invoke
    return _process_result(sub_ctx.command.invoke(sub_ctx))
  File "C:\Users\DELL\AppData\Roaming\Python\Python38\site-packages\click\core.py", line 1404, in invoke
    return ctx.invoke(self.callback, **ctx.params)
  File "C:\Users\DELL\AppData\Roaming\Python\Python38\site-packages\click\core.py", line 763, in invoke
    return __callback(*args, **kwargs)
  File "C:\Users\DELL\AppData\Roaming\Python\Python38\site-packages\openfl\interface\director.py", line 104, in start
    director_server.start()
  File "C:\Users\DELL\AppData\Roaming\Python\Python38\site-packages\openfl\transport\grpc\director_server.py", line 94, in start
    loop.run_until_complete(self._run_server())
  File "C:\Users\DELL\anaconda3\envs\myenv\lib\asyncio\base_events.py", line 603, in run_until_complete
    self.run_forever()
  File "C:\Users\DELL\anaconda3\envs\myenv\lib\asyncio\windows_events.py", line 316, in run_forever
    super().run_forever()
  File "C:\Users\DELL\anaconda3\envs\myenv\lib\asyncio\base_events.py", line 570, in run_forever
    self._run_once()
  File "C:\Users\DELL\anaconda3\envs\myenv\lib\asyncio\base_events.py", line 1859, in _run_once
    handle._run()
  File "C:\Users\DELL\anaconda3\envs\myenv\lib\asyncio\events.py", line 81, in _run
    self._context.run(self._callback, *self._args)
  File "C:\Users\DELL\AppData\Roaming\Python\Python38\site-packages\openfl\component\director\experiment.py", line 72, in start
    aggregator_grpc_server = self._create_aggregator_grpc_server(
  File "C:\Users\DELL\AppData\Roaming\Python\Python38\site-packages\openfl\component\director\experiment.py", line 99, in _create_aggregator_grpc_server
    aggregator_grpc_server = plan.interactive_api_get_server(
  File "C:\Users\DELL\AppData\Roaming\Python\Python38\site-packages\openfl\federated\plan\plan.py", line 566, in interactive_api_get_server
    server_args['aggregator'] = self.get_aggregator(tensor_dict)
  File "C:\Users\DELL\AppData\Roaming\Python\Python38\site-packages\openfl\federated\plan\plan.py", line 326, in get_aggregator
    defaults[SETTINGS]['straggler_handling_policy'] = self.get_straggler_handling_policy()
  File "C:\Users\DELL\AppData\Roaming\Python\Python38\site-packages\openfl\federated\plan\plan.py", line 368, in get_straggler_handling_policy
    self.straggler_policy_ = Plan.build(**defaults)
  File "C:\Users\DELL\AppData\Roaming\Python\Python38\site-packages\openfl\federated\plan\plan.py", line 171, in build
    Plan.logger.info(f'Building [red]\U0001f846[/] Object [red]{class_name}[/] '
  File "C:\Users\DELL\anaconda3\envs\myenv\lib\logging\__init__.py", line 1446, in info
    self._log(INFO, msg, args, **kwargs)
  File "C:\Users\DELL\anaconda3\envs\myenv\lib\logging\__init__.py", line 1589, in _log
    self.handle(record)
  File "C:\Users\DELL\anaconda3\envs\myenv\lib\logging\__init__.py", line 1599, in handle
    self.callHandlers(record)
  File "C:\Users\DELL\anaconda3\envs\myenv\lib\logging\__init__.py", line 1661, in callHandlers
    hdlr.handle(record)
  File "C:\Users\DELL\anaconda3\envs\myenv\lib\logging\__init__.py", line 954, in handle
    self.emit(record)
  File "C:\Users\DELL\AppData\Roaming\Python\Python38\site-packages\rich\logging.py", line 172, in emit
    self.handleError(record)
Message: 'Building [red]\U0001f846[/] Object [red]CutoffTimeBasedStragglerHandling[/] from [red]openfl.component.straggler_handling_functions[/] Module.'
Arguments: ()
--- Logging error ---
Traceback (most recent call last):
  File "C:\Users\DELL\AppData\Roaming\Python\Python38\site-packages\rich\logging.py", line 170, in emit
    self.console.print(log_renderable)
  File "C:\Users\DELL\AppData\Roaming\Python\Python38\site-packages\rich\console.py", line 1720, in print
    self._buffer.extend(new_segments)
[19:54:14] INFO     [19:54:14] INFO       File "C:\Users\DELL\AppData\Roaming\Python\Python38\site-packages\rich\console.py", line 864, in __exit__
    self._exit_buffer()
  File "C:\Users\DELL\AppData\Roaming\Python\Python38\site-packages\rich\console.py", line 822, in _exit_buffer
    self._check_buffer()
  File "C:\Users\DELL\AppData\Roaming\Python\Python38\site-packages\rich\console.py", line 2027, in _check_buffer
    legacy_windows_render(buffer, LegacyWindowsTerm(self.file))
  File "C:\Users\DELL\AppData\Roaming\Python\Python38\site-packages\rich\_windows_renderer.py", line 19, in legacy_windows_render
    term.write_text(text)
  File "C:\Users\DELL\AppData\Roaming\Python\Python38\site-packages\rich\_win32_console.py", line 403, in write_text
    self.write(text)
  File "C:\Users\DELL\anaconda3\envs\myenv\lib\encodings\cp1252.py", line 19, in encode
    return codecs.charmap_encode(input,self.errors,encoding_table)[0]
UnicodeEncodeError: 'charmap' codec can't encode character '\U0001f9ff' in position 0: character maps to <undefined>
Call stack:
  File "C:\Users\DELL\anaconda3\envs\myenv\lib\runpy.py", line 194, in _run_module_as_main
    return _run_code(code, main_globals, None,
  File "C:\Users\DELL\anaconda3\envs\myenv\lib\runpy.py", line 87, in _run_code
    exec(code, run_globals)
  File "C:\Users\DELL\anaconda3\envs\myenv\Scripts\fx.exe\__main__.py", line 7, in <module>
    sys.exit(entry())
  File "C:\Users\DELL\AppData\Roaming\Python\Python38\site-packages\openfl\interface\cli.py", line 212, in entry
    cli()
  File "C:\Users\DELL\AppData\Roaming\Python\Python38\site-packages\click\core.py", line 1137, in __call__
    return self.main(*args, **kwargs)
  File "C:\Users\DELL\AppData\Roaming\Python\Python38\site-packages\click\core.py", line 1062, in main
    rv = self.invoke(ctx)
  File "C:\Users\DELL\AppData\Roaming\Python\Python38\site-packages\click\core.py", line 1668, in invoke
    return _process_result(sub_ctx.command.invoke(sub_ctx))
  File "C:\Users\DELL\AppData\Roaming\Python\Python38\site-packages\click\core.py", line 1668, in invoke
    return _process_result(sub_ctx.command.invoke(sub_ctx))
  File "C:\Users\DELL\AppData\Roaming\Python\Python38\site-packages\click\core.py", line 1404, in invoke
    return ctx.invoke(self.callback, **ctx.params)
  File "C:\Users\DELL\AppData\Roaming\Python\Python38\site-packages\click\core.py", line 763, in invoke
    return __callback(*args, **kwargs)
  File "C:\Users\DELL\AppData\Roaming\Python\Python38\site-packages\openfl\interface\director.py", line 104, in start
    director_server.start()
  File "C:\Users\DELL\AppData\Roaming\Python\Python38\site-packages\openfl\transport\grpc\director_server.py", line 94, in start
    loop.run_until_complete(self._run_server())
  File "C:\Users\DELL\anaconda3\envs\myenv\lib\asyncio\base_events.py", line 603, in run_until_complete
    self.run_forever()
  File "C:\Users\DELL\anaconda3\envs\myenv\lib\asyncio\windows_events.py", line 316, in run_forever
    super().run_forever()
  File "C:\Users\DELL\anaconda3\envs\myenv\lib\asyncio\base_events.py", line 570, in run_forever
    self._run_once()
  File "C:\Users\DELL\anaconda3\envs\myenv\lib\asyncio\base_events.py", line 1859, in _run_once
    handle._run()
  File "C:\Users\DELL\anaconda3\envs\myenv\lib\asyncio\events.py", line 81, in _run
    self._context.run(self._callback, *self._args)
  File "C:\Users\DELL\AppData\Roaming\Python\Python38\site-packages\openfl\component\director\experiment.py", line 72, in start
    aggregator_grpc_server = self._create_aggregator_grpc_server(
  File "C:\Users\DELL\AppData\Roaming\Python\Python38\site-packages\openfl\component\director\experiment.py", line 99, in _create_aggregator_grpc_server
    aggregator_grpc_server = plan.interactive_api_get_server(
  File "C:\Users\DELL\AppData\Roaming\Python\Python38\site-packages\openfl\federated\plan\plan.py", line 566, in interactive_api_get_server
    server_args['aggregator'] = self.get_aggregator(tensor_dict)
  File "C:\Users\DELL\AppData\Roaming\Python\Python38\site-packages\openfl\federated\plan\plan.py", line 338, in get_aggregator
    self.aggregator_ = Plan.build(**defaults, initial_tensor_dict=tensor_dict)
  File "C:\Users\DELL\AppData\Roaming\Python\Python38\site-packages\openfl\federated\plan\plan.py", line 171, in build
    Plan.logger.info(f'Building [red]\U0001f846[/] Object [red]{class_name}[/] '
  File "C:\Users\DELL\anaconda3\envs\myenv\lib\logging\__init__.py", line 1446, in info
    self._log(INFO, msg, args, **kwargs)
  File "C:\Users\DELL\anaconda3\envs\myenv\lib\logging\__init__.py", line 1589, in _log
    self.handle(record)
  File "C:\Users\DELL\anaconda3\envs\myenv\lib\logging\__init__.py", line 1599, in handle
    self.callHandlers(record)
  File "C:\Users\DELL\anaconda3\envs\myenv\lib\logging\__init__.py", line 1661, in callHandlers
    hdlr.handle(record)
  File "C:\Users\DELL\anaconda3\envs\myenv\lib\logging\__init__.py", line 954, in handle
    self.emit(record)
  File "C:\Users\DELL\AppData\Roaming\Python\Python38\site-packages\rich\logging.py", line 172, in emit
    self.handleError(record)
Message: 'Building [red]\U0001f846[/] Object [red]Aggregator[/] from [red]openfl.component.aggregator[/] Module.'
Arguments: ()
--- Logging error ---
Traceback (most recent call last):
  File "C:\Users\DELL\AppData\Roaming\Python\Python38\site-packages\rich\logging.py", line 170, in emit
    self.console.print(log_renderable)
  File "C:\Users\DELL\AppData\Roaming\Python\Python38\site-packages\rich\console.py", line 1720, in print
    self._buffer.extend(new_segments)
  File "C:\Users\DELL\AppData\Roaming\Python\Python38\site-packages\rich\console.py", line 864, in __exit__
    self._exit_buffer()
  File "C:\Users\DELL\AppData\Roaming\Python\Python38\site-packages\rich\console.py", line 822, in _exit_buffer
    self._check_buffer()
  File "C:\Users\DELL\AppData\Roaming\Python\Python38\site-packages\rich\console.py", line 2027, in _check_buffer
    legacy_windows_render(buffer, LegacyWindowsTerm(self.file))
  File "C:\Users\DELL\AppData\Roaming\Python\Python38\site-packages\rich\_windows_renderer.py", line 19, in legacy_windows_render
    term.write_text(text)
  File "C:\Users\DELL\AppData\Roaming\Python\Python38\site-packages\rich\_win32_console.py", line 403, in write_text
    self.write(text)
  File "C:\Users\DELL\anaconda3\envs\myenv\lib\encodings\cp1252.py", line 19, in encode
    return codecs.charmap_encode(input,self.errors,encoding_table)[0]
UnicodeEncodeError: 'charmap' codec can't encode character '\U0001f9ff' in position 0: character maps to <undefined>
Call stack:
  File "C:\Users\DELL\anaconda3\envs\myenv\lib\runpy.py", line 194, in _run_module_as_main
    return _run_code(code, main_globals, None,
  File "C:\Users\DELL\anaconda3\envs\myenv\lib\runpy.py", line 87, in _run_code
    exec(code, run_globals)
  File "C:\Users\DELL\anaconda3\envs\myenv\Scripts\fx.exe\__main__.py", line 7, in <module>
    sys.exit(entry())
  File "C:\Users\DELL\AppData\Roaming\Python\Python38\site-packages\openfl\interface\cli.py", line 212, in entry
    cli()
  File "C:\Users\DELL\AppData\Roaming\Python\Python38\site-packages\click\core.py", line 1137, in __call__
    return self.main(*args, **kwargs)
  File "C:\Users\DELL\AppData\Roaming\Python\Python38\site-packages\click\core.py", line 1062, in main
    rv = self.invoke(ctx)
  File "C:\Users\DELL\AppData\Roaming\Python\Python38\site-packages\click\core.py", line 1668, in invoke
    return _process_result(sub_ctx.command.invoke(sub_ctx))
  File "C:\Users\DELL\AppData\Roaming\Python\Python38\site-packages\click\core.py", line 1668, in invoke
    return _process_result(sub_ctx.command.invoke(sub_ctx))
  File "C:\Users\DELL\AppData\Roaming\Python\Python38\site-packages\click\core.py", line 1404, in invoke
    return ctx.invoke(self.callback, **ctx.params)
  File "C:\Users\DELL\AppData\Roaming\Python\Python38\site-packages\click\core.py", line 763, in invoke
    return __callback(*args, **kwargs)
[19:54:14] INFO       File "C:\Users\DELL\AppData\Roaming\Python\Python38\site-packages\openfl\interface\director.py", line 104, in start
    director_server.start()
  File "C:\Users\DELL\AppData\Roaming\Python\Python38\site-packages\openfl\transport\grpc\director_server.py", line 94, in start
    loop.run_until_complete(self._run_server())
  File "C:\Users\DELL\anaconda3\envs\myenv\lib\asyncio\base_events.py", line 603, in run_until_complete
    self.run_forever()
  File "C:\Users\DELL\anaconda3\envs\myenv\lib\asyncio\windows_events.py", line 316, in run_forever
    super().run_forever()
  File "C:\Users\DELL\anaconda3\envs\myenv\lib\asyncio\base_events.py", line 570, in run_forever
    self._run_once()
  File "C:\Users\DELL\anaconda3\envs\myenv\lib\asyncio\base_events.py", line 1859, in _run_once
    handle._run()
  File "C:\Users\DELL\anaconda3\envs\myenv\lib\asyncio\events.py", line 81, in _run
    self._context.run(self._callback, *self._args)
  File "C:\Users\DELL\AppData\Roaming\Python\Python38\site-packages\openfl\component\director\experiment.py", line 79, in start
    await self._run_aggregator_grpc_server(
  File "C:\Users\DELL\AppData\Roaming\Python\Python38\site-packages\openfl\component\director\experiment.py", line 111, in _run_aggregator_grpc_server
    logger.info('\U0001f9ff Starting the Aggregator Service.')
  File "C:\Users\DELL\anaconda3\envs\myenv\lib\logging\__init__.py", line 1446, in info
    self._log(INFO, msg, args, **kwargs)
  File "C:\Users\DELL\anaconda3\envs\myenv\lib\logging\__init__.py", line 1589, in _log
    self.handle(record)
  File "C:\Users\DELL\anaconda3\envs\myenv\lib\logging\__init__.py", line 1599, in handle
    self.callHandlers(record)
  File "C:\Users\DELL\anaconda3\envs\myenv\lib\logging\__init__.py", line 1661, in callHandlers
    hdlr.handle(record)
  File "C:\Users\DELL\anaconda3\envs\myenv\lib\logging\__init__.py", line 954, in handle
    self.emit(record)
  File "C:\Users\DELL\AppData\Roaming\Python\Python38\site-packages\rich\logging.py", line 172, in emit
    self.handleError(record)
Message: '\U0001f9ff Starting the Aggregator Service.'
Arguments: ()
--- Logging error ---
Traceback (most recent call last):
  File "C:\Users\DELL\AppData\Roaming\Python\Python38\site-packages\rich\logging.py", line 170, in emit
    self.console.print(log_renderable)
  File "C:\Users\DELL\AppData\Roaming\Python\Python38\site-packages\rich\console.py", line 1720, in print
    self._buffer.extend(new_segments)
  File "C:\Users\DELL\AppData\Roaming\Python\Python38\site-packages\rich\console.py", line 864, in __exit__
    self._exit_buffer()
  File "C:\Users\DELL\AppData\Roaming\Python\Python38\site-packages\rich\console.py", line 822, in _exit_buffer
    self._check_buffer()
  File "C:\Users\DELL\AppData\Roaming\Python\Python38\site-packages\rich\console.py", line 2027, in _check_buffer
    legacy_windows_render(buffer, LegacyWindowsTerm(self.file))
  File "C:\Users\DELL\AppData\Roaming\Python\Python38\site-packages\rich\_windows_renderer.py", line 19, in legacy_windows_render
    term.write_text(text)
  File "C:\Users\DELL\AppData\Roaming\Python\Python38\site-packages\rich\_win32_console.py", line 403, in write_text
    self.write(text)
  File "C:\Users\DELL\anaconda3\envs\myenv\lib\encodings\cp1252.py", line 19, in encode
    return codecs.charmap_encode(input,self.errors,encoding_table)[0]
UnicodeEncodeError: 'charmap' codec can't encode character '\U0001f9ff' in position 0: character maps to <undefined>
Call stack:
  File "C:\Users\DELL\anaconda3\envs\myenv\lib\runpy.py", line 194, in _run_module_as_main
    return _run_code(code, main_globals, None,
  File "C:\Users\DELL\anaconda3\envs\myenv\lib\runpy.py", line 87, in _run_code
    exec(code, run_globals)
  File "C:\Users\DELL\anaconda3\envs\myenv\Scripts\fx.exe\__main__.py", line 7, in <module>
    sys.exit(entry())
  File "C:\Users\DELL\AppData\Roaming\Python\Python38\site-packages\openfl\interface\cli.py", line 212, in entry
    cli()
  File "C:\Users\DELL\AppData\Roaming\Python\Python38\site-packages\click\core.py", line 1137, in __call__
    return self.main(*args, **kwargs)
  File "C:\Users\DELL\AppData\Roaming\Python\Python38\site-packages\click\core.py", line 1062, in main
    rv = self.invoke(ctx)
  File "C:\Users\DELL\AppData\Roaming\Python\Python38\site-packages\click\core.py", line 1668, in invoke
    return _process_result(sub_ctx.command.invoke(sub_ctx))
  File "C:\Users\DELL\AppData\Roaming\Python\Python38\site-packages\click\core.py", line 1668, in invoke
    return _process_result(sub_ctx.command.invoke(sub_ctx))
  File "C:\Users\DELL\AppData\Roaming\Python\Python38\site-packages\click\core.py", line 1404, in invoke
    return ctx.invoke(self.callback, **ctx.params)
  File "C:\Users\DELL\AppData\Roaming\Python\Python38\site-packages\click\core.py", line 763, in invoke
    return __callback(*args, **kwargs)
  File "C:\Users\DELL\AppData\Roaming\Python\Python38\site-packages\openfl\interface\director.py", line 104, in start
    director_server.start()
  File "C:\Users\DELL\AppData\Roaming\Python\Python38\site-packages\openfl\transport\grpc\director_server.py", line 94, in start
    loop.run_until_complete(self._run_server())
  File "C:\Users\DELL\anaconda3\envs\myenv\lib\asyncio\base_events.py", line 603, in run_until_complete
    self.run_forever()
  File "C:\Users\DELL\anaconda3\envs\myenv\lib\asyncio\windows_events.py", line 316, in run_forever
    super().run_forever()
  File "C:\Users\DELL\anaconda3\envs\myenv\lib\asyncio\base_events.py", line 570, in run_forever
    self._run_once()
  File "C:\Users\DELL\anaconda3\envs\myenv\lib\asyncio\base_events.py", line 1859, in _run_once
    handle._run()
  File "C:\Users\DELL\anaconda3\envs\myenv\lib\asyncio\events.py", line 81, in _run
    self._context.run(self._callback, *self._args)
  File "C:\Users\DELL\AppData\Roaming\Python\Python38\site-packages\openfl\component\director\experiment.py", line 79, in start
    await self._run_aggregator_grpc_server(
  File "C:\Users\DELL\AppData\Roaming\Python\Python38\site-packages\openfl\component\director\experiment.py", line 112, in _run_aggregator_grpc_server
    grpc_server = aggregator_grpc_server.get_server()
  File "C:\Users\DELL\AppData\Roaming\Python\Python38\site-packages\openfl\transport\grpc\aggregator_server.py", line 258, in get_server
    self.logger.warn(
  File "C:\Users\DELL\anaconda3\envs\myenv\lib\logging\__init__.py", line 1463, in warn
    self.warning(msg, *args, **kwargs)
  File "C:\Users\DELL\anaconda3\envs\myenv\lib\logging\__init__.py", line 1458, in warning
    self._log(WARNING, msg, args, **kwargs)
  File "C:\Users\DELL\anaconda3\envs\myenv\lib\logging\__init__.py", line 1589, in _log
    self.handle(record)
  File "C:\Users\DELL\anaconda3\envs\myenv\lib\logging\__init__.py", line 1599, in handle
    self.callHandlers(record)
  File "C:\Users\DELL\anaconda3\envs\myenv\lib\logging\__init__.py", line 1661, in callHandlers
    hdlr.handle(record)
  File "C:\Users\DELL\anaconda3\envs\myenv\lib\logging\__init__.py", line 954, in handle
    self.emit(record)
  File "C:\Users\DELL\AppData\Roaming\Python\Python38\site-packages\rich\logging.py", line 172, in emit
    self.handleError(record)
Message: 'gRPC is running on insecure channel with TLS disabled.'
Arguments: ()
--- Logging error ---
Traceback (most recent call last):
  File "C:\Users\DELL\AppData\Roaming\Python\Python38\site-packages\rich\logging.py", line 170, in emit
    self.console.print(log_renderable)
  File "C:\Users\DELL\AppData\Roaming\Python\Python38\site-packages\rich\console.py", line 1720, in print
    self._buffer.extend(new_segments)
  File "C:\Users\DELL\AppData\Roaming\Python\Python38\site-packages\rich\console.py", line 864, in __exit__
    self._exit_buffer()
  File "C:\Users\DELL\AppData\Roaming\Python\Python38\site-packages\rich\console.py", line 822, in _exit_buffer
    self._check_buffer()
[19:54:14] INFO     [19:54:53] INFO     Sending tasks to collaborator envoy_1 for round 0                                                                          aggregator.py:334
[19:54:56] INFO     Collaborator envoy_1 is sending task results for 1_train, round 0                                                          aggregator.py:537
           METRIC   Round 0, collaborator trained 1_train result Corcondance-index: 0.7954391837120056                                         aggregator.py:578
           METRIC   Round 0, collaborator trained 1_train result Integrated-Brier-Score:    0.10508086532354355                                aggregator.py:578
           METRIC   Round 0, aggregator: 1_train <openfl.interface.aggregation_functions.weighted_average.WeightedAverage object at            aggregator.py:882
                    0x00000164AB96AAC0> Corcondance-index:  0.7954391837120056                                                                                  
           METRIC   Round 0, aggregator: 1_train <openfl.interface.aggregation_functions.weighted_average.WeightedAverage object at            aggregator.py:882
                    0x00000164AB96AAC0> Integrated-Brier-Score:     0.10508086532354355                                                                         
[19:54:58] INFO     Collaborator envoy_1 is sending task results for 2_weak_learners_validate, round 0                                         aggregator.py:537
           METRIC   Round 0, collaborator validate_agg 2_weak_learners_validate result errors:      [3075.3264 3075.3264]                      aggregator.py:578
           METRIC   Round 0, aggregator: 2_weak_learners_validate <openfl.interface.aggregation_functions.aggregate_adaboost.AggregateAdaboost aggregator.py:882
                    object at 0x00000164C097D430> errors:        [9.99999917e+09 0.00000000e+00]                                                                
           INFO     Collaborator envoy_1 is sending task results for 3_adaboost_update, round 0                                                aggregator.py:537
           METRIC   Round 0, collaborator validate_agg 3_adaboost_update result adaboost_update:    0.0                                        aggregator.py:578
           METRIC   Round 0, aggregator: 3_adaboost_update <openfl.interface.aggregation_functions.weighted_average.WeightedAverage object at  aggregator.py:882
                    0x00000164AB96AAC0> adaboost_update:  0.0                                                                                                   
           INFO     Collaborator envoy_1 is sending task results for 4_adaboost_validate, round 0                                              aggregator.py:537
           METRIC   Round 0, collaborator validate_local 4_adaboost_validate result Corcondance-index:      0.3011913001537323                 aggregator.py:578
           METRIC   Round 0, collaborator validate_local 4_adaboost_validate result Integrated-Brier-Score: 0.1525840014219284                 aggregator.py:578
           METRIC   Round 0, aggregator: 4_adaboost_validate <openfl.interface.aggregation_functions.weighted_average.WeightedAverage object   aggregator.py:882
                    at 0x00000164AB96AAC0> Corcondance-index:      0.3011913001537323                                                                           
           METRIC   Round 0, aggregator: 4_adaboost_validate <openfl.interface.aggregation_functions.weighted_average.WeightedAverage object   aggregator.py:882
                    at 0x00000164AB96AAC0> Integrated-Brier-Score: 0.1525840014219284                                                                           
           INFO     Starting round 1...                                                                                                        aggregator.py:952
[19:54:59] INFO     Sending tasks to collaborator envoy_1 for round 1                                                                          aggregator.py:334
[19:55:02] INFO     Collaborator envoy_1 is sending task results for 1_train, round 1                                                          aggregator.py:537
           METRIC   Round 1, collaborator trained 1_train result Corcondance-index: 0.8001564145088196                                         aggregator.py:578
           METRIC   Round 1, collaborator trained 1_train result Integrated-Brier-Score:    0.10608663409948349                                aggregator.py:578
           METRIC   Round 1, aggregator: 1_train <openfl.interface.aggregation_functions.weighted_average.WeightedAverage object at            aggregator.py:882
                    0x00000164AB96AAC0> Corcondance-index:  0.8001564145088196                                                                                  
           METRIC   Round 1, aggregator: 1_train <openfl.interface.aggregation_functions.weighted_average.WeightedAverage object at            aggregator.py:882
                    0x00000164AB96AAC0> Integrated-Brier-Score:     0.10608663409948349                                                                         
[19:55:04] INFO     Collaborator envoy_1 is sending task results for 2_weak_learners_validate, round 1                                         aggregator.py:537
           METRIC   Round 1, collaborator validate_agg 2_weak_learners_validate result errors:      [42.52658 42.52658]                        aggregator.py:578
           METRIC   Round 1, aggregator: 2_weak_learners_validate <openfl.interface.aggregation_functions.aggregate_adaboost.AggregateAdaboost aggregator.py:882
                    object at 0x00000164C097D430> errors:        [9.99999917e+09 0.00000000e+00]                                                                
           INFO     Collaborator envoy_1 is sending task results for 3_adaboost_update, round 1                                                aggregator.py:537
           METRIC   Round 1, collaborator validate_agg 3_adaboost_update result adaboost_update:    0.0                                        aggregator.py:578
           METRIC   Round 1, aggregator: 3_adaboost_update <openfl.interface.aggregation_functions.weighted_average.WeightedAverage object at  aggregator.py:882
                    0x00000164AB96AAC0> adaboost_update:  0.0                                                                                                   
           INFO     Collaborator envoy_1 is sending task results for 4_adaboost_validate, round 1                                              aggregator.py:537
           METRIC   Round 1, collaborator validate_local 4_adaboost_validate result Corcondance-index:      0.26891669631004333                aggregator.py:578
           METRIC   Round 1, collaborator validate_local 4_adaboost_validate result Integrated-Brier-Score: 0.12786710262298584                aggregator.py:578
           METRIC   Round 1, aggregator: 4_adaboost_validate <openfl.interface.aggregation_functions.weighted_average.WeightedAverage object   aggregator.py:882
                    at 0x00000164AB96AAC0> Corcondance-index:      0.26891669631004333                                                                          
           METRIC   Round 1, aggregator: 4_adaboost_validate <openfl.interface.aggregation_functions.weighted_average.WeightedAverage object   aggregator.py:882
                    at 0x00000164AB96AAC0> Integrated-Brier-Score: 0.12786710262298584                                                                          
[19:55:05] INFO     Starting round 2...                                                                                                        aggregator.py:952
           INFO     Sending tasks to collaborator envoy_1 for round 2                                                                          aggregator.py:334
[19:55:08] INFO     Collaborator envoy_1 is sending task results for 1_train, round 2                                                          aggregator.py:537
           METRIC   Round 2, collaborator trained 1_train result Corcondance-index: 0.7944068312644958                                         aggregator.py:578
           METRIC   Round 2, collaborator trained 1_train result Integrated-Brier-Score:    0.10561969131231308                                aggregator.py:578
           METRIC   Round 2, aggregator: 1_train <openfl.interface.aggregation_functions.weighted_average.WeightedAverage object at            aggregator.py:882
                    0x00000164AB96AAC0> Corcondance-index:  0.7944068312644958                                                                                  
           METRIC   Round 2, aggregator: 1_train <openfl.interface.aggregation_functions.weighted_average.WeightedAverage object at            aggregator.py:882
                    0x00000164AB96AAC0> Integrated-Brier-Score:     0.10561969131231308                                                                         
[19:55:09] INFO     Collaborator envoy_1 is sending task results for 2_weak_learners_validate, round 2                                         aggregator.py:537
           METRIC   Round 2, collaborator validate_agg 2_weak_learners_validate result errors:      [43.15537 43.15537]                        aggregator.py:578
           METRIC   Round 2, aggregator: 2_weak_learners_validate <openfl.interface.aggregation_functions.aggregate_adaboost.AggregateAdaboost aggregator.py:882
                    object at 0x00000164C097D430> errors:        [9.99999917e+09 0.00000000e+00]                                                                
           INFO     Collaborator envoy_1 is sending task results for 3_adaboost_update, round 2                                                aggregator.py:537
           METRIC   Round 2, collaborator validate_agg 3_adaboost_update result adaboost_update:    0.0                                        aggregator.py:578
           METRIC   Round 2, aggregator: 3_adaboost_update <openfl.interface.aggregation_functions.weighted_average.WeightedAverage object at  aggregator.py:882
                    0x00000164AB96AAC0> adaboost_update:  0.0                                                                                                   
[19:55:10] INFO     Collaborator envoy_1 is sending task results for 4_adaboost_validate, round 2                                              aggregator.py:537
           METRIC   Round 2, collaborator validate_local 4_adaboost_validate result Corcondance-index:      0.2584097385406494                 aggregator.py:578
           METRIC   Round 2, collaborator validate_local 4_adaboost_validate result Integrated-Brier-Score: 0.12007701396942139                aggregator.py:578
           METRIC   Round 2, aggregator: 4_adaboost_validate <openfl.interface.aggregation_functions.weighted_average.WeightedAverage object   aggregator.py:882
                    at 0x00000164AB96AAC0> Corcondance-index:      0.2584097385406494                                                                           
           METRIC   Round 2, aggregator: 4_adaboost_validate <openfl.interface.aggregation_functions.weighted_average.WeightedAverage object   aggregator.py:882
                    at 0x00000164AB96AAC0> Integrated-Brier-Score: 0.12007701396942139                                                                          
           INFO     Starting round 3...                                                                                                        aggregator.py:952
           INFO     Sending tasks to collaborator envoy_1 for round 3                                                                          aggregator.py:334
[19:55:13] INFO     Collaborator envoy_1 is sending task results for 1_train, round 3                                                          aggregator.py:537
           METRIC   Round 3, collaborator trained 1_train result Corcondance-index: 0.7926016449928284                                         aggregator.py:578
           METRIC   Round 3, collaborator trained 1_train result Integrated-Brier-Score:    0.10629631578922272                                aggregator.py:578
           METRIC   Round 3, aggregator: 1_train <openfl.interface.aggregation_functions.weighted_average.WeightedAverage object at            aggregator.py:882
                    0x00000164AB96AAC0> Corcondance-index:  0.7926016449928284                                                                                  
           METRIC   Round 3, aggregator: 1_train <openfl.interface.aggregation_functions.weighted_average.WeightedAverage object at            aggregator.py:882
                    0x00000164AB96AAC0> Integrated-Brier-Score:     0.10629631578922272                                                                         
[19:55:15] INFO     Collaborator envoy_1 is sending task results for 2_weak_learners_validate, round 3                                         aggregator.py:537
           METRIC   Round 3, collaborator validate_agg 2_weak_learners_validate result errors:      [43.03156 43.03156]                        aggregator.py:578
           METRIC   Round 3, aggregator: 2_weak_learners_validate <openfl.interface.aggregation_functions.aggregate_adaboost.AggregateAdaboost aggregator.py:882
                    object at 0x00000164C097D430> errors:        [9.99999917e+09 0.00000000e+00]                                                                
           INFO     Collaborator envoy_1 is sending task results for 3_adaboost_update, round 3                                                aggregator.py:537
           METRIC   Round 3, collaborator validate_agg 3_adaboost_update result adaboost_update:    0.0                                        aggregator.py:578
           METRIC   Round 3, aggregator: 3_adaboost_update <openfl.interface.aggregation_functions.weighted_average.WeightedAverage object at  aggregator.py:882
                    0x00000164AB96AAC0> adaboost_update:  0.0                                                                                                   
[19:55:16] INFO     Collaborator envoy_1 is sending task results for 4_adaboost_validate, round 3                                              aggregator.py:537
           METRIC   Round 3, collaborator validate_local 4_adaboost_validate result Corcondance-index:      0.2574222981929779                 aggregator.py:578
           METRIC   Round 3, collaborator validate_local 4_adaboost_validate result Integrated-Brier-Score: 0.11669893562793732                aggregator.py:578
           METRIC   Round 3, aggregator: 4_adaboost_validate <openfl.interface.aggregation_functions.weighted_average.WeightedAverage object   aggregator.py:882
                    at 0x00000164AB96AAC0> Corcondance-index:      0.2574222981929779                                                                           
           METRIC   Round 3, aggregator: 4_adaboost_validate <openfl.interface.aggregation_functions.weighted_average.WeightedAverage object   aggregator.py:882
                    at 0x00000164AB96AAC0> Integrated-Brier-Score: 0.11669893562793732                                                                          
           INFO     Starting round 4...                                                                                                        aggregator.py:952
           INFO     Sending tasks to collaborator envoy_1 for round 4                                                                          aggregator.py:334
[19:55:19] INFO     Collaborator envoy_1 is sending task results for 1_train, round 4                                                          aggregator.py:537
           METRIC   Round 4, collaborator trained 1_train result Corcondance-index: 0.8023209571838379                                         aggregator.py:578
           METRIC   Round 4, collaborator trained 1_train result Integrated-Brier-Score:    0.10083618015050888                                aggregator.py:578
           METRIC   Round 4, aggregator: 1_train <openfl.interface.aggregation_functions.weighted_average.WeightedAverage object at            aggregator.py:882
                    0x00000164AB96AAC0> Corcondance-index:  0.8023209571838379                                                                                  
           METRIC   Round 4, aggregator: 1_train <openfl.interface.aggregation_functions.weighted_average.WeightedAverage object at            aggregator.py:882
                    0x00000164AB96AAC0> Integrated-Brier-Score:     0.10083618015050888                                                                         
[19:55:21] INFO     Collaborator envoy_1 is sending task results for 2_weak_learners_validate, round 4                                         aggregator.py:537
           METRIC   Round 4, collaborator validate_agg 2_weak_learners_validate result errors:      [43.527897 43.527897]                      aggregator.py:578
           METRIC   Round 4, aggregator: 2_weak_learners_validate <openfl.interface.aggregation_functions.aggregate_adaboost.AggregateAdaboost aggregator.py:882
                    object at 0x00000164C097D430> errors:        [9.99999917e+09 0.00000000e+00]                                                                
           INFO     Collaborator envoy_1 is sending task results for 3_adaboost_update, round 4                                                aggregator.py:537
           METRIC   Round 4, collaborator validate_agg 3_adaboost_update result adaboost_update:    0.0                                        aggregator.py:578
           METRIC   Round 4, aggregator: 3_adaboost_update <openfl.interface.aggregation_functions.weighted_average.WeightedAverage object at  aggregator.py:882
                    0x00000164AB96AAC0> adaboost_update:  0.0                                                                                                   
[19:55:22] INFO     Collaborator envoy_1 is sending task results for 4_adaboost_validate, round 4                                              aggregator.py:537
           METRIC   Round 4, collaborator validate_local 4_adaboost_validate result Corcondance-index:      0.24479852616786957                aggregator.py:578
           METRIC   Round 4, collaborator validate_local 4_adaboost_validate result Integrated-Brier-Score: 0.11224406212568283                aggregator.py:578
           METRIC   Round 4, aggregator: 4_adaboost_validate <openfl.interface.aggregation_functions.weighted_average.WeightedAverage object   aggregator.py:882
                    at 0x00000164AB96AAC0> Corcondance-index:      0.24479852616786957                                                                          
           METRIC   Round 4, aggregator: 4_adaboost_validate <openfl.interface.aggregation_functions.weighted_average.WeightedAverage object   aggregator.py:882
                    at 0x00000164AB96AAC0> Integrated-Brier-Score: 0.11224406212568283                                                                          
           INFO     Starting round 5...                                                                                                        aggregator.py:952
           INFO     Sending tasks to collaborator envoy_1 for round 5                                                                          aggregator.py:334
[19:55:25] INFO     Collaborator envoy_1 is sending task results for 1_train, round 5                                                          aggregator.py:537
           METRIC   Round 5, collaborator trained 1_train result Corcondance-index: 0.7918113470077515                                         aggregator.py:578
           METRIC   Round 5, collaborator trained 1_train result Integrated-Brier-Score:    0.10882797092199326                                aggregator.py:578
           METRIC   Round 5, aggregator: 1_train <openfl.interface.aggregation_functions.weighted_average.WeightedAverage object at            aggregator.py:882
                    0x00000164AB96AAC0> Corcondance-index:  0.7918113470077515                                                                                  
           METRIC   Round 5, aggregator: 1_train <openfl.interface.aggregation_functions.weighted_average.WeightedAverage object at            aggregator.py:882
                    0x00000164AB96AAC0> Integrated-Brier-Score:     0.10882797092199326                                                                         
[19:55:27] INFO     Collaborator envoy_1 is sending task results for 2_weak_learners_validate, round 5                                         aggregator.py:537
           METRIC   Round 5, collaborator validate_agg 2_weak_learners_validate result errors:      [42.293606 42.293606]                      aggregator.py:578
           METRIC   Round 5, aggregator: 2_weak_learners_validate <openfl.interface.aggregation_functions.aggregate_adaboost.AggregateAdaboost aggregator.py:882
                    object at 0x00000164C097D430> errors:        [9.99999917e+09 0.00000000e+00]                                                                
           INFO     Collaborator envoy_1 is sending task results for 3_adaboost_update, round 5                                                aggregator.py:537
           METRIC   Round 5, collaborator validate_agg 3_adaboost_update result adaboost_update:    0.0                                        aggregator.py:578
           METRIC   Round 5, aggregator: 3_adaboost_update <openfl.interface.aggregation_functions.weighted_average.WeightedAverage object at  aggregator.py:882
                    0x00000164AB96AAC0> adaboost_update:  0.0                                                                                                   
[19:55:28] INFO     Collaborator envoy_1 is sending task results for 4_adaboost_validate, round 5                                              aggregator.py:537
           METRIC   Round 5, collaborator validate_local 4_adaboost_validate result Corcondance-index:      0.2464393526315689                 aggregator.py:578
           METRIC   Round 5, collaborator validate_local 4_adaboost_validate result Integrated-Brier-Score: 0.11209095269441605                aggregator.py:578
           METRIC   Round 5, aggregator: 4_adaboost_validate <openfl.interface.aggregation_functions.weighted_average.WeightedAverage object   aggregator.py:882
                    at 0x00000164AB96AAC0> Corcondance-index:      0.2464393526315689                                                                           
           METRIC   Round 5, aggregator: 4_adaboost_validate <openfl.interface.aggregation_functions.weighted_average.WeightedAverage object   aggregator.py:882
                    at 0x00000164AB96AAC0> Integrated-Brier-Score: 0.11209095269441605                                                                          
           INFO     Starting round 6...                                                                                                        aggregator.py:952
           INFO     Sending tasks to collaborator envoy_1 for round 6                                                                          aggregator.py:334
[19:55:31] INFO     Collaborator envoy_1 is sending task results for 1_train, round 6                                                          aggregator.py:537
           METRIC   Round 6, collaborator trained 1_train result Corcondance-index: 0.770002007484436                                          aggregator.py:578
           METRIC   Round 6, collaborator trained 1_train result Integrated-Brier-Score:    0.11268635094165802                                aggregator.py:578
           METRIC   Round 6, aggregator: 1_train <openfl.interface.aggregation_functions.weighted_average.WeightedAverage object at            aggregator.py:882
                    0x00000164AB96AAC0> Corcondance-index:  0.770002007484436                                                                                   
           METRIC   Round 6, aggregator: 1_train <openfl.interface.aggregation_functions.weighted_average.WeightedAverage object at            aggregator.py:882
                    0x00000164AB96AAC0> Integrated-Brier-Score:     0.11268635094165802                                                                         
[19:55:32] INFO     Collaborator envoy_1 is sending task results for 2_weak_learners_validate, round 6                                         aggregator.py:537
           METRIC   Round 6, collaborator validate_agg 2_weak_learners_validate result errors:      [43.63275 43.63275]                        aggregator.py:578
           METRIC   Round 6, aggregator: 2_weak_learners_validate <openfl.interface.aggregation_functions.aggregate_adaboost.AggregateAdaboost aggregator.py:882
                    object at 0x00000164C097D430> errors:        [9.99999917e+09 0.00000000e+00]                                                                
[19:55:33] INFO     Collaborator envoy_1 is sending task results for 3_adaboost_update, round 6                                                aggregator.py:537
           METRIC   Round 6, collaborator validate_agg 3_adaboost_update result adaboost_update:    0.0                                        aggregator.py:578
           METRIC   Round 6, aggregator: 3_adaboost_update <openfl.interface.aggregation_functions.weighted_average.WeightedAverage object at  aggregator.py:882
                    0x00000164AB96AAC0> adaboost_update:  0.0                                                                                                   
[19:55:34] INFO     Collaborator envoy_1 is sending task results for 4_adaboost_validate, round 6                                              aggregator.py:537
           METRIC   Round 6, collaborator validate_local 4_adaboost_validate result Corcondance-index:      0.24567461013793945                aggregator.py:578
           METRIC   Round 6, collaborator validate_local 4_adaboost_validate result Integrated-Brier-Score: 0.11138758063316345                aggregator.py:578
           METRIC   Round 6, aggregator: 4_adaboost_validate <openfl.interface.aggregation_functions.weighted_average.WeightedAverage object   aggregator.py:882
                    at 0x00000164AB96AAC0> Corcondance-index:      0.24567461013793945                                                                          
           METRIC   Round 6, aggregator: 4_adaboost_validate <openfl.interface.aggregation_functions.weighted_average.WeightedAverage object   aggregator.py:882
                    at 0x00000164AB96AAC0> Integrated-Brier-Score: 0.11138758063316345                                                                          
           INFO     Starting round 7...                                                                                                        aggregator.py:952
           INFO     Sending tasks to collaborator envoy_1 for round 7                                                                          aggregator.py:334
[19:55:37] INFO     Collaborator envoy_1 is sending task results for 1_train, round 7                                                          aggregator.py:537
           METRIC   Round 7, collaborator trained 1_train result Corcondance-index: 0.8035406470298767                                         aggregator.py:578
           METRIC   Round 7, collaborator trained 1_train result Integrated-Brier-Score:    0.10088130086660385                                aggregator.py:578
           METRIC   Round 7, aggregator: 1_train <openfl.interface.aggregation_functions.weighted_average.WeightedAverage object at            aggregator.py:882
                    0x00000164AB96AAC0> Corcondance-index:  0.8035406470298767                                                                                  
           METRIC   Round 7, aggregator: 1_train <openfl.interface.aggregation_functions.weighted_average.WeightedAverage object at            aggregator.py:882
                    0x00000164AB96AAC0> Integrated-Brier-Score:     0.10088130086660385                                                                         
[19:55:39] INFO     Collaborator envoy_1 is sending task results for 2_weak_learners_validate, round 7                                         aggregator.py:537
           METRIC   Round 7, collaborator validate_agg 2_weak_learners_validate result errors:      [43.461067 43.461067]                      aggregator.py:578
           METRIC   Round 7, aggregator: 2_weak_learners_validate <openfl.interface.aggregation_functions.aggregate_adaboost.AggregateAdaboost aggregator.py:882
                    object at 0x00000164C097D430> errors:        [9.99999917e+09 0.00000000e+00]                                                                
           INFO     Collaborator envoy_1 is sending task results for 3_adaboost_update, round 7                                                aggregator.py:537
           METRIC   Round 7, collaborator validate_agg 3_adaboost_update result adaboost_update:    0.0                                        aggregator.py:578
           METRIC   Round 7, aggregator: 3_adaboost_update <openfl.interface.aggregation_functions.weighted_average.WeightedAverage object at  aggregator.py:882
                    0x00000164AB96AAC0> adaboost_update:  0.0                                                                                                   
[19:55:40] INFO     Collaborator envoy_1 is sending task results for 4_adaboost_validate, round 7                                              aggregator.py:537
           METRIC   Round 7, collaborator validate_local 4_adaboost_validate result Corcondance-index:      0.24545559287071228                aggregator.py:578
           METRIC   Round 7, collaborator validate_local 4_adaboost_validate result Integrated-Brier-Score: 0.11034098267555237                aggregator.py:578
           METRIC   Round 7, aggregator: 4_adaboost_validate <openfl.interface.aggregation_functions.weighted_average.WeightedAverage object   aggregator.py:882
                    at 0x00000164AB96AAC0> Corcondance-index:      0.24545559287071228                                                                          
           METRIC   Round 7, aggregator: 4_adaboost_validate <openfl.interface.aggregation_functions.weighted_average.WeightedAverage object   aggregator.py:882
                    at 0x00000164AB96AAC0> Integrated-Brier-Score: 0.11034098267555237                                                                          
           INFO     Starting round 8...                                                                                                        aggregator.py:952
           INFO     Sending tasks to collaborator envoy_1 for round 8                                                                          aggregator.py:334
[19:55:43] INFO     Collaborator envoy_1 is sending task results for 1_train, round 8                                                          aggregator.py:537
           METRIC   Round 8, collaborator trained 1_train result Corcondance-index: 0.767602801322937                                          aggregator.py:578
           METRIC   Round 8, collaborator trained 1_train result Integrated-Brier-Score:    0.11767162382602692                                aggregator.py:578
           METRIC   Round 8, aggregator: 1_train <openfl.interface.aggregation_functions.weighted_average.WeightedAverage object at            aggregator.py:882
                    0x00000164AB96AAC0> Corcondance-index:  0.767602801322937                                                                                   
           METRIC   Round 8, aggregator: 1_train <openfl.interface.aggregation_functions.weighted_average.WeightedAverage object at            aggregator.py:882
                    0x00000164AB96AAC0> Integrated-Brier-Score:     0.11767162382602692                                                                         
[19:55:44] INFO     Collaborator envoy_1 is sending task results for 2_weak_learners_validate, round 8                                         aggregator.py:537
           METRIC   Round 8, collaborator validate_agg 2_weak_learners_validate result errors:      [43.830437 43.830437]                      aggregator.py:578
           METRIC   Round 8, aggregator: 2_weak_learners_validate <openfl.interface.aggregation_functions.aggregate_adaboost.AggregateAdaboost aggregator.py:882
                    object at 0x00000164C097D430> errors:        [9.99999917e+09 0.00000000e+00]                                                                
           INFO     Collaborator envoy_1 is sending task results for 3_adaboost_update, round 8                                                aggregator.py:537
           METRIC   Round 8, collaborator validate_agg 3_adaboost_update result adaboost_update:    0.0                                        aggregator.py:578
           METRIC   Round 8, aggregator: 3_adaboost_update <openfl.interface.aggregation_functions.weighted_average.WeightedAverage object at  aggregator.py:882
                    0x00000164AB96AAC0> adaboost_update:  0.0                                                                                                   
[19:55:46] INFO     Collaborator envoy_1 is sending task results for 4_adaboost_validate, round 8                                              aggregator.py:537
           METRIC   Round 8, collaborator validate_local 4_adaboost_validate result Corcondance-index:      0.2442980706691742                 aggregator.py:578
           METRIC   Round 8, collaborator validate_local 4_adaboost_validate result Integrated-Brier-Score: 0.10913120955228806                aggregator.py:578
           METRIC   Round 8, aggregator: 4_adaboost_validate <openfl.interface.aggregation_functions.weighted_average.WeightedAverage object   aggregator.py:882
                    at 0x00000164AB96AAC0> Corcondance-index:      0.2442980706691742                                                                           
           METRIC   Round 8, aggregator: 4_adaboost_validate <openfl.interface.aggregation_functions.weighted_average.WeightedAverage object   aggregator.py:882
                    at 0x00000164AB96AAC0> Integrated-Brier-Score: 0.10913120955228806                                                                          
           INFO     Starting round 9...                                                                                                        aggregator.py:952
           INFO     Sending tasks to collaborator envoy_1 for round 9                                                                          aggregator.py:334
[19:55:49] INFO     Collaborator envoy_1 is sending task results for 1_train, round 9                                                          aggregator.py:537
           METRIC   Round 9, collaborator trained 1_train result Corcondance-index: 0.795754075050354                                          aggregator.py:578
           METRIC   Round 9, collaborator trained 1_train result Integrated-Brier-Score:    0.10726680606603622                                aggregator.py:578
           METRIC   Round 9, aggregator: 1_train <openfl.interface.aggregation_functions.weighted_average.WeightedAverage object at            aggregator.py:882
                    0x00000164AB96AAC0> Corcondance-index:  0.795754075050354                                                                                   
           METRIC   Round 9, aggregator: 1_train <openfl.interface.aggregation_functions.weighted_average.WeightedAverage object at            aggregator.py:882
                    0x00000164AB96AAC0> Integrated-Brier-Score:     0.10726680606603622                                                                         
[19:55:51] INFO     Collaborator envoy_1 is sending task results for 2_weak_learners_validate, round 9                                         aggregator.py:537
           METRIC   Round 9, collaborator validate_agg 2_weak_learners_validate result errors:      [44.16917 44.16917]                        aggregator.py:578
           METRIC   Round 9, aggregator: 2_weak_learners_validate <openfl.interface.aggregation_functions.aggregate_adaboost.AggregateAdaboost aggregator.py:882
                    object at 0x00000164C097D430> errors:        [9.99999917e+09 0.00000000e+00]                                                                
           INFO     Collaborator envoy_1 is sending task results for 3_adaboost_update, round 9                                                aggregator.py:537
           METRIC   Round 9, collaborator validate_agg 3_adaboost_update result adaboost_update:    0.0                                        aggregator.py:578
           METRIC   Round 9, aggregator: 3_adaboost_update <openfl.interface.aggregation_functions.weighted_average.WeightedAverage object at  aggregator.py:882
                    0x00000164AB96AAC0> adaboost_update:  0.0                                                                                                   
[19:55:53] INFO     Collaborator envoy_1 is sending task results for 4_adaboost_validate, round 9                                              aggregator.py:537
           METRIC   Round 9, collaborator validate_local 4_adaboost_validate result Corcondance-index:      0.24352231621742249                aggregator.py:578
           METRIC   Round 9, collaborator validate_local 4_adaboost_validate result Integrated-Brier-Score: 0.10888408869504929                aggregator.py:578
           METRIC   Round 9, aggregator: 4_adaboost_validate <openfl.interface.aggregation_functions.weighted_average.WeightedAverage object   aggregator.py:882
                    at 0x00000164AB96AAC0> Corcondance-index:      0.24352231621742249                                                                          
           METRIC   Round 9, aggregator: 4_adaboost_validate <openfl.interface.aggregation_functions.weighted_average.WeightedAverage object   aggregator.py:882
                    at 0x00000164AB96AAC0> Integrated-Brier-Score: 0.10888408869504929                                                                          
           INFO     Starting round 10...                                                                                                       aggregator.py:952
           INFO     Sending tasks to collaborator envoy_1 for round 10                                                                         aggregator.py:334
[19:55:55] INFO     Collaborator envoy_1 is sending task results for 1_train, round 10                                                         aggregator.py:537
           METRIC   Round 10, collaborator trained 1_train result Corcondance-index:        0.7899953722953796                                 aggregator.py:578
           METRIC   Round 10, collaborator trained 1_train result Integrated-Brier-Score:   0.10562536865472794                                aggregator.py:578
[19:55:56] METRIC   Round 10, aggregator: 1_train <openfl.interface.aggregation_functions.weighted_average.WeightedAverage object at           aggregator.py:882
                    0x00000164AB96AAC0> Corcondance-index: 0.7899953722953796                                                                                   
           METRIC   Round 10, aggregator: 1_train <openfl.interface.aggregation_functions.weighted_average.WeightedAverage object at           aggregator.py:882
                    0x00000164AB96AAC0> Integrated-Brier-Score:    0.10562536865472794                                                                          
