[19:43:03] INFO     [19:43:03] INFO     [19:43:03] INFO     [19:43:03] INFO     --- Logging error ---
Traceback (most recent call last):
  File "C:\Users\DELL\AppData\Roaming\Python\Python38\site-packages\rich\logging.py", line 170, in emit
    self.console.print(log_renderable)
  File "C:\Users\DELL\AppData\Roaming\Python\Python38\site-packages\rich\console.py", line 1720, in print
    self._buffer.extend(new_segments)
  File "C:\Users\DELL\AppData\Roaming\Python\Python38\site-packages\rich\console.py", line 864, in __exit__
    self._exit_buffer()
  File "C:\Users\DELL\AppData\Roaming\Python\Python38\site-packages\rich\console.py", line 822, in _exit_buffer
    self._check_buffer()
  File "C:\Users\DELL\AppData\Roaming\Python\Python38\site-packages\rich\console.py", line 2027, in _check_buffer
    legacy_windows_render(buffer, LegacyWindowsTerm(self.file))
  File "C:\Users\DELL\AppData\Roaming\Python\Python38\site-packages\rich\_windows_renderer.py", line 19, in legacy_windows_render
    term.write_text(text)
  File "C:\Users\DELL\AppData\Roaming\Python\Python38\site-packages\rich\_win32_console.py", line 403, in write_text
    self.write(text)
  File "C:\Users\DELL\anaconda3\envs\myenv\lib\encodings\cp1252.py", line 19, in encode
    return codecs.charmap_encode(input,self.errors,encoding_table)[0]
UnicodeEncodeError: 'charmap' codec can't encode character '\U0001f9ff' in position 0: character maps to <undefined>
Call stack:
  File "C:\Users\DELL\anaconda3\envs\myenv\lib\runpy.py", line 194, in _run_module_as_main
    return _run_code(code, main_globals, None,
  File "C:\Users\DELL\anaconda3\envs\myenv\lib\runpy.py", line 87, in _run_code
    exec(code, run_globals)
  File "C:\Users\DELL\anaconda3\envs\myenv\Scripts\fx.exe\__main__.py", line 7, in <module>
    sys.exit(entry())
  File "C:\Users\DELL\AppData\Roaming\Python\Python38\site-packages\openfl\interface\cli.py", line 212, in entry
    cli()
  File "C:\Users\DELL\AppData\Roaming\Python\Python38\site-packages\click\core.py", line 1137, in __call__
    return self.main(*args, **kwargs)
  File "C:\Users\DELL\AppData\Roaming\Python\Python38\site-packages\click\core.py", line 1062, in main
    rv = self.invoke(ctx)
  File "C:\Users\DELL\AppData\Roaming\Python\Python38\site-packages\click\core.py", line 1668, in invoke
    return _process_result(sub_ctx.command.invoke(sub_ctx))
  File "C:\Users\DELL\AppData\Roaming\Python\Python38\site-packages\click\core.py", line 1668, in invoke
    return _process_result(sub_ctx.command.invoke(sub_ctx))
  File "C:\Users\DELL\AppData\Roaming\Python\Python38\site-packages\click\core.py", line 1404, in invoke
    return ctx.invoke(self.callback, **ctx.params)
  File "C:\Users\DELL\AppData\Roaming\Python\Python38\site-packages\click\core.py", line 763, in invoke
    return __callback(*args, **kwargs)
  File "C:\Users\DELL\AppData\Roaming\Python\Python38\site-packages\openfl\interface\director.py", line 53, in start
    logger.info('\U0001f9ff Starting the Director Service.')
  File "C:\Users\DELL\anaconda3\envs\myenv\lib\logging\__init__.py", line 1446, in info
    self._log(INFO, msg, args, **kwargs)
  File "C:\Users\DELL\anaconda3\envs\myenv\lib\logging\__init__.py", line 1589, in _log
    self.handle(record)
  File "C:\Users\DELL\anaconda3\envs\myenv\lib\logging\__init__.py", line 1599, in handle
    self.callHandlers(record)
  File "C:\Users\DELL\anaconda3\envs\myenv\lib\logging\__init__.py", line 1661, in callHandlers
    hdlr.handle(record)
  File "C:\Users\DELL\anaconda3\envs\myenv\lib\logging\__init__.py", line 954, in handle
    self.emit(record)
  File "C:\Users\DELL\AppData\Roaming\Python\Python38\site-packages\rich\logging.py", line 172, in emit
    self.handleError(record)
Message: '\U0001f9ff Starting the Director Service.'
Arguments: ()
--- Logging error ---
Traceback (most recent call last):
  File "C:\Users\DELL\AppData\Roaming\Python\Python38\site-packages\rich\logging.py", line 170, in emit
    self.console.print(log_renderable)
  File "C:\Users\DELL\AppData\Roaming\Python\Python38\site-packages\rich\console.py", line 1720, in print
    self._buffer.extend(new_segments)
  File "C:\Users\DELL\AppData\Roaming\Python\Python38\site-packages\rich\console.py", line 864, in __exit__
    self._exit_buffer()
  File "C:\Users\DELL\AppData\Roaming\Python\Python38\site-packages\rich\console.py", line 822, in _exit_buffer
    self._check_buffer()
  File "C:\Users\DELL\AppData\Roaming\Python\Python38\site-packages\rich\console.py", line 2027, in _check_buffer
    legacy_windows_render(buffer, LegacyWindowsTerm(self.file))
  File "C:\Users\DELL\AppData\Roaming\Python\Python38\site-packages\rich\_windows_renderer.py", line 19, in legacy_windows_render
    term.write_text(text)
  File "C:\Users\DELL\AppData\Roaming\Python\Python38\site-packages\rich\_win32_console.py", line 403, in write_text
    self.write(text)
  File "C:\Users\DELL\anaconda3\envs\myenv\lib\encodings\cp1252.py", line 19, in encode
    return codecs.charmap_encode(input,self.errors,encoding_table)[0]
UnicodeEncodeError: 'charmap' codec can't encode character '\U0001f9ff' in position 0: character maps to <undefined>
Call stack:
  File "C:\Users\DELL\anaconda3\envs\myenv\lib\runpy.py", line 194, in _run_module_as_main
    return _run_code(code, main_globals, None,
  File "C:\Users\DELL\anaconda3\envs\myenv\lib\runpy.py", line 87, in _run_code
    exec(code, run_globals)
  File "C:\Users\DELL\anaconda3\envs\myenv\Scripts\fx.exe\__main__.py", line 7, in <module>
    sys.exit(entry())
  File "C:\Users\DELL\AppData\Roaming\Python\Python38\site-packages\openfl\interface\cli.py", line 212, in entry
    cli()
  File "C:\Users\DELL\AppData\Roaming\Python\Python38\site-packages\click\core.py", line 1137, in __call__
    return self.main(*args, **kwargs)
  File "C:\Users\DELL\AppData\Roaming\Python\Python38\site-packages\click\core.py", line 1062, in main
    rv = self.invoke(ctx)
  File "C:\Users\DELL\AppData\Roaming\Python\Python38\site-packages\click\core.py", line 1668, in invoke
    return _process_result(sub_ctx.command.invoke(sub_ctx))
  File "C:\Users\DELL\AppData\Roaming\Python\Python38\site-packages\click\core.py", line 1668, in invoke
    return _process_result(sub_ctx.command.invoke(sub_ctx))
  File "C:\Users\DELL\AppData\Roaming\Python\Python38\site-packages\click\core.py", line 1404, in invoke
    return ctx.invoke(self.callback, **ctx.params)
  File "C:\Users\DELL\AppData\Roaming\Python\Python38\site-packages\click\core.py", line 763, in invoke
    return __callback(*args, **kwargs)
  File "C:\Users\DELL\AppData\Roaming\Python\Python38\site-packages\openfl\interface\director.py", line 77, in start
    logger.info(
  File "C:\Users\DELL\anaconda3\envs\myenv\lib\logging\__init__.py", line 1446, in info
    self._log(INFO, msg, args, **kwargs)
  File "C:\Users\DELL\anaconda3\envs\myenv\lib\logging\__init__.py", line 1589, in _log
    self.handle(record)
  File "C:\Users\DELL\anaconda3\envs\myenv\lib\logging\__init__.py", line 1599, in handle
    self.callHandlers(record)
  File "C:\Users\DELL\anaconda3\envs\myenv\lib\logging\__init__.py", line 1661, in callHandlers
    hdlr.handle(record)
  File "C:\Users\DELL\anaconda3\envs\myenv\lib\logging\__init__.py", line 954, in handle
    self.emit(record)
  File "C:\Users\DELL\AppData\Roaming\Python\Python38\site-packages\rich\logging.py", line 172, in emit
    self.handleError(record)
Message: "Sample shape: ['8'], target shape: ['2']"
Arguments: ()
--- Logging error ---
Traceback (most recent call last):
  File "C:\Users\DELL\AppData\Roaming\Python\Python38\site-packages\rich\logging.py", line 170, in emit
    self.console.print(log_renderable)
  File "C:\Users\DELL\AppData\Roaming\Python\Python38\site-packages\rich\console.py", line 1720, in print
    self._buffer.extend(new_segments)
  File "C:\Users\DELL\AppData\Roaming\Python\Python38\site-packages\rich\console.py", line 864, in __exit__
    self._exit_buffer()
  File "C:\Users\DELL\AppData\Roaming\Python\Python38\site-packages\rich\console.py", line 822, in _exit_buffer
    self._check_buffer()
[19:43:03] INFO     [19:43:03] INFO       File "C:\Users\DELL\AppData\Roaming\Python\Python38\site-packages\rich\console.py", line 2027, in _check_buffer
    legacy_windows_render(buffer, LegacyWindowsTerm(self.file))
  File "C:\Users\DELL\AppData\Roaming\Python\Python38\site-packages\rich\_windows_renderer.py", line 19, in legacy_windows_render
    term.write_text(text)
  File "C:\Users\DELL\AppData\Roaming\Python\Python38\site-packages\rich\_win32_console.py", line 403, in write_text
    self.write(text)
  File "C:\Users\DELL\anaconda3\envs\myenv\lib\encodings\cp1252.py", line 19, in encode
    return codecs.charmap_encode(input,self.errors,encoding_table)[0]
UnicodeEncodeError: 'charmap' codec can't encode character '\U0001f9ff' in position 0: character maps to <undefined>
Call stack:
  File "C:\Users\DELL\anaconda3\envs\myenv\lib\runpy.py", line 194, in _run_module_as_main
    return _run_code(code, main_globals, None,
  File "C:\Users\DELL\anaconda3\envs\myenv\lib\runpy.py", line 87, in _run_code
    exec(code, run_globals)
  File "C:\Users\DELL\anaconda3\envs\myenv\Scripts\fx.exe\__main__.py", line 7, in <module>
    sys.exit(entry())
  File "C:\Users\DELL\AppData\Roaming\Python\Python38\site-packages\openfl\interface\cli.py", line 212, in entry
    cli()
  File "C:\Users\DELL\AppData\Roaming\Python\Python38\site-packages\click\core.py", line 1137, in __call__
    return self.main(*args, **kwargs)
  File "C:\Users\DELL\AppData\Roaming\Python\Python38\site-packages\click\core.py", line 1062, in main
    rv = self.invoke(ctx)
  File "C:\Users\DELL\AppData\Roaming\Python\Python38\site-packages\click\core.py", line 1668, in invoke
    return _process_result(sub_ctx.command.invoke(sub_ctx))
  File "C:\Users\DELL\AppData\Roaming\Python\Python38\site-packages\click\core.py", line 1668, in invoke
    return _process_result(sub_ctx.command.invoke(sub_ctx))
  File "C:\Users\DELL\AppData\Roaming\Python\Python38\site-packages\click\core.py", line 1404, in invoke
    return ctx.invoke(self.callback, **ctx.params)
  File "C:\Users\DELL\AppData\Roaming\Python\Python38\site-packages\click\core.py", line 763, in invoke
    return __callback(*args, **kwargs)
  File "C:\Users\DELL\AppData\Roaming\Python\Python38\site-packages\openfl\interface\director.py", line 104, in start
    director_server.start()
  File "C:\Users\DELL\AppData\Roaming\Python\Python38\site-packages\openfl\transport\grpc\director_server.py", line 94, in start
    loop.run_until_complete(self._run_server())
  File "C:\Users\DELL\anaconda3\envs\myenv\lib\asyncio\base_events.py", line 603, in run_until_complete
    self.run_forever()
  File "C:\Users\DELL\anaconda3\envs\myenv\lib\asyncio\windows_events.py", line 316, in run_forever
    super().run_forever()
  File "C:\Users\DELL\anaconda3\envs\myenv\lib\asyncio\base_events.py", line 570, in run_forever
    self._run_once()
  File "C:\Users\DELL\anaconda3\envs\myenv\lib\asyncio\base_events.py", line 1859, in _run_once
    handle._run()
  File "C:\Users\DELL\anaconda3\envs\myenv\lib\asyncio\events.py", line 81, in _run
    self._context.run(self._callback, *self._args)
  File "C:\Users\DELL\AppData\Roaming\Python\Python38\site-packages\openfl\transport\grpc\director_server.py", line 115, in _run_server
    logger.info(f'Starting server on {self.listen_uri}')
  File "C:\Users\DELL\anaconda3\envs\myenv\lib\logging\__init__.py", line 1446, in info
    self._log(INFO, msg, args, **kwargs)
  File "C:\Users\DELL\anaconda3\envs\myenv\lib\logging\__init__.py", line 1589, in _log
    self.handle(record)
  File "C:\Users\DELL\anaconda3\envs\myenv\lib\logging\__init__.py", line 1599, in handle
    self.callHandlers(record)
  File "C:\Users\DELL\anaconda3\envs\myenv\lib\logging\__init__.py", line 1661, in callHandlers
    hdlr.handle(record)
  File "C:\Users\DELL\anaconda3\envs\myenv\lib\logging\__init__.py", line 954, in handle
    self.emit(record)
  File "C:\Users\DELL\AppData\Roaming\Python\Python38\site-packages\rich\logging.py", line 172, in emit
    self.handleError(record)
Message: 'Starting server on localhost:50054'
Arguments: ()
--- Logging error ---
Traceback (most recent call last):
  File "C:\Users\DELL\AppData\Roaming\Python\Python38\site-packages\rich\logging.py", line 170, in emit
    self.console.print(log_renderable)
  File "C:\Users\DELL\AppData\Roaming\Python\Python38\site-packages\rich\console.py", line 1720, in print
    self._buffer.extend(new_segments)
  File "C:\Users\DELL\AppData\Roaming\Python\Python38\site-packages\rich\console.py", line 864, in __exit__
    self._exit_buffer()
  File "C:\Users\DELL\AppData\Roaming\Python\Python38\site-packages\rich\console.py", line 822, in _exit_buffer
    self._check_buffer()
  File "C:\Users\DELL\AppData\Roaming\Python\Python38\site-packages\rich\console.py", line 2027, in _check_buffer
    legacy_windows_render(buffer, LegacyWindowsTerm(self.file))
  File "C:\Users\DELL\AppData\Roaming\Python\Python38\site-packages\rich\_windows_renderer.py", line 19, in legacy_windows_render
    term.write_text(text)
  File "C:\Users\DELL\AppData\Roaming\Python\Python38\site-packages\rich\_win32_console.py", line 403, in write_text
    self.write(text)
  File "C:\Users\DELL\anaconda3\envs\myenv\lib\encodings\cp1252.py", line 19, in encode
    return codecs.charmap_encode(input,self.errors,encoding_table)[0]
UnicodeEncodeError: 'charmap' codec can't encode character '\U0001f9ff' in position 0: character maps to <undefined>
Call stack:
  File "C:\Users\DELL\anaconda3\envs\myenv\lib\runpy.py", line 194, in _run_module_as_main
    return _run_code(code, main_globals, None,
  File "C:\Users\DELL\anaconda3\envs\myenv\lib\runpy.py", line 87, in _run_code
    exec(code, run_globals)
  File "C:\Users\DELL\anaconda3\envs\myenv\Scripts\fx.exe\__main__.py", line 7, in <module>
    sys.exit(entry())
  File "C:\Users\DELL\AppData\Roaming\Python\Python38\site-packages\openfl\interface\cli.py", line 212, in entry
    cli()
  File "C:\Users\DELL\AppData\Roaming\Python\Python38\site-packages\click\core.py", line 1137, in __call__
    return self.main(*args, **kwargs)
  File "C:\Users\DELL\AppData\Roaming\Python\Python38\site-packages\click\core.py", line 1062, in main
    rv = self.invoke(ctx)
  File "C:\Users\DELL\AppData\Roaming\Python\Python38\site-packages\click\core.py", line 1668, in invoke
    return _process_result(sub_ctx.command.invoke(sub_ctx))
  File "C:\Users\DELL\AppData\Roaming\Python\Python38\site-packages\click\core.py", line 1668, in invoke
    return _process_result(sub_ctx.command.invoke(sub_ctx))
  File "C:\Users\DELL\AppData\Roaming\Python\Python38\site-packages\click\core.py", line 1404, in invoke
    return ctx.invoke(self.callback, **ctx.params)
  File "C:\Users\DELL\AppData\Roaming\Python\Python38\site-packages\click\core.py", line 763, in invoke
    return __callback(*args, **kwargs)
  File "C:\Users\DELL\AppData\Roaming\Python\Python38\site-packages\openfl\interface\director.py", line 104, in start
    director_server.start()
  File "C:\Users\DELL\AppData\Roaming\Python\Python38\site-packages\openfl\transport\grpc\director_server.py", line 94, in start
    loop.run_until_complete(self._run_server())
  File "C:\Users\DELL\anaconda3\envs\myenv\lib\asyncio\base_events.py", line 603, in run_until_complete
    self.run_forever()
  File "C:\Users\DELL\anaconda3\envs\myenv\lib\asyncio\windows_events.py", line 316, in run_forever
    super().run_forever()
  File "C:\Users\DELL\anaconda3\envs\myenv\lib\asyncio\base_events.py", line 570, in run_forever
    self._run_once()
  File "C:\Users\DELL\anaconda3\envs\myenv\lib\asyncio\base_events.py", line 1859, in _run_once
    handle._run()
  File "C:\Users\DELL\anaconda3\envs\myenv\lib\asyncio\events.py", line 81, in _run
    self._context.run(self._callback, *self._args)
  File "C:\Users\DELL\AppData\Roaming\Python\Python38\site-packages\openfl\transport\grpc\director_server.py", line 121, in UpdateShardInfo
    logger.info(f'UpdateShardInfo request has got: {request.shard_info}')
[19:43:03] INFO     [19:43:03] INFO       File "C:\Users\DELL\anaconda3\envs\myenv\lib\logging\__init__.py", line 1446, in info
    self._log(INFO, msg, args, **kwargs)
  File "C:\Users\DELL\anaconda3\envs\myenv\lib\logging\__init__.py", line 1589, in _log
    self.handle(record)
  File "C:\Users\DELL\anaconda3\envs\myenv\lib\logging\__init__.py", line 1599, in handle
    self.callHandlers(record)
  File "C:\Users\DELL\anaconda3\envs\myenv\lib\logging\__init__.py", line 1661, in callHandlers
    hdlr.handle(record)
  File "C:\Users\DELL\anaconda3\envs\myenv\lib\logging\__init__.py", line 954, in handle
    self.emit(record)
  File "C:\Users\DELL\AppData\Roaming\Python\Python38\site-packages\rich\logging.py", line 172, in emit
    self.handleError(record)
Message: 'UpdateShardInfo request has got: node_info {\n  name: "envoy_1"\n}\nshard_description: "FL_Chain dataset, shard number 1 out of 1"\nsample_shape: "8"\ntarget_shape: "2"\n'
Arguments: ()
--- Logging error ---
Traceback (most recent call last):
  File "C:\Users\DELL\AppData\Roaming\Python\Python38\site-packages\rich\logging.py", line 170, in emit
    self.console.print(log_renderable)
  File "C:\Users\DELL\AppData\Roaming\Python\Python38\site-packages\rich\console.py", line 1720, in print
    self._buffer.extend(new_segments)
  File "C:\Users\DELL\AppData\Roaming\Python\Python38\site-packages\rich\console.py", line 864, in __exit__
    self._exit_buffer()
  File "C:\Users\DELL\AppData\Roaming\Python\Python38\site-packages\rich\console.py", line 822, in _exit_buffer
    self._check_buffer()
  File "C:\Users\DELL\AppData\Roaming\Python\Python38\site-packages\rich\console.py", line 2027, in _check_buffer
    legacy_windows_render(buffer, LegacyWindowsTerm(self.file))
  File "C:\Users\DELL\AppData\Roaming\Python\Python38\site-packages\rich\_windows_renderer.py", line 19, in legacy_windows_render
    term.write_text(text)
  File "C:\Users\DELL\AppData\Roaming\Python\Python38\site-packages\rich\_win32_console.py", line 403, in write_text
    self.write(text)
  File "C:\Users\DELL\anaconda3\envs\myenv\lib\encodings\cp1252.py", line 19, in encode
    return codecs.charmap_encode(input,self.errors,encoding_table)[0]
UnicodeEncodeError: 'charmap' codec can't encode character '\U0001f9ff' in position 0: character maps to <undefined>
Call stack:
  File "C:\Users\DELL\anaconda3\envs\myenv\lib\runpy.py", line 194, in _run_module_as_main
    return _run_code(code, main_globals, None,
  File "C:\Users\DELL\anaconda3\envs\myenv\lib\runpy.py", line 87, in _run_code
    exec(code, run_globals)
  File "C:\Users\DELL\anaconda3\envs\myenv\Scripts\fx.exe\__main__.py", line 7, in <module>
    sys.exit(entry())
  File "C:\Users\DELL\AppData\Roaming\Python\Python38\site-packages\openfl\interface\cli.py", line 212, in entry
    cli()
  File "C:\Users\DELL\AppData\Roaming\Python\Python38\site-packages\click\core.py", line 1137, in __call__
    return self.main(*args, **kwargs)
  File "C:\Users\DELL\AppData\Roaming\Python\Python38\site-packages\click\core.py", line 1062, in main
    rv = self.invoke(ctx)
  File "C:\Users\DELL\AppData\Roaming\Python\Python38\site-packages\click\core.py", line 1668, in invoke
    return _process_result(sub_ctx.command.invoke(sub_ctx))
  File "C:\Users\DELL\AppData\Roaming\Python\Python38\site-packages\click\core.py", line 1668, in invoke
    return _process_result(sub_ctx.command.invoke(sub_ctx))
  File "C:\Users\DELL\AppData\Roaming\Python\Python38\site-packages\click\core.py", line 1404, in invoke
    return ctx.invoke(self.callback, **ctx.params)
  File "C:\Users\DELL\AppData\Roaming\Python\Python38\site-packages\click\core.py", line 763, in invoke
    return __callback(*args, **kwargs)
  File "C:\Users\DELL\AppData\Roaming\Python\Python38\site-packages\openfl\interface\director.py", line 104, in start
    director_server.start()
  File "C:\Users\DELL\AppData\Roaming\Python\Python38\site-packages\openfl\transport\grpc\director_server.py", line 94, in start
    loop.run_until_complete(self._run_server())
  File "C:\Users\DELL\anaconda3\envs\myenv\lib\asyncio\base_events.py", line 603, in run_until_complete
    self.run_forever()
  File "C:\Users\DELL\anaconda3\envs\myenv\lib\asyncio\windows_events.py", line 316, in run_forever
    super().run_forever()
  File "C:\Users\DELL\anaconda3\envs\myenv\lib\asyncio\base_events.py", line 570, in run_forever
    self._run_once()
  File "C:\Users\DELL\anaconda3\envs\myenv\lib\asyncio\base_events.py", line 1859, in _run_once
    handle._run()
  File "C:\Users\DELL\anaconda3\envs\myenv\lib\asyncio\events.py", line 81, in _run
    self._context.run(self._callback, *self._args)
  File "C:\Users\DELL\AppData\Roaming\Python\Python38\site-packages\openfl\transport\grpc\director_server.py", line 126, in UpdateShardInfo
    is_accepted = self.director.acknowledge_shard(dict_shard_info)
  File "C:\Users\DELL\AppData\Roaming\Python\Python38\site-packages\openfl\component\director\director.py", line 56, in acknowledge_shard
    logger.info('Request was accepted')
  File "C:\Users\DELL\anaconda3\envs\myenv\lib\logging\__init__.py", line 1446, in info
    self._log(INFO, msg, args, **kwargs)
  File "C:\Users\DELL\anaconda3\envs\myenv\lib\logging\__init__.py", line 1589, in _log
    self.handle(record)
  File "C:\Users\DELL\anaconda3\envs\myenv\lib\logging\__init__.py", line 1599, in handle
    self.callHandlers(record)
  File "C:\Users\DELL\anaconda3\envs\myenv\lib\logging\__init__.py", line 1661, in callHandlers
    hdlr.handle(record)
  File "C:\Users\DELL\anaconda3\envs\myenv\lib\logging\__init__.py", line 954, in handle
    self.emit(record)
  File "C:\Users\DELL\AppData\Roaming\Python\Python38\site-packages\rich\logging.py", line 172, in emit
    self.handleError(record)
Message: 'Request was accepted'
Arguments: ()
--- Logging error ---
Traceback (most recent call last):
  File "C:\Users\DELL\AppData\Roaming\Python\Python38\site-packages\rich\logging.py", line 170, in emit
    self.console.print(log_renderable)
  File "C:\Users\DELL\AppData\Roaming\Python\Python38\site-packages\rich\console.py", line 1720, in print
    self._buffer.extend(new_segments)
  File "C:\Users\DELL\AppData\Roaming\Python\Python38\site-packages\rich\console.py", line 864, in __exit__
    self._exit_buffer()
  File "C:\Users\DELL\AppData\Roaming\Python\Python38\site-packages\rich\console.py", line 822, in _exit_buffer
    self._check_buffer()
  File "C:\Users\DELL\AppData\Roaming\Python\Python38\site-packages\rich\console.py", line 2027, in _check_buffer
    legacy_windows_render(buffer, LegacyWindowsTerm(self.file))
  File "C:\Users\DELL\AppData\Roaming\Python\Python38\site-packages\rich\_windows_renderer.py", line 19, in legacy_windows_render
    term.write_text(text)
  File "C:\Users\DELL\AppData\Roaming\Python\Python38\site-packages\rich\_win32_console.py", line 403, in write_text
    self.write(text)
  File "C:\Users\DELL\anaconda3\envs\myenv\lib\encodings\cp1252.py", line 19, in encode
    return codecs.charmap_encode(input,self.errors,encoding_table)[0]
UnicodeEncodeError: 'charmap' codec can't encode character '\U0001f9ff' in position 0: character maps to <undefined>
Call stack:
  File "C:\Users\DELL\anaconda3\envs\myenv\lib\runpy.py", line 194, in _run_module_as_main
    return _run_code(code, main_globals, None,
  File "C:\Users\DELL\anaconda3\envs\myenv\lib\runpy.py", line 87, in _run_code
    exec(code, run_globals)
  File "C:\Users\DELL\anaconda3\envs\myenv\Scripts\fx.exe\__main__.py", line 7, in <module>
    sys.exit(entry())
  File "C:\Users\DELL\AppData\Roaming\Python\Python38\site-packages\openfl\interface\cli.py", line 212, in entry
    cli()
  File "C:\Users\DELL\AppData\Roaming\Python\Python38\site-packages\click\core.py", line 1137, in __call__
    return self.main(*args, **kwargs)
  File "C:\Users\DELL\AppData\Roaming\Python\Python38\site-packages\click\core.py", line 1062, in main
    rv = self.invoke(ctx)
  File "C:\Users\DELL\AppData\Roaming\Python\Python38\site-packages\click\core.py", line 1668, in invoke
    return _process_result(sub_ctx.command.invoke(sub_ctx))
[19:43:03] INFO       File "C:\Users\DELL\AppData\Roaming\Python\Python38\site-packages\click\core.py", line 1668, in invoke
    return _process_result(sub_ctx.command.invoke(sub_ctx))
  File "C:\Users\DELL\AppData\Roaming\Python\Python38\site-packages\click\core.py", line 1404, in invoke
    return ctx.invoke(self.callback, **ctx.params)
  File "C:\Users\DELL\AppData\Roaming\Python\Python38\site-packages\click\core.py", line 763, in invoke
    return __callback(*args, **kwargs)
  File "C:\Users\DELL\AppData\Roaming\Python\Python38\site-packages\openfl\interface\director.py", line 104, in start
    director_server.start()
  File "C:\Users\DELL\AppData\Roaming\Python\Python38\site-packages\openfl\transport\grpc\director_server.py", line 94, in start
    loop.run_until_complete(self._run_server())
  File "C:\Users\DELL\anaconda3\envs\myenv\lib\asyncio\base_events.py", line 603, in run_until_complete
    self.run_forever()
  File "C:\Users\DELL\anaconda3\envs\myenv\lib\asyncio\windows_events.py", line 316, in run_forever
    super().run_forever()
  File "C:\Users\DELL\anaconda3\envs\myenv\lib\asyncio\base_events.py", line 570, in run_forever
    self._run_once()
  File "C:\Users\DELL\anaconda3\envs\myenv\lib\asyncio\base_events.py", line 1859, in _run_once
    handle._run()
  File "C:\Users\DELL\anaconda3\envs\myenv\lib\asyncio\events.py", line 81, in _run
    self._context.run(self._callback, *self._args)
  File "C:\Users\DELL\AppData\Roaming\Python\Python38\site-packages\openfl\transport\grpc\director_server.py", line 204, in WaitExperiment
    logger.info('Request WaitExperiment has got!')
  File "C:\Users\DELL\anaconda3\envs\myenv\lib\logging\__init__.py", line 1446, in info
    self._log(INFO, msg, args, **kwargs)
  File "C:\Users\DELL\anaconda3\envs\myenv\lib\logging\__init__.py", line 1589, in _log
    self.handle(record)
  File "C:\Users\DELL\anaconda3\envs\myenv\lib\logging\__init__.py", line 1599, in handle
    self.callHandlers(record)
  File "C:\Users\DELL\anaconda3\envs\myenv\lib\logging\__init__.py", line 1661, in callHandlers
    hdlr.handle(record)
  File "C:\Users\DELL\anaconda3\envs\myenv\lib\logging\__init__.py", line 954, in handle
    self.emit(record)
  File "C:\Users\DELL\AppData\Roaming\Python\Python38\site-packages\rich\logging.py", line 172, in emit
    self.handleError(record)
Message: 'Request WaitExperiment has got!'
Arguments: ()
--- Logging error ---
Traceback (most recent call last):
  File "C:\Users\DELL\AppData\Roaming\Python\Python38\site-packages\rich\logging.py", line 170, in emit
    self.console.print(log_renderable)
  File "C:\Users\DELL\AppData\Roaming\Python\Python38\site-packages\rich\console.py", line 1720, in print
    self._buffer.extend(new_segments)
  File "C:\Users\DELL\AppData\Roaming\Python\Python38\site-packages\rich\console.py", line 864, in __exit__
    self._exit_buffer()
  File "C:\Users\DELL\AppData\Roaming\Python\Python38\site-packages\rich\console.py", line 822, in _exit_buffer
    self._check_buffer()
  File "C:\Users\DELL\AppData\Roaming\Python\Python38\site-packages\rich\console.py", line 2027, in _check_buffer
    legacy_windows_render(buffer, LegacyWindowsTerm(self.file))
  File "C:\Users\DELL\AppData\Roaming\Python\Python38\site-packages\rich\_windows_renderer.py", line 19, in legacy_windows_render
    term.write_text(text)
  File "C:\Users\DELL\AppData\Roaming\Python\Python38\site-packages\rich\_win32_console.py", line 403, in write_text
    self.write(text)
  File "C:\Users\DELL\anaconda3\envs\myenv\lib\encodings\cp1252.py", line 19, in encode
    return codecs.charmap_encode(input,self.errors,encoding_table)[0]
UnicodeEncodeError: 'charmap' codec can't encode character '\U0001f9ff' in position 0: character maps to <undefined>
Call stack:
  File "C:\Users\DELL\anaconda3\envs\myenv\lib\runpy.py", line 194, in _run_module_as_main
    return _run_code(code, main_globals, None,
  File "C:\Users\DELL\anaconda3\envs\myenv\lib\runpy.py", line 87, in _run_code
    exec(code, run_globals)
  File "C:\Users\DELL\anaconda3\envs\myenv\Scripts\fx.exe\__main__.py", line 7, in <module>
    sys.exit(entry())
  File "C:\Users\DELL\AppData\Roaming\Python\Python38\site-packages\openfl\interface\cli.py", line 212, in entry
    cli()
  File "C:\Users\DELL\AppData\Roaming\Python\Python38\site-packages\click\core.py", line 1137, in __call__
    return self.main(*args, **kwargs)
  File "C:\Users\DELL\AppData\Roaming\Python\Python38\site-packages\click\core.py", line 1062, in main
    rv = self.invoke(ctx)
  File "C:\Users\DELL\AppData\Roaming\Python\Python38\site-packages\click\core.py", line 1668, in invoke
    return _process_result(sub_ctx.command.invoke(sub_ctx))
  File "C:\Users\DELL\AppData\Roaming\Python\Python38\site-packages\click\core.py", line 1668, in invoke
    return _process_result(sub_ctx.command.invoke(sub_ctx))
  File "C:\Users\DELL\AppData\Roaming\Python\Python38\site-packages\click\core.py", line 1404, in invoke
    return ctx.invoke(self.callback, **ctx.params)
  File "C:\Users\DELL\AppData\Roaming\Python\Python38\site-packages\click\core.py", line 763, in invoke
    return __callback(*args, **kwargs)
  File "C:\Users\DELL\AppData\Roaming\Python\Python38\site-packages\openfl\interface\director.py", line 104, in start
    director_server.start()
  File "C:\Users\DELL\AppData\Roaming\Python\Python38\site-packages\openfl\transport\grpc\director_server.py", line 94, in start
    loop.run_until_complete(self._run_server())
  File "C:\Users\DELL\anaconda3\envs\myenv\lib\asyncio\base_events.py", line 603, in run_until_complete
    self.run_forever()
  File "C:\Users\DELL\anaconda3\envs\myenv\lib\asyncio\windows_events.py", line 316, in run_forever
    super().run_forever()
  File "C:\Users\DELL\anaconda3\envs\myenv\lib\asyncio\base_events.py", line 570, in run_forever
    self._run_once()
  File "C:\Users\DELL\anaconda3\envs\myenv\lib\asyncio\base_events.py", line 1859, in _run_once
    handle._run()
  File "C:\Users\DELL\anaconda3\envs\myenv\lib\asyncio\events.py", line 81, in _run
    self._context.run(self._callback, *self._args)
  File "C:\Users\DELL\AppData\Roaming\Python\Python38\site-packages\openfl\transport\grpc\director_server.py", line 206, in WaitExperiment
    logger.info(msg)
  File "C:\Users\DELL\anaconda3\envs\myenv\lib\logging\__init__.py", line 1446, in info
    self._log(INFO, msg, args, **kwargs)
  File "C:\Users\DELL\anaconda3\envs\myenv\lib\logging\__init__.py", line 1589, in _log
    self.handle(record)
  File "C:\Users\DELL\anaconda3\envs\myenv\lib\logging\__init__.py", line 1599, in handle
    self.callHandlers(record)
  File "C:\Users\DELL\anaconda3\envs\myenv\lib\logging\__init__.py", line 1661, in callHandlers
    hdlr.handle(record)
  File "C:\Users\DELL\anaconda3\envs\myenv\lib\logging\__init__.py", line 954, in handle
    self.emit(record)
  File "C:\Users\DELL\AppData\Roaming\Python\Python38\site-packages\rich\logging.py", line 172, in emit
    self.handleError(record)
Message: collaborator_name: "envoy_1"

Arguments: ()
--- Logging error ---
Traceback (most recent call last):
  File "C:\Users\DELL\AppData\Roaming\Python\Python38\site-packages\rich\logging.py", line 170, in emit
    self.console.print(log_renderable)
  File "C:\Users\DELL\AppData\Roaming\Python\Python38\site-packages\rich\console.py", line 1720, in print
    self._buffer.extend(new_segments)
  File "C:\Users\DELL\AppData\Roaming\Python\Python38\site-packages\rich\console.py", line 864, in __exit__
    self._exit_buffer()
  File "C:\Users\DELL\AppData\Roaming\Python\Python38\site-packages\rich\console.py", line 822, in _exit_buffer
    self._check_buffer()
  File "C:\Users\DELL\AppData\Roaming\Python\Python38\site-packages\rich\console.py", line 2027, in _check_buffer
    legacy_windows_render(buffer, LegacyWindowsTerm(self.file))
  File "C:\Users\DELL\AppData\Roaming\Python\Python38\site-packages\rich\_windows_renderer.py", line 19, in legacy_windows_render
    term.write_text(text)
[19:43:03] INFO     [19:43:03] INFO       File "C:\Users\DELL\AppData\Roaming\Python\Python38\site-packages\rich\_win32_console.py", line 403, in write_text
    self.write(text)
  File "C:\Users\DELL\anaconda3\envs\myenv\lib\encodings\cp1252.py", line 19, in encode
    return codecs.charmap_encode(input,self.errors,encoding_table)[0]
UnicodeEncodeError: 'charmap' codec can't encode character '\U0001f9ff' in position 0: character maps to <undefined>
Call stack:
  File "C:\Users\DELL\anaconda3\envs\myenv\lib\runpy.py", line 194, in _run_module_as_main
    return _run_code(code, main_globals, None,
  File "C:\Users\DELL\anaconda3\envs\myenv\lib\runpy.py", line 87, in _run_code
    exec(code, run_globals)
  File "C:\Users\DELL\anaconda3\envs\myenv\Scripts\fx.exe\__main__.py", line 7, in <module>
    sys.exit(entry())
  File "C:\Users\DELL\AppData\Roaming\Python\Python38\site-packages\openfl\interface\cli.py", line 212, in entry
    cli()
  File "C:\Users\DELL\AppData\Roaming\Python\Python38\site-packages\click\core.py", line 1137, in __call__
    return self.main(*args, **kwargs)
  File "C:\Users\DELL\AppData\Roaming\Python\Python38\site-packages\click\core.py", line 1062, in main
    rv = self.invoke(ctx)
  File "C:\Users\DELL\AppData\Roaming\Python\Python38\site-packages\click\core.py", line 1668, in invoke
    return _process_result(sub_ctx.command.invoke(sub_ctx))
  File "C:\Users\DELL\AppData\Roaming\Python\Python38\site-packages\click\core.py", line 1668, in invoke
    return _process_result(sub_ctx.command.invoke(sub_ctx))
  File "C:\Users\DELL\AppData\Roaming\Python\Python38\site-packages\click\core.py", line 1404, in invoke
    return ctx.invoke(self.callback, **ctx.params)
  File "C:\Users\DELL\AppData\Roaming\Python\Python38\site-packages\click\core.py", line 763, in invoke
    return __callback(*args, **kwargs)
  File "C:\Users\DELL\AppData\Roaming\Python\Python38\site-packages\openfl\interface\director.py", line 104, in start
    director_server.start()
  File "C:\Users\DELL\AppData\Roaming\Python\Python38\site-packages\openfl\transport\grpc\director_server.py", line 94, in start
    loop.run_until_complete(self._run_server())
  File "C:\Users\DELL\anaconda3\envs\myenv\lib\asyncio\base_events.py", line 603, in run_until_complete
    self.run_forever()
  File "C:\Users\DELL\anaconda3\envs\myenv\lib\asyncio\windows_events.py", line 316, in run_forever
    super().run_forever()
  File "C:\Users\DELL\anaconda3\envs\myenv\lib\asyncio\base_events.py", line 570, in run_forever
    self._run_once()
  File "C:\Users\DELL\anaconda3\envs\myenv\lib\asyncio\base_events.py", line 1859, in _run_once
    handle._run()
  File "C:\Users\DELL\anaconda3\envs\myenv\lib\asyncio\events.py", line 81, in _run
    self._context.run(self._callback, *self._args)
  File "C:\Users\DELL\AppData\Roaming\Python\Python38\site-packages\openfl\transport\grpc\director_server.py", line 214, in GetDatasetInfo
    logger.info('Request GetDatasetInfo has got!')
  File "C:\Users\DELL\anaconda3\envs\myenv\lib\logging\__init__.py", line 1446, in info
    self._log(INFO, msg, args, **kwargs)
  File "C:\Users\DELL\anaconda3\envs\myenv\lib\logging\__init__.py", line 1589, in _log
    self.handle(record)
  File "C:\Users\DELL\anaconda3\envs\myenv\lib\logging\__init__.py", line 1599, in handle
    self.callHandlers(record)
  File "C:\Users\DELL\anaconda3\envs\myenv\lib\logging\__init__.py", line 1661, in callHandlers
    hdlr.handle(record)
  File "C:\Users\DELL\anaconda3\envs\myenv\lib\logging\__init__.py", line 954, in handle
    self.emit(record)
  File "C:\Users\DELL\AppData\Roaming\Python\Python38\site-packages\rich\logging.py", line 172, in emit
    self.handleError(record)
Message: 'Request GetDatasetInfo has got!'
Arguments: ()
--- Logging error ---
Traceback (most recent call last):
  File "C:\Users\DELL\AppData\Roaming\Python\Python38\site-packages\rich\logging.py", line 170, in emit
    self.console.print(log_renderable)
  File "C:\Users\DELL\AppData\Roaming\Python\Python38\site-packages\rich\console.py", line 1720, in print
    self._buffer.extend(new_segments)
  File "C:\Users\DELL\AppData\Roaming\Python\Python38\site-packages\rich\console.py", line 864, in __exit__
    self._exit_buffer()
  File "C:\Users\DELL\AppData\Roaming\Python\Python38\site-packages\rich\console.py", line 822, in _exit_buffer
    self._check_buffer()
  File "C:\Users\DELL\AppData\Roaming\Python\Python38\site-packages\rich\console.py", line 2027, in _check_buffer
    legacy_windows_render(buffer, LegacyWindowsTerm(self.file))
  File "C:\Users\DELL\AppData\Roaming\Python\Python38\site-packages\rich\_windows_renderer.py", line 19, in legacy_windows_render
    term.write_text(text)
  File "C:\Users\DELL\AppData\Roaming\Python\Python38\site-packages\rich\_win32_console.py", line 403, in write_text
    self.write(text)
  File "C:\Users\DELL\anaconda3\envs\myenv\lib\encodings\cp1252.py", line 19, in encode
    return codecs.charmap_encode(input,self.errors,encoding_table)[0]
UnicodeEncodeError: 'charmap' codec can't encode character '\U0001f9ff' in position 0: character maps to <undefined>
Call stack:
  File "C:\Users\DELL\anaconda3\envs\myenv\lib\runpy.py", line 194, in _run_module_as_main
    return _run_code(code, main_globals, None,
  File "C:\Users\DELL\anaconda3\envs\myenv\lib\runpy.py", line 87, in _run_code
    exec(code, run_globals)
  File "C:\Users\DELL\anaconda3\envs\myenv\Scripts\fx.exe\__main__.py", line 7, in <module>
    sys.exit(entry())
  File "C:\Users\DELL\AppData\Roaming\Python\Python38\site-packages\openfl\interface\cli.py", line 212, in entry
    cli()
  File "C:\Users\DELL\AppData\Roaming\Python\Python38\site-packages\click\core.py", line 1137, in __call__
    return self.main(*args, **kwargs)
  File "C:\Users\DELL\AppData\Roaming\Python\Python38\site-packages\click\core.py", line 1062, in main
    rv = self.invoke(ctx)
  File "C:\Users\DELL\AppData\Roaming\Python\Python38\site-packages\click\core.py", line 1668, in invoke
    return _process_result(sub_ctx.command.invoke(sub_ctx))
  File "C:\Users\DELL\AppData\Roaming\Python\Python38\site-packages\click\core.py", line 1668, in invoke
    return _process_result(sub_ctx.command.invoke(sub_ctx))
  File "C:\Users\DELL\AppData\Roaming\Python\Python38\site-packages\click\core.py", line 1404, in invoke
    return ctx.invoke(self.callback, **ctx.params)
  File "C:\Users\DELL\AppData\Roaming\Python\Python38\site-packages\click\core.py", line 763, in invoke
    return __callback(*args, **kwargs)
  File "C:\Users\DELL\AppData\Roaming\Python\Python38\site-packages\openfl\interface\director.py", line 104, in start
    director_server.start()
  File "C:\Users\DELL\AppData\Roaming\Python\Python38\site-packages\openfl\transport\grpc\director_server.py", line 94, in start
    loop.run_until_complete(self._run_server())
  File "C:\Users\DELL\anaconda3\envs\myenv\lib\asyncio\base_events.py", line 603, in run_until_complete
    self.run_forever()
  File "C:\Users\DELL\anaconda3\envs\myenv\lib\asyncio\windows_events.py", line 316, in run_forever
    super().run_forever()
  File "C:\Users\DELL\anaconda3\envs\myenv\lib\asyncio\base_events.py", line 570, in run_forever
    self._run_once()
  File "C:\Users\DELL\anaconda3\envs\myenv\lib\asyncio\base_events.py", line 1859, in _run_once
    handle._run()
  File "C:\Users\DELL\anaconda3\envs\myenv\lib\asyncio\events.py", line 81, in _run
    self._context.run(self._callback, *self._args)
  File "C:\Users\DELL\AppData\Roaming\Python\Python38\site-packages\openfl\transport\grpc\director_server.py", line 283, in GetEnvoys
    envoy_infos = self.director.get_envoys()
  File "C:\Users\DELL\AppData\Roaming\Python\Python38\site-packages\openfl\component\director\director.py", line 207, in get_envoys
    logger.info(f'Shard registry: {self._shard_registry}')
  File "C:\Users\DELL\anaconda3\envs\myenv\lib\logging\__init__.py", line 1446, in info
    self._log(INFO, msg, args, **kwargs)
  File "C:\Users\DELL\anaconda3\envs\myenv\lib\logging\__init__.py", line 1589, in _log
    self.handle(record)
[19:43:03] INFO     [19:43:03] INFO       File "C:\Users\DELL\anaconda3\envs\myenv\lib\logging\__init__.py", line 1599, in handle
    self.callHandlers(record)
  File "C:\Users\DELL\anaconda3\envs\myenv\lib\logging\__init__.py", line 1661, in callHandlers
    hdlr.handle(record)
  File "C:\Users\DELL\anaconda3\envs\myenv\lib\logging\__init__.py", line 954, in handle
    self.emit(record)
  File "C:\Users\DELL\AppData\Roaming\Python\Python38\site-packages\rich\logging.py", line 172, in emit
    self.handleError(record)
Message: "Shard registry: {'envoy_1': {'shard_info': {'node_info': {'name': 'envoy_1'}, 'shard_description': 'FL_Chain dataset, shard number 1 out of 1', 'sample_shape': ['8'], 'target_shape': ['2']}, 'is_online': True, 'is_experiment_running': False, 'valid_duration': 120, 'last_updated': 1692294188.6383069}}"
Arguments: ()
--- Logging error ---
Traceback (most recent call last):
  File "C:\Users\DELL\AppData\Roaming\Python\Python38\site-packages\rich\logging.py", line 170, in emit
    self.console.print(log_renderable)
  File "C:\Users\DELL\AppData\Roaming\Python\Python38\site-packages\rich\console.py", line 1720, in print
    self._buffer.extend(new_segments)
  File "C:\Users\DELL\AppData\Roaming\Python\Python38\site-packages\rich\console.py", line 864, in __exit__
    self._exit_buffer()
  File "C:\Users\DELL\AppData\Roaming\Python\Python38\site-packages\rich\console.py", line 822, in _exit_buffer
    self._check_buffer()
  File "C:\Users\DELL\AppData\Roaming\Python\Python38\site-packages\rich\console.py", line 2027, in _check_buffer
    legacy_windows_render(buffer, LegacyWindowsTerm(self.file))
  File "C:\Users\DELL\AppData\Roaming\Python\Python38\site-packages\rich\_windows_renderer.py", line 19, in legacy_windows_render
    term.write_text(text)
  File "C:\Users\DELL\AppData\Roaming\Python\Python38\site-packages\rich\_win32_console.py", line 403, in write_text
    self.write(text)
  File "C:\Users\DELL\anaconda3\envs\myenv\lib\encodings\cp1252.py", line 19, in encode
    return codecs.charmap_encode(input,self.errors,encoding_table)[0]
UnicodeEncodeError: 'charmap' codec can't encode character '\U0001f9ff' in position 0: character maps to <undefined>
Call stack:
  File "C:\Users\DELL\anaconda3\envs\myenv\lib\runpy.py", line 194, in _run_module_as_main
    return _run_code(code, main_globals, None,
  File "C:\Users\DELL\anaconda3\envs\myenv\lib\runpy.py", line 87, in _run_code
    exec(code, run_globals)
  File "C:\Users\DELL\anaconda3\envs\myenv\Scripts\fx.exe\__main__.py", line 7, in <module>
    sys.exit(entry())
  File "C:\Users\DELL\AppData\Roaming\Python\Python38\site-packages\openfl\interface\cli.py", line 212, in entry
    cli()
  File "C:\Users\DELL\AppData\Roaming\Python\Python38\site-packages\click\core.py", line 1137, in __call__
    return self.main(*args, **kwargs)
  File "C:\Users\DELL\AppData\Roaming\Python\Python38\site-packages\click\core.py", line 1062, in main
    rv = self.invoke(ctx)
  File "C:\Users\DELL\AppData\Roaming\Python\Python38\site-packages\click\core.py", line 1668, in invoke
    return _process_result(sub_ctx.command.invoke(sub_ctx))
  File "C:\Users\DELL\AppData\Roaming\Python\Python38\site-packages\click\core.py", line 1668, in invoke
    return _process_result(sub_ctx.command.invoke(sub_ctx))
  File "C:\Users\DELL\AppData\Roaming\Python\Python38\site-packages\click\core.py", line 1404, in invoke
    return ctx.invoke(self.callback, **ctx.params)
  File "C:\Users\DELL\AppData\Roaming\Python\Python38\site-packages\click\core.py", line 763, in invoke
    return __callback(*args, **kwargs)
  File "C:\Users\DELL\AppData\Roaming\Python\Python38\site-packages\openfl\interface\director.py", line 104, in start
    director_server.start()
  File "C:\Users\DELL\AppData\Roaming\Python\Python38\site-packages\openfl\transport\grpc\director_server.py", line 94, in start
    loop.run_until_complete(self._run_server())
  File "C:\Users\DELL\anaconda3\envs\myenv\lib\asyncio\base_events.py", line 603, in run_until_complete
    self.run_forever()
  File "C:\Users\DELL\anaconda3\envs\myenv\lib\asyncio\windows_events.py", line 316, in run_forever
    super().run_forever()
  File "C:\Users\DELL\anaconda3\envs\myenv\lib\asyncio\base_events.py", line 570, in run_forever
    self._run_once()
  File "C:\Users\DELL\anaconda3\envs\myenv\lib\asyncio\base_events.py", line 1859, in _run_once
    handle._run()
  File "C:\Users\DELL\anaconda3\envs\myenv\lib\asyncio\events.py", line 81, in _run
    self._context.run(self._callback, *self._args)
  File "C:\Users\DELL\AppData\Roaming\Python\Python38\site-packages\openfl\transport\grpc\director_server.py", line 133, in SetNewExperiment
    logger.info(f'SetNewExperiment request has got {stream}')
  File "C:\Users\DELL\anaconda3\envs\myenv\lib\logging\__init__.py", line 1446, in info
    self._log(INFO, msg, args, **kwargs)
  File "C:\Users\DELL\anaconda3\envs\myenv\lib\logging\__init__.py", line 1589, in _log
    self.handle(record)
  File "C:\Users\DELL\anaconda3\envs\myenv\lib\logging\__init__.py", line 1599, in handle
    self.callHandlers(record)
  File "C:\Users\DELL\anaconda3\envs\myenv\lib\logging\__init__.py", line 1661, in callHandlers
    hdlr.handle(record)
  File "C:\Users\DELL\anaconda3\envs\myenv\lib\logging\__init__.py", line 954, in handle
    self.emit(record)
  File "C:\Users\DELL\AppData\Roaming\Python\Python38\site-packages\rich\logging.py", line 172, in emit
    self.handleError(record)
Message: 'SetNewExperiment request has got <grpc._cython.cygrpc._MessageReceiver object at 0x00000185C5C54940>'
Arguments: ()
--- Logging error ---
Traceback (most recent call last):
  File "C:\Users\DELL\AppData\Roaming\Python\Python38\site-packages\rich\logging.py", line 170, in emit
    self.console.print(log_renderable)
  File "C:\Users\DELL\AppData\Roaming\Python\Python38\site-packages\rich\console.py", line 1720, in print
    self._buffer.extend(new_segments)
  File "C:\Users\DELL\AppData\Roaming\Python\Python38\site-packages\rich\console.py", line 864, in __exit__
    self._exit_buffer()
  File "C:\Users\DELL\AppData\Roaming\Python\Python38\site-packages\rich\console.py", line 822, in _exit_buffer
    self._check_buffer()
  File "C:\Users\DELL\AppData\Roaming\Python\Python38\site-packages\rich\console.py", line 2027, in _check_buffer
    legacy_windows_render(buffer, LegacyWindowsTerm(self.file))
  File "C:\Users\DELL\AppData\Roaming\Python\Python38\site-packages\rich\_windows_renderer.py", line 19, in legacy_windows_render
    term.write_text(text)
  File "C:\Users\DELL\AppData\Roaming\Python\Python38\site-packages\rich\_win32_console.py", line 403, in write_text
    self.write(text)
  File "C:\Users\DELL\anaconda3\envs\myenv\lib\encodings\cp1252.py", line 19, in encode
    return codecs.charmap_encode(input,self.errors,encoding_table)[0]
UnicodeEncodeError: 'charmap' codec can't encode character '\U0001f9ff' in position 0: character maps to <undefined>
Call stack:
  File "C:\Users\DELL\anaconda3\envs\myenv\lib\runpy.py", line 194, in _run_module_as_main
    return _run_code(code, main_globals, None,
  File "C:\Users\DELL\anaconda3\envs\myenv\lib\runpy.py", line 87, in _run_code
    exec(code, run_globals)
  File "C:\Users\DELL\anaconda3\envs\myenv\Scripts\fx.exe\__main__.py", line 7, in <module>
    sys.exit(entry())
  File "C:\Users\DELL\AppData\Roaming\Python\Python38\site-packages\openfl\interface\cli.py", line 212, in entry
    cli()
  File "C:\Users\DELL\AppData\Roaming\Python\Python38\site-packages\click\core.py", line 1137, in __call__
    return self.main(*args, **kwargs)
  File "C:\Users\DELL\AppData\Roaming\Python\Python38\site-packages\click\core.py", line 1062, in main
    rv = self.invoke(ctx)
  File "C:\Users\DELL\AppData\Roaming\Python\Python38\site-packages\click\core.py", line 1668, in invoke
    return _process_result(sub_ctx.command.invoke(sub_ctx))
  File "C:\Users\DELL\AppData\Roaming\Python\Python38\site-packages\click\core.py", line 1668, in invoke
    return _process_result(sub_ctx.command.invoke(sub_ctx))
[19:43:03] INFO       File "C:\Users\DELL\AppData\Roaming\Python\Python38\site-packages\click\core.py", line 1404, in invoke
    return ctx.invoke(self.callback, **ctx.params)
  File "C:\Users\DELL\AppData\Roaming\Python\Python38\site-packages\click\core.py", line 763, in invoke
    return __callback(*args, **kwargs)
  File "C:\Users\DELL\AppData\Roaming\Python\Python38\site-packages\openfl\interface\director.py", line 104, in start
    director_server.start()
  File "C:\Users\DELL\AppData\Roaming\Python\Python38\site-packages\openfl\transport\grpc\director_server.py", line 94, in start
    loop.run_until_complete(self._run_server())
  File "C:\Users\DELL\anaconda3\envs\myenv\lib\asyncio\base_events.py", line 603, in run_until_complete
    self.run_forever()
  File "C:\Users\DELL\anaconda3\envs\myenv\lib\asyncio\windows_events.py", line 316, in run_forever
    super().run_forever()
  File "C:\Users\DELL\anaconda3\envs\myenv\lib\asyncio\base_events.py", line 570, in run_forever
    self._run_once()
  File "C:\Users\DELL\anaconda3\envs\myenv\lib\asyncio\base_events.py", line 1859, in _run_once
    handle._run()
  File "C:\Users\DELL\anaconda3\envs\myenv\lib\asyncio\events.py", line 81, in _run
    self._context.run(self._callback, *self._args)
  File "C:\Users\DELL\AppData\Roaming\Python\Python38\site-packages\openfl\transport\grpc\director_server.py", line 158, in SetNewExperiment
    logger.info('Send response')
  File "C:\Users\DELL\anaconda3\envs\myenv\lib\logging\__init__.py", line 1446, in info
    self._log(INFO, msg, args, **kwargs)
  File "C:\Users\DELL\anaconda3\envs\myenv\lib\logging\__init__.py", line 1589, in _log
    self.handle(record)
  File "C:\Users\DELL\anaconda3\envs\myenv\lib\logging\__init__.py", line 1599, in handle
    self.callHandlers(record)
  File "C:\Users\DELL\anaconda3\envs\myenv\lib\logging\__init__.py", line 1661, in callHandlers
    hdlr.handle(record)
  File "C:\Users\DELL\anaconda3\envs\myenv\lib\logging\__init__.py", line 954, in handle
    self.emit(record)
  File "C:\Users\DELL\AppData\Roaming\Python\Python38\site-packages\rich\logging.py", line 172, in emit
    self.handleError(record)
Message: 'Send response'
Arguments: ()
--- Logging error ---
Traceback (most recent call last):
  File "C:\Users\DELL\AppData\Roaming\Python\Python38\site-packages\rich\logging.py", line 170, in emit
    self.console.print(log_renderable)
  File "C:\Users\DELL\AppData\Roaming\Python\Python38\site-packages\rich\console.py", line 1720, in print
    self._buffer.extend(new_segments)
  File "C:\Users\DELL\AppData\Roaming\Python\Python38\site-packages\rich\console.py", line 864, in __exit__
    self._exit_buffer()
  File "C:\Users\DELL\AppData\Roaming\Python\Python38\site-packages\rich\console.py", line 822, in _exit_buffer
    self._check_buffer()
  File "C:\Users\DELL\AppData\Roaming\Python\Python38\site-packages\rich\console.py", line 2027, in _check_buffer
    legacy_windows_render(buffer, LegacyWindowsTerm(self.file))
  File "C:\Users\DELL\AppData\Roaming\Python\Python38\site-packages\rich\_windows_renderer.py", line 19, in legacy_windows_render
    term.write_text(text)
  File "C:\Users\DELL\AppData\Roaming\Python\Python38\site-packages\rich\_win32_console.py", line 403, in write_text
    self.write(text)
  File "C:\Users\DELL\anaconda3\envs\myenv\lib\encodings\cp1252.py", line 19, in encode
    return codecs.charmap_encode(input,self.errors,encoding_table)[0]
UnicodeEncodeError: 'charmap' codec can't encode character '\U0001f9ff' in position 0: character maps to <undefined>
Call stack:
  File "C:\Users\DELL\anaconda3\envs\myenv\lib\runpy.py", line 194, in _run_module_as_main
    return _run_code(code, main_globals, None,
  File "C:\Users\DELL\anaconda3\envs\myenv\lib\runpy.py", line 87, in _run_code
    exec(code, run_globals)
  File "C:\Users\DELL\anaconda3\envs\myenv\Scripts\fx.exe\__main__.py", line 7, in <module>
    sys.exit(entry())
  File "C:\Users\DELL\AppData\Roaming\Python\Python38\site-packages\openfl\interface\cli.py", line 212, in entry
    cli()
  File "C:\Users\DELL\AppData\Roaming\Python\Python38\site-packages\click\core.py", line 1137, in __call__
    return self.main(*args, **kwargs)
  File "C:\Users\DELL\AppData\Roaming\Python\Python38\site-packages\click\core.py", line 1062, in main
    rv = self.invoke(ctx)
  File "C:\Users\DELL\AppData\Roaming\Python\Python38\site-packages\click\core.py", line 1668, in invoke
    return _process_result(sub_ctx.command.invoke(sub_ctx))
  File "C:\Users\DELL\AppData\Roaming\Python\Python38\site-packages\click\core.py", line 1668, in invoke
    return _process_result(sub_ctx.command.invoke(sub_ctx))
  File "C:\Users\DELL\AppData\Roaming\Python\Python38\site-packages\click\core.py", line 1404, in invoke
    return ctx.invoke(self.callback, **ctx.params)
  File "C:\Users\DELL\AppData\Roaming\Python\Python38\site-packages\click\core.py", line 763, in invoke
    return __callback(*args, **kwargs)
  File "C:\Users\DELL\AppData\Roaming\Python\Python38\site-packages\openfl\interface\director.py", line 104, in start
    director_server.start()
  File "C:\Users\DELL\AppData\Roaming\Python\Python38\site-packages\openfl\transport\grpc\director_server.py", line 94, in start
    loop.run_until_complete(self._run_server())
  File "C:\Users\DELL\anaconda3\envs\myenv\lib\asyncio\base_events.py", line 603, in run_until_complete
    self.run_forever()
  File "C:\Users\DELL\anaconda3\envs\myenv\lib\asyncio\windows_events.py", line 316, in run_forever
    super().run_forever()
  File "C:\Users\DELL\anaconda3\envs\myenv\lib\asyncio\base_events.py", line 570, in run_forever
    self._run_once()
  File "C:\Users\DELL\anaconda3\envs\myenv\lib\asyncio\base_events.py", line 1859, in _run_once
    handle._run()
  File "C:\Users\DELL\anaconda3\envs\myenv\lib\asyncio\events.py", line 81, in _run
    self._context.run(self._callback, *self._args)
  File "C:\Users\DELL\AppData\Roaming\Python\Python38\site-packages\openfl\transport\grpc\director_server.py", line 226, in GetMetricStream
    logger.info(f'Request GetMetricStream for {request.experiment_name} experiment has got!')
  File "C:\Users\DELL\anaconda3\envs\myenv\lib\logging\__init__.py", line 1446, in info
    self._log(INFO, msg, args, **kwargs)
  File "C:\Users\DELL\anaconda3\envs\myenv\lib\logging\__init__.py", line 1589, in _log
    self.handle(record)
  File "C:\Users\DELL\anaconda3\envs\myenv\lib\logging\__init__.py", line 1599, in handle
    self.callHandlers(record)
  File "C:\Users\DELL\anaconda3\envs\myenv\lib\logging\__init__.py", line 1661, in callHandlers
    hdlr.handle(record)
  File "C:\Users\DELL\anaconda3\envs\myenv\lib\logging\__init__.py", line 954, in handle
    self.emit(record)
  File "C:\Users\DELL\AppData\Roaming\Python\Python38\site-packages\rich\logging.py", line 172, in emit
    self.handleError(record)
Message: 'Request GetMetricStream for AdaboostF_Fl_Chain experiment has got!'
Arguments: ()
--- Logging error ---
Traceback (most recent call last):
  File "C:\Users\DELL\AppData\Roaming\Python\Python38\site-packages\rich\logging.py", line 170, in emit
    self.console.print(log_renderable)
  File "C:\Users\DELL\AppData\Roaming\Python\Python38\site-packages\rich\console.py", line 1720, in print
    self._buffer.extend(new_segments)
  File "C:\Users\DELL\AppData\Roaming\Python\Python38\site-packages\rich\console.py", line 864, in __exit__
    self._exit_buffer()
  File "C:\Users\DELL\AppData\Roaming\Python\Python38\site-packages\rich\console.py", line 822, in _exit_buffer
    self._check_buffer()
  File "C:\Users\DELL\AppData\Roaming\Python\Python38\site-packages\rich\console.py", line 2027, in _check_buffer
    legacy_windows_render(buffer, LegacyWindowsTerm(self.file))
  File "C:\Users\DELL\AppData\Roaming\Python\Python38\site-packages\rich\_windows_renderer.py", line 19, in legacy_windows_render
    term.write_text(text)
  File "C:\Users\DELL\AppData\Roaming\Python\Python38\site-packages\rich\_win32_console.py", line 403, in write_text
    self.write(text)
[19:43:03] INFO     [19:43:03] INFO       File "C:\Users\DELL\anaconda3\envs\myenv\lib\encodings\cp1252.py", line 19, in encode
    return codecs.charmap_encode(input,self.errors,encoding_table)[0]
UnicodeEncodeError: 'charmap' codec can't encode character '\U0001f9ff' in position 0: character maps to <undefined>
Call stack:
  File "C:\Users\DELL\anaconda3\envs\myenv\lib\runpy.py", line 194, in _run_module_as_main
    return _run_code(code, main_globals, None,
  File "C:\Users\DELL\anaconda3\envs\myenv\lib\runpy.py", line 87, in _run_code
    exec(code, run_globals)
  File "C:\Users\DELL\anaconda3\envs\myenv\Scripts\fx.exe\__main__.py", line 7, in <module>
    sys.exit(entry())
  File "C:\Users\DELL\AppData\Roaming\Python\Python38\site-packages\openfl\interface\cli.py", line 212, in entry
    cli()
  File "C:\Users\DELL\AppData\Roaming\Python\Python38\site-packages\click\core.py", line 1137, in __call__
    return self.main(*args, **kwargs)
  File "C:\Users\DELL\AppData\Roaming\Python\Python38\site-packages\click\core.py", line 1062, in main
    rv = self.invoke(ctx)
  File "C:\Users\DELL\AppData\Roaming\Python\Python38\site-packages\click\core.py", line 1668, in invoke
    return _process_result(sub_ctx.command.invoke(sub_ctx))
  File "C:\Users\DELL\AppData\Roaming\Python\Python38\site-packages\click\core.py", line 1668, in invoke
    return _process_result(sub_ctx.command.invoke(sub_ctx))
  File "C:\Users\DELL\AppData\Roaming\Python\Python38\site-packages\click\core.py", line 1404, in invoke
    return ctx.invoke(self.callback, **ctx.params)
  File "C:\Users\DELL\AppData\Roaming\Python\Python38\site-packages\click\core.py", line 763, in invoke
    return __callback(*args, **kwargs)
  File "C:\Users\DELL\AppData\Roaming\Python\Python38\site-packages\openfl\interface\director.py", line 104, in start
    director_server.start()
  File "C:\Users\DELL\AppData\Roaming\Python\Python38\site-packages\openfl\transport\grpc\director_server.py", line 94, in start
    loop.run_until_complete(self._run_server())
  File "C:\Users\DELL\anaconda3\envs\myenv\lib\asyncio\base_events.py", line 603, in run_until_complete
    self.run_forever()
  File "C:\Users\DELL\anaconda3\envs\myenv\lib\asyncio\windows_events.py", line 316, in run_forever
    super().run_forever()
  File "C:\Users\DELL\anaconda3\envs\myenv\lib\asyncio\base_events.py", line 570, in run_forever
    self._run_once()
  File "C:\Users\DELL\anaconda3\envs\myenv\lib\asyncio\base_events.py", line 1859, in _run_once
    handle._run()
  File "C:\Users\DELL\anaconda3\envs\myenv\lib\asyncio\events.py", line 81, in _run
    self._context.run(self._callback, *self._args)
  File "C:\Users\DELL\AppData\Roaming\Python\Python38\site-packages\openfl\component\director\experiment.py", line 68, in start
    logger.info(f'New experiment {self.name} for '
  File "C:\Users\DELL\anaconda3\envs\myenv\lib\logging\__init__.py", line 1446, in info
    self._log(INFO, msg, args, **kwargs)
  File "C:\Users\DELL\anaconda3\envs\myenv\lib\logging\__init__.py", line 1589, in _log
    self.handle(record)
  File "C:\Users\DELL\anaconda3\envs\myenv\lib\logging\__init__.py", line 1599, in handle
    self.callHandlers(record)
  File "C:\Users\DELL\anaconda3\envs\myenv\lib\logging\__init__.py", line 1661, in callHandlers
    hdlr.handle(record)
  File "C:\Users\DELL\anaconda3\envs\myenv\lib\logging\__init__.py", line 954, in handle
    self.emit(record)
  File "C:\Users\DELL\AppData\Roaming\Python\Python38\site-packages\rich\logging.py", line 172, in emit
    self.handleError(record)
Message: "New experiment AdaboostF_Fl_Chain for collaborators ['envoy_1']"
Arguments: ()
--- Logging error ---
Traceback (most recent call last):
  File "C:\Users\DELL\AppData\Roaming\Python\Python38\site-packages\rich\logging.py", line 170, in emit
    self.console.print(log_renderable)
  File "C:\Users\DELL\AppData\Roaming\Python\Python38\site-packages\rich\console.py", line 1720, in print
    self._buffer.extend(new_segments)
  File "C:\Users\DELL\AppData\Roaming\Python\Python38\site-packages\rich\console.py", line 864, in __exit__
    self._exit_buffer()
  File "C:\Users\DELL\AppData\Roaming\Python\Python38\site-packages\rich\console.py", line 822, in _exit_buffer
    self._check_buffer()
  File "C:\Users\DELL\AppData\Roaming\Python\Python38\site-packages\rich\console.py", line 2027, in _check_buffer
    legacy_windows_render(buffer, LegacyWindowsTerm(self.file))
  File "C:\Users\DELL\AppData\Roaming\Python\Python38\site-packages\rich\_windows_renderer.py", line 19, in legacy_windows_render
    term.write_text(text)
  File "C:\Users\DELL\AppData\Roaming\Python\Python38\site-packages\rich\_win32_console.py", line 403, in write_text
    self.write(text)
  File "C:\Users\DELL\anaconda3\envs\myenv\lib\encodings\cp1252.py", line 19, in encode
    return codecs.charmap_encode(input,self.errors,encoding_table)[0]
UnicodeEncodeError: 'charmap' codec can't encode character '\U0001f9ff' in position 0: character maps to <undefined>
Call stack:
  File "C:\Users\DELL\anaconda3\envs\myenv\lib\runpy.py", line 194, in _run_module_as_main
    return _run_code(code, main_globals, None,
  File "C:\Users\DELL\anaconda3\envs\myenv\lib\runpy.py", line 87, in _run_code
    exec(code, run_globals)
  File "C:\Users\DELL\anaconda3\envs\myenv\Scripts\fx.exe\__main__.py", line 7, in <module>
    sys.exit(entry())
  File "C:\Users\DELL\AppData\Roaming\Python\Python38\site-packages\openfl\interface\cli.py", line 212, in entry
    cli()
  File "C:\Users\DELL\AppData\Roaming\Python\Python38\site-packages\click\core.py", line 1137, in __call__
    return self.main(*args, **kwargs)
  File "C:\Users\DELL\AppData\Roaming\Python\Python38\site-packages\click\core.py", line 1062, in main
    rv = self.invoke(ctx)
  File "C:\Users\DELL\AppData\Roaming\Python\Python38\site-packages\click\core.py", line 1668, in invoke
    return _process_result(sub_ctx.command.invoke(sub_ctx))
  File "C:\Users\DELL\AppData\Roaming\Python\Python38\site-packages\click\core.py", line 1668, in invoke
    return _process_result(sub_ctx.command.invoke(sub_ctx))
  File "C:\Users\DELL\AppData\Roaming\Python\Python38\site-packages\click\core.py", line 1404, in invoke
    return ctx.invoke(self.callback, **ctx.params)
  File "C:\Users\DELL\AppData\Roaming\Python\Python38\site-packages\click\core.py", line 763, in invoke
    return __callback(*args, **kwargs)
  File "C:\Users\DELL\AppData\Roaming\Python\Python38\site-packages\openfl\interface\director.py", line 104, in start
    director_server.start()
  File "C:\Users\DELL\AppData\Roaming\Python\Python38\site-packages\openfl\transport\grpc\director_server.py", line 94, in start
    loop.run_until_complete(self._run_server())
  File "C:\Users\DELL\anaconda3\envs\myenv\lib\asyncio\base_events.py", line 603, in run_until_complete
    self.run_forever()
  File "C:\Users\DELL\anaconda3\envs\myenv\lib\asyncio\windows_events.py", line 316, in run_forever
    super().run_forever()
  File "C:\Users\DELL\anaconda3\envs\myenv\lib\asyncio\base_events.py", line 570, in run_forever
    self._run_once()
  File "C:\Users\DELL\anaconda3\envs\myenv\lib\asyncio\base_events.py", line 1859, in _run_once
    handle._run()
  File "C:\Users\DELL\anaconda3\envs\myenv\lib\asyncio\events.py", line 81, in _run
    self._context.run(self._callback, *self._args)
  File "C:\Users\DELL\AppData\Roaming\Python\Python38\site-packages\openfl\component\director\experiment.py", line 72, in start
    aggregator_grpc_server = self._create_aggregator_grpc_server(
  File "C:\Users\DELL\AppData\Roaming\Python\Python38\site-packages\openfl\component\director\experiment.py", line 95, in _create_aggregator_grpc_server
    plan = Plan.parse(plan_config_path=Path(self.plan_path))
  File "C:\Users\DELL\AppData\Roaming\Python\Python38\site-packages\openfl\federated\plan\plan.py", line 140, in parse
    plan.resolve()
  File "C:\Users\DELL\AppData\Roaming\Python\Python38\site-packages\openfl\federated\plan\plan.py", line 242, in resolve
    self.federation_uuid = f'{self.name}_{self.hash[:8]}'
[19:43:03] INFO       File "C:\Users\DELL\AppData\Roaming\Python\Python38\site-packages\openfl\federated\plan\plan.py", line 235, in hash
    Plan.logger.info(f'FL-Plan hash is [blue]{self.hash_.hexdigest()}[/]',
  File "C:\Users\DELL\anaconda3\envs\myenv\lib\logging\__init__.py", line 1446, in info
    self._log(INFO, msg, args, **kwargs)
  File "C:\Users\DELL\anaconda3\envs\myenv\lib\logging\__init__.py", line 1589, in _log
    self.handle(record)
  File "C:\Users\DELL\anaconda3\envs\myenv\lib\logging\__init__.py", line 1599, in handle
    self.callHandlers(record)
  File "C:\Users\DELL\anaconda3\envs\myenv\lib\logging\__init__.py", line 1661, in callHandlers
    hdlr.handle(record)
  File "C:\Users\DELL\anaconda3\envs\myenv\lib\logging\__init__.py", line 954, in handle
    self.emit(record)
  File "C:\Users\DELL\AppData\Roaming\Python\Python38\site-packages\rich\logging.py", line 172, in emit
    self.handleError(record)
Message: 'FL-Plan hash is [blue]324696447f9be07ccb338d1f0bc9152c2c15f578cdce475c15491bf5869711bdd6e92353bdb7d402cf46e091d18c6d76[/]'
Arguments: ()
--- Logging error ---
Traceback (most recent call last):
  File "C:\Users\DELL\AppData\Roaming\Python\Python38\site-packages\rich\logging.py", line 170, in emit
    self.console.print(log_renderable)
  File "C:\Users\DELL\AppData\Roaming\Python\Python38\site-packages\rich\console.py", line 1720, in print
    self._buffer.extend(new_segments)
  File "C:\Users\DELL\AppData\Roaming\Python\Python38\site-packages\rich\console.py", line 864, in __exit__
    self._exit_buffer()
  File "C:\Users\DELL\AppData\Roaming\Python\Python38\site-packages\rich\console.py", line 822, in _exit_buffer
    self._check_buffer()
  File "C:\Users\DELL\AppData\Roaming\Python\Python38\site-packages\rich\console.py", line 2027, in _check_buffer
    legacy_windows_render(buffer, LegacyWindowsTerm(self.file))
  File "C:\Users\DELL\AppData\Roaming\Python\Python38\site-packages\rich\_windows_renderer.py", line 19, in legacy_windows_render
    term.write_text(text)
  File "C:\Users\DELL\AppData\Roaming\Python\Python38\site-packages\rich\_win32_console.py", line 403, in write_text
    self.write(text)
  File "C:\Users\DELL\anaconda3\envs\myenv\lib\encodings\cp1252.py", line 19, in encode
    return codecs.charmap_encode(input,self.errors,encoding_table)[0]
UnicodeEncodeError: 'charmap' codec can't encode character '\U0001f9ff' in position 0: character maps to <undefined>
Call stack:
  File "C:\Users\DELL\anaconda3\envs\myenv\lib\runpy.py", line 194, in _run_module_as_main
    return _run_code(code, main_globals, None,
  File "C:\Users\DELL\anaconda3\envs\myenv\lib\runpy.py", line 87, in _run_code
    exec(code, run_globals)
  File "C:\Users\DELL\anaconda3\envs\myenv\Scripts\fx.exe\__main__.py", line 7, in <module>
    sys.exit(entry())
  File "C:\Users\DELL\AppData\Roaming\Python\Python38\site-packages\openfl\interface\cli.py", line 212, in entry
    cli()
  File "C:\Users\DELL\AppData\Roaming\Python\Python38\site-packages\click\core.py", line 1137, in __call__
    return self.main(*args, **kwargs)
  File "C:\Users\DELL\AppData\Roaming\Python\Python38\site-packages\click\core.py", line 1062, in main
    rv = self.invoke(ctx)
  File "C:\Users\DELL\AppData\Roaming\Python\Python38\site-packages\click\core.py", line 1668, in invoke
    return _process_result(sub_ctx.command.invoke(sub_ctx))
  File "C:\Users\DELL\AppData\Roaming\Python\Python38\site-packages\click\core.py", line 1668, in invoke
    return _process_result(sub_ctx.command.invoke(sub_ctx))
  File "C:\Users\DELL\AppData\Roaming\Python\Python38\site-packages\click\core.py", line 1404, in invoke
    return ctx.invoke(self.callback, **ctx.params)
  File "C:\Users\DELL\AppData\Roaming\Python\Python38\site-packages\click\core.py", line 763, in invoke
    return __callback(*args, **kwargs)
  File "C:\Users\DELL\AppData\Roaming\Python\Python38\site-packages\openfl\interface\director.py", line 104, in start
    director_server.start()
  File "C:\Users\DELL\AppData\Roaming\Python\Python38\site-packages\openfl\transport\grpc\director_server.py", line 94, in start
    loop.run_until_complete(self._run_server())
  File "C:\Users\DELL\anaconda3\envs\myenv\lib\asyncio\base_events.py", line 603, in run_until_complete
    self.run_forever()
  File "C:\Users\DELL\anaconda3\envs\myenv\lib\asyncio\windows_events.py", line 316, in run_forever
    super().run_forever()
  File "C:\Users\DELL\anaconda3\envs\myenv\lib\asyncio\base_events.py", line 570, in run_forever
    self._run_once()
  File "C:\Users\DELL\anaconda3\envs\myenv\lib\asyncio\base_events.py", line 1859, in _run_once
    handle._run()
  File "C:\Users\DELL\anaconda3\envs\myenv\lib\asyncio\events.py", line 81, in _run
    self._context.run(self._callback, *self._args)
  File "C:\Users\DELL\AppData\Roaming\Python\Python38\site-packages\openfl\component\director\experiment.py", line 72, in start
    aggregator_grpc_server = self._create_aggregator_grpc_server(
  File "C:\Users\DELL\AppData\Roaming\Python\Python38\site-packages\openfl\component\director\experiment.py", line 95, in _create_aggregator_grpc_server
    plan = Plan.parse(plan_config_path=Path(self.plan_path))
  File "C:\Users\DELL\AppData\Roaming\Python\Python38\site-packages\openfl\federated\plan\plan.py", line 140, in parse
    plan.resolve()
  File "C:\Users\DELL\AppData\Roaming\Python\Python38\site-packages\openfl\federated\plan\plan.py", line 253, in resolve
    self.hash[:8], 16
  File "C:\Users\DELL\AppData\Roaming\Python\Python38\site-packages\openfl\federated\plan\plan.py", line 235, in hash
    Plan.logger.info(f'FL-Plan hash is [blue]{self.hash_.hexdigest()}[/]',
  File "C:\Users\DELL\anaconda3\envs\myenv\lib\logging\__init__.py", line 1446, in info
    self._log(INFO, msg, args, **kwargs)
  File "C:\Users\DELL\anaconda3\envs\myenv\lib\logging\__init__.py", line 1589, in _log
    self.handle(record)
  File "C:\Users\DELL\anaconda3\envs\myenv\lib\logging\__init__.py", line 1599, in handle
    self.callHandlers(record)
  File "C:\Users\DELL\anaconda3\envs\myenv\lib\logging\__init__.py", line 1661, in callHandlers
    hdlr.handle(record)
  File "C:\Users\DELL\anaconda3\envs\myenv\lib\logging\__init__.py", line 954, in handle
    self.emit(record)
  File "C:\Users\DELL\AppData\Roaming\Python\Python38\site-packages\rich\logging.py", line 172, in emit
    self.handleError(record)
Message: 'FL-Plan hash is [blue]324696447f9be07ccb338d1f0bc9152c2c15f578cdce475c15491bf5869711bdd6e92353bdb7d402cf46e091d18c6d76[/]'
Arguments: ()
--- Logging error ---
Traceback (most recent call last):
  File "C:\Users\DELL\AppData\Roaming\Python\Python38\site-packages\rich\logging.py", line 170, in emit
    self.console.print(log_renderable)
  File "C:\Users\DELL\AppData\Roaming\Python\Python38\site-packages\rich\console.py", line 1720, in print
    self._buffer.extend(new_segments)
  File "C:\Users\DELL\AppData\Roaming\Python\Python38\site-packages\rich\console.py", line 864, in __exit__
    self._exit_buffer()
  File "C:\Users\DELL\AppData\Roaming\Python\Python38\site-packages\rich\console.py", line 822, in _exit_buffer
    self._check_buffer()
  File "C:\Users\DELL\AppData\Roaming\Python\Python38\site-packages\rich\console.py", line 2027, in _check_buffer
    legacy_windows_render(buffer, LegacyWindowsTerm(self.file))
  File "C:\Users\DELL\AppData\Roaming\Python\Python38\site-packages\rich\_windows_renderer.py", line 19, in legacy_windows_render
    term.write_text(text)
  File "C:\Users\DELL\AppData\Roaming\Python\Python38\site-packages\rich\_win32_console.py", line 403, in write_text
    self.write(text)
  File "C:\Users\DELL\anaconda3\envs\myenv\lib\encodings\cp1252.py", line 19, in encode
    return codecs.charmap_encode(input,self.errors,encoding_table)[0]
UnicodeEncodeError: 'charmap' codec can't encode character '\U0001f9ff' in position 0: character maps to <undefined>
Call stack:
  File "C:\Users\DELL\anaconda3\envs\myenv\lib\runpy.py", line 194, in _run_module_as_main
    return _run_code(code, main_globals, None,
[19:43:03] INFO       File "C:\Users\DELL\anaconda3\envs\myenv\lib\runpy.py", line 87, in _run_code
    exec(code, run_globals)
  File "C:\Users\DELL\anaconda3\envs\myenv\Scripts\fx.exe\__main__.py", line 7, in <module>
    sys.exit(entry())
  File "C:\Users\DELL\AppData\Roaming\Python\Python38\site-packages\openfl\interface\cli.py", line 212, in entry
    cli()
  File "C:\Users\DELL\AppData\Roaming\Python\Python38\site-packages\click\core.py", line 1137, in __call__
    return self.main(*args, **kwargs)
  File "C:\Users\DELL\AppData\Roaming\Python\Python38\site-packages\click\core.py", line 1062, in main
    rv = self.invoke(ctx)
  File "C:\Users\DELL\AppData\Roaming\Python\Python38\site-packages\click\core.py", line 1668, in invoke
    return _process_result(sub_ctx.command.invoke(sub_ctx))
  File "C:\Users\DELL\AppData\Roaming\Python\Python38\site-packages\click\core.py", line 1668, in invoke
    return _process_result(sub_ctx.command.invoke(sub_ctx))
  File "C:\Users\DELL\AppData\Roaming\Python\Python38\site-packages\click\core.py", line 1404, in invoke
    return ctx.invoke(self.callback, **ctx.params)
  File "C:\Users\DELL\AppData\Roaming\Python\Python38\site-packages\click\core.py", line 763, in invoke
    return __callback(*args, **kwargs)
  File "C:\Users\DELL\AppData\Roaming\Python\Python38\site-packages\openfl\interface\director.py", line 104, in start
    director_server.start()
  File "C:\Users\DELL\AppData\Roaming\Python\Python38\site-packages\openfl\transport\grpc\director_server.py", line 94, in start
    loop.run_until_complete(self._run_server())
  File "C:\Users\DELL\anaconda3\envs\myenv\lib\asyncio\base_events.py", line 603, in run_until_complete
    self.run_forever()
  File "C:\Users\DELL\anaconda3\envs\myenv\lib\asyncio\windows_events.py", line 316, in run_forever
    super().run_forever()
  File "C:\Users\DELL\anaconda3\envs\myenv\lib\asyncio\base_events.py", line 570, in run_forever
    self._run_once()
  File "C:\Users\DELL\anaconda3\envs\myenv\lib\asyncio\base_events.py", line 1859, in _run_once
    handle._run()
  File "C:\Users\DELL\anaconda3\envs\myenv\lib\asyncio\events.py", line 81, in _run
    self._context.run(self._callback, *self._args)
  File "C:\Users\DELL\AppData\Roaming\Python\Python38\site-packages\openfl\component\director\experiment.py", line 72, in start
    aggregator_grpc_server = self._create_aggregator_grpc_server(
  File "C:\Users\DELL\AppData\Roaming\Python\Python38\site-packages\openfl\component\director\experiment.py", line 95, in _create_aggregator_grpc_server
    plan = Plan.parse(plan_config_path=Path(self.plan_path))
  File "C:\Users\DELL\AppData\Roaming\Python\Python38\site-packages\openfl\federated\plan\plan.py", line 142, in parse
    Plan.logger.info(
  File "C:\Users\DELL\anaconda3\envs\myenv\lib\logging\__init__.py", line 1446, in info
    self._log(INFO, msg, args, **kwargs)
  File "C:\Users\DELL\anaconda3\envs\myenv\lib\logging\__init__.py", line 1589, in _log
    self.handle(record)
  File "C:\Users\DELL\anaconda3\envs\myenv\lib\logging\__init__.py", line 1599, in handle
    self.callHandlers(record)
  File "C:\Users\DELL\anaconda3\envs\myenv\lib\logging\__init__.py", line 1661, in callHandlers
    hdlr.handle(record)
  File "C:\Users\DELL\anaconda3\envs\myenv\lib\logging\__init__.py", line 954, in handle
    self.emit(record)
  File "C:\Users\DELL\AppData\Roaming\Python\Python38\site-packages\rich\logging.py", line 172, in emit
    self.handleError(record)
Message: 'Parsing Federated Learning Plan : [green]SUCCESS[/] : [blue]plan\\plan.yaml[/].'
Arguments: ()
--- Logging error ---
Traceback (most recent call last):
  File "C:\Users\DELL\AppData\Roaming\Python\Python38\site-packages\rich\logging.py", line 170, in emit
    self.console.print(log_renderable)
  File "C:\Users\DELL\AppData\Roaming\Python\Python38\site-packages\rich\console.py", line 1720, in print
    self._buffer.extend(new_segments)
  File "C:\Users\DELL\AppData\Roaming\Python\Python38\site-packages\rich\console.py", line 864, in __exit__
    self._exit_buffer()
  File "C:\Users\DELL\AppData\Roaming\Python\Python38\site-packages\rich\console.py", line 822, in _exit_buffer
    self._check_buffer()
  File "C:\Users\DELL\AppData\Roaming\Python\Python38\site-packages\rich\console.py", line 2027, in _check_buffer
    legacy_windows_render(buffer, LegacyWindowsTerm(self.file))
  File "C:\Users\DELL\AppData\Roaming\Python\Python38\site-packages\rich\_windows_renderer.py", line 19, in legacy_windows_render
    term.write_text(text)
  File "C:\Users\DELL\AppData\Roaming\Python\Python38\site-packages\rich\_win32_console.py", line 403, in write_text
    self.write(text)
  File "C:\Users\DELL\anaconda3\envs\myenv\lib\encodings\cp1252.py", line 19, in encode
    return codecs.charmap_encode(input,self.errors,encoding_table)[0]
UnicodeEncodeError: 'charmap' codec can't encode character '\U0001f9ff' in position 0: character maps to <undefined>
Call stack:
  File "C:\Users\DELL\anaconda3\envs\myenv\lib\runpy.py", line 194, in _run_module_as_main
    return _run_code(code, main_globals, None,
  File "C:\Users\DELL\anaconda3\envs\myenv\lib\runpy.py", line 87, in _run_code
    exec(code, run_globals)
  File "C:\Users\DELL\anaconda3\envs\myenv\Scripts\fx.exe\__main__.py", line 7, in <module>
    sys.exit(entry())
  File "C:\Users\DELL\AppData\Roaming\Python\Python38\site-packages\openfl\interface\cli.py", line 212, in entry
    cli()
  File "C:\Users\DELL\AppData\Roaming\Python\Python38\site-packages\click\core.py", line 1137, in __call__
    return self.main(*args, **kwargs)
  File "C:\Users\DELL\AppData\Roaming\Python\Python38\site-packages\click\core.py", line 1062, in main
    rv = self.invoke(ctx)
  File "C:\Users\DELL\AppData\Roaming\Python\Python38\site-packages\click\core.py", line 1668, in invoke
    return _process_result(sub_ctx.command.invoke(sub_ctx))
  File "C:\Users\DELL\AppData\Roaming\Python\Python38\site-packages\click\core.py", line 1668, in invoke
    return _process_result(sub_ctx.command.invoke(sub_ctx))
  File "C:\Users\DELL\AppData\Roaming\Python\Python38\site-packages\click\core.py", line 1404, in invoke
    return ctx.invoke(self.callback, **ctx.params)
  File "C:\Users\DELL\AppData\Roaming\Python\Python38\site-packages\click\core.py", line 763, in invoke
    return __callback(*args, **kwargs)
  File "C:\Users\DELL\AppData\Roaming\Python\Python38\site-packages\openfl\interface\director.py", line 104, in start
    director_server.start()
  File "C:\Users\DELL\AppData\Roaming\Python\Python38\site-packages\openfl\transport\grpc\director_server.py", line 94, in start
    loop.run_until_complete(self._run_server())
  File "C:\Users\DELL\anaconda3\envs\myenv\lib\asyncio\base_events.py", line 603, in run_until_complete
    self.run_forever()
  File "C:\Users\DELL\anaconda3\envs\myenv\lib\asyncio\windows_events.py", line 316, in run_forever
    super().run_forever()
  File "C:\Users\DELL\anaconda3\envs\myenv\lib\asyncio\base_events.py", line 570, in run_forever
    self._run_once()
  File "C:\Users\DELL\anaconda3\envs\myenv\lib\asyncio\base_events.py", line 1859, in _run_once
    handle._run()
  File "C:\Users\DELL\anaconda3\envs\myenv\lib\asyncio\events.py", line 81, in _run
    self._context.run(self._callback, *self._args)
  File "C:\Users\DELL\AppData\Roaming\Python\Python38\site-packages\openfl\component\director\experiment.py", line 72, in start
    aggregator_grpc_server = self._create_aggregator_grpc_server(
  File "C:\Users\DELL\AppData\Roaming\Python\Python38\site-packages\openfl\component\director\experiment.py", line 95, in _create_aggregator_grpc_server
    plan = Plan.parse(plan_config_path=Path(self.plan_path))
  File "C:\Users\DELL\AppData\Roaming\Python\Python38\site-packages\openfl\federated\plan\plan.py", line 146, in parse
    Plan.logger.info(dump(plan.config))
  File "C:\Users\DELL\anaconda3\envs\myenv\lib\logging\__init__.py", line 1446, in info
    self._log(INFO, msg, args, **kwargs)
[19:43:03] INFO     [19:43:03] INFO       File "C:\Users\DELL\anaconda3\envs\myenv\lib\logging\__init__.py", line 1589, in _log
    self.handle(record)
  File "C:\Users\DELL\anaconda3\envs\myenv\lib\logging\__init__.py", line 1599, in handle
    self.callHandlers(record)
  File "C:\Users\DELL\anaconda3\envs\myenv\lib\logging\__init__.py", line 1661, in callHandlers
    hdlr.handle(record)
  File "C:\Users\DELL\anaconda3\envs\myenv\lib\logging\__init__.py", line 954, in handle
    self.emit(record)
  File "C:\Users\DELL\AppData\Roaming\Python\Python38\site-packages\rich\logging.py", line 172, in emit
    self.handleError(record)
Message: 'aggregator:\n  settings:\n    assigner: openfl.component.assigner.AdaBoostAssigner\n    best_state_path: save/best.pbuf\n    db_store_rounds: 1\n    init_state_path: save/init.pbuf\n    last_state_path: save/last.pbuf\n    nn: false\n    rounds_to_train: 50\n    write_logs: false\n  template: openfl.component.aggregator.Aggregator\napi_layer:\n  required_plugin_components:\n    serializer_plugin: openfl.plugins.interface_serializer.dill_serializer.DillSerializer\n  settings:\n    aggregation_function_interface_file: aggregation_function_obj.pkl\n    dataloader_interface_file: loader_obj.pkl\n    model_interface_file: model_obj.pkl\n    task_assigner_file: task_assigner_obj.pkl\n    tasks_interface_file: tasks_obj.pkl\nassigner:\n  settings:\n    task_groups:\n    - name: train_and_validate\n      percentage: 1.0\n      tasks:\n      - 1_train\n      - 2_weak_learners_validate\n      - 3_adaboost_update\n      - 4_adaboost_validate\n  template: openfl.component.assigner.AdaBoostAssigner\ncollaborator:\n  settings:\n    db_store_rounds: 2\n    delta_updates: false\n    device_assignment_policy: CPU_ONLY\n    nn: false\n    opt_treatment: CONTINUE_GLOBAL\n  template: openfl.component.collaborator.Collaborator\ncompression_pipeline:\n  settings:\n    nn: false\n  template: openfl.pipelines.GenericPipeline\nnetwork:\n  settings:\n    agg_addr: localhost\n    agg_port: 53234\n    cert_folder: cert\n    client_reconnect_interval: 5\n    disable_client_auth: false\n    hash_salt: auto\n    tls: false\n  template: openfl.federation.Network\ntask_runner:\n  required_plugin_components:\n    framework_adapters: openfl.plugins.frameworks_adapters.generic_adapter.GenericAdapter\n  settings: {}\n  template: openfl.federated.task.runner_generic.GenericTaskRunner\ntasks:\n  1_train:\n    aggregation_type: openfl.interface.aggregation_functions.AggregateRandomForest\n    function: train_adaboost\n    kwargs:\n      apply: global\n      data: train\n      retrieve: weak_learner\n  2_weak_learners_validate:\n    aggregation_type: openfl.interface.aggregation_functions.AggregateAdaboost\n    function: validate_weak_learners\n    kwargs:\n      apply: global\n      data: train\n      retrieve: model\n    n_classes: 2\n  3_adaboost_update:\n    aggregation_type: openfl.interface.aggregation_functions.WeightedAverage\n    function: adaboost_update\n    kwargs:\n      apply: global\n      retrieve: adaboost_coeff\n  4_adaboost_validate:\n    aggregation_type: openfl.interface.aggregation_functions.WeightedAverage\n    function: validate_adaboost\n    kwargs:\n      apply: local\n      data: test\n      retrieve: adaboost\n  settings: {}\n'
Arguments: ()
--- Logging error ---
Traceback (most recent call last):
  File "C:\Users\DELL\AppData\Roaming\Python\Python38\site-packages\rich\logging.py", line 170, in emit
    self.console.print(log_renderable)
  File "C:\Users\DELL\AppData\Roaming\Python\Python38\site-packages\rich\console.py", line 1720, in print
    self._buffer.extend(new_segments)
  File "C:\Users\DELL\AppData\Roaming\Python\Python38\site-packages\rich\console.py", line 864, in __exit__
    self._exit_buffer()
  File "C:\Users\DELL\AppData\Roaming\Python\Python38\site-packages\rich\console.py", line 822, in _exit_buffer
    self._check_buffer()
  File "C:\Users\DELL\AppData\Roaming\Python\Python38\site-packages\rich\console.py", line 2027, in _check_buffer
    legacy_windows_render(buffer, LegacyWindowsTerm(self.file))
  File "C:\Users\DELL\AppData\Roaming\Python\Python38\site-packages\rich\_windows_renderer.py", line 19, in legacy_windows_render
    term.write_text(text)
  File "C:\Users\DELL\AppData\Roaming\Python\Python38\site-packages\rich\_win32_console.py", line 403, in write_text
    self.write(text)
  File "C:\Users\DELL\anaconda3\envs\myenv\lib\encodings\cp1252.py", line 19, in encode
    return codecs.charmap_encode(input,self.errors,encoding_table)[0]
UnicodeEncodeError: 'charmap' codec can't encode character '\U0001f9ff' in position 0: character maps to <undefined>
Call stack:
  File "C:\Users\DELL\anaconda3\envs\myenv\lib\runpy.py", line 194, in _run_module_as_main
    return _run_code(code, main_globals, None,
  File "C:\Users\DELL\anaconda3\envs\myenv\lib\runpy.py", line 87, in _run_code
    exec(code, run_globals)
  File "C:\Users\DELL\anaconda3\envs\myenv\Scripts\fx.exe\__main__.py", line 7, in <module>
    sys.exit(entry())
  File "C:\Users\DELL\AppData\Roaming\Python\Python38\site-packages\openfl\interface\cli.py", line 212, in entry
    cli()
  File "C:\Users\DELL\AppData\Roaming\Python\Python38\site-packages\click\core.py", line 1137, in __call__
    return self.main(*args, **kwargs)
  File "C:\Users\DELL\AppData\Roaming\Python\Python38\site-packages\click\core.py", line 1062, in main
    rv = self.invoke(ctx)
  File "C:\Users\DELL\AppData\Roaming\Python\Python38\site-packages\click\core.py", line 1668, in invoke
    return _process_result(sub_ctx.command.invoke(sub_ctx))
  File "C:\Users\DELL\AppData\Roaming\Python\Python38\site-packages\click\core.py", line 1668, in invoke
    return _process_result(sub_ctx.command.invoke(sub_ctx))
  File "C:\Users\DELL\AppData\Roaming\Python\Python38\site-packages\click\core.py", line 1404, in invoke
    return ctx.invoke(self.callback, **ctx.params)
  File "C:\Users\DELL\AppData\Roaming\Python\Python38\site-packages\click\core.py", line 763, in invoke
    return __callback(*args, **kwargs)
  File "C:\Users\DELL\AppData\Roaming\Python\Python38\site-packages\openfl\interface\director.py", line 104, in start
    director_server.start()
  File "C:\Users\DELL\AppData\Roaming\Python\Python38\site-packages\openfl\transport\grpc\director_server.py", line 94, in start
    loop.run_until_complete(self._run_server())
  File "C:\Users\DELL\anaconda3\envs\myenv\lib\asyncio\base_events.py", line 603, in run_until_complete
    self.run_forever()
  File "C:\Users\DELL\anaconda3\envs\myenv\lib\asyncio\windows_events.py", line 316, in run_forever
    super().run_forever()
  File "C:\Users\DELL\anaconda3\envs\myenv\lib\asyncio\base_events.py", line 570, in run_forever
    self._run_once()
  File "C:\Users\DELL\anaconda3\envs\myenv\lib\asyncio\base_events.py", line 1859, in _run_once
    handle._run()
  File "C:\Users\DELL\anaconda3\envs\myenv\lib\asyncio\events.py", line 81, in _run
    self._context.run(self._callback, *self._args)
  File "C:\Users\DELL\AppData\Roaming\Python\Python38\site-packages\openfl\component\director\experiment.py", line 72, in start
    aggregator_grpc_server = self._create_aggregator_grpc_server(
  File "C:\Users\DELL\AppData\Roaming\Python\Python38\site-packages\openfl\component\director\experiment.py", line 98, in _create_aggregator_grpc_server
    logger.info('\U0001f9ff Starting the Aggregator Service.')
  File "C:\Users\DELL\anaconda3\envs\myenv\lib\logging\__init__.py", line 1446, in info
    self._log(INFO, msg, args, **kwargs)
  File "C:\Users\DELL\anaconda3\envs\myenv\lib\logging\__init__.py", line 1589, in _log
    self.handle(record)
  File "C:\Users\DELL\anaconda3\envs\myenv\lib\logging\__init__.py", line 1599, in handle
    self.callHandlers(record)
  File "C:\Users\DELL\anaconda3\envs\myenv\lib\logging\__init__.py", line 1661, in callHandlers
    hdlr.handle(record)
  File "C:\Users\DELL\anaconda3\envs\myenv\lib\logging\__init__.py", line 954, in handle
    self.emit(record)
[19:43:03] INFO       File "C:\Users\DELL\AppData\Roaming\Python\Python38\site-packages\rich\logging.py", line 172, in emit
    self.handleError(record)
Message: '\U0001f9ff Starting the Aggregator Service.'
Arguments: ()
--- Logging error ---
Traceback (most recent call last):
  File "C:\Users\DELL\AppData\Roaming\Python\Python38\site-packages\rich\logging.py", line 170, in emit
    self.console.print(log_renderable)
  File "C:\Users\DELL\AppData\Roaming\Python\Python38\site-packages\rich\console.py", line 1720, in print
    self._buffer.extend(new_segments)
  File "C:\Users\DELL\AppData\Roaming\Python\Python38\site-packages\rich\console.py", line 864, in __exit__
    self._exit_buffer()
  File "C:\Users\DELL\AppData\Roaming\Python\Python38\site-packages\rich\console.py", line 822, in _exit_buffer
    self._check_buffer()
  File "C:\Users\DELL\AppData\Roaming\Python\Python38\site-packages\rich\console.py", line 2027, in _check_buffer
    legacy_windows_render(buffer, LegacyWindowsTerm(self.file))
  File "C:\Users\DELL\AppData\Roaming\Python\Python38\site-packages\rich\_windows_renderer.py", line 19, in legacy_windows_render
    term.write_text(text)
  File "C:\Users\DELL\AppData\Roaming\Python\Python38\site-packages\rich\_win32_console.py", line 403, in write_text
    self.write(text)
  File "C:\Users\DELL\anaconda3\envs\myenv\lib\encodings\cp1252.py", line 19, in encode
    return codecs.charmap_encode(input,self.errors,encoding_table)[0]
UnicodeEncodeError: 'charmap' codec can't encode character '\U0001f9ff' in position 0: character maps to <undefined>
Call stack:
  File "C:\Users\DELL\anaconda3\envs\myenv\lib\runpy.py", line 194, in _run_module_as_main
    return _run_code(code, main_globals, None,
  File "C:\Users\DELL\anaconda3\envs\myenv\lib\runpy.py", line 87, in _run_code
    exec(code, run_globals)
  File "C:\Users\DELL\anaconda3\envs\myenv\Scripts\fx.exe\__main__.py", line 7, in <module>
    sys.exit(entry())
  File "C:\Users\DELL\AppData\Roaming\Python\Python38\site-packages\openfl\interface\cli.py", line 212, in entry
    cli()
  File "C:\Users\DELL\AppData\Roaming\Python\Python38\site-packages\click\core.py", line 1137, in __call__
    return self.main(*args, **kwargs)
  File "C:\Users\DELL\AppData\Roaming\Python\Python38\site-packages\click\core.py", line 1062, in main
    rv = self.invoke(ctx)
  File "C:\Users\DELL\AppData\Roaming\Python\Python38\site-packages\click\core.py", line 1668, in invoke
    return _process_result(sub_ctx.command.invoke(sub_ctx))
  File "C:\Users\DELL\AppData\Roaming\Python\Python38\site-packages\click\core.py", line 1668, in invoke
    return _process_result(sub_ctx.command.invoke(sub_ctx))
  File "C:\Users\DELL\AppData\Roaming\Python\Python38\site-packages\click\core.py", line 1404, in invoke
    return ctx.invoke(self.callback, **ctx.params)
  File "C:\Users\DELL\AppData\Roaming\Python\Python38\site-packages\click\core.py", line 763, in invoke
    return __callback(*args, **kwargs)
  File "C:\Users\DELL\AppData\Roaming\Python\Python38\site-packages\openfl\interface\director.py", line 104, in start
    director_server.start()
  File "C:\Users\DELL\AppData\Roaming\Python\Python38\site-packages\openfl\transport\grpc\director_server.py", line 94, in start
    loop.run_until_complete(self._run_server())
  File "C:\Users\DELL\anaconda3\envs\myenv\lib\asyncio\base_events.py", line 603, in run_until_complete
    self.run_forever()
  File "C:\Users\DELL\anaconda3\envs\myenv\lib\asyncio\windows_events.py", line 316, in run_forever
    super().run_forever()
  File "C:\Users\DELL\anaconda3\envs\myenv\lib\asyncio\base_events.py", line 570, in run_forever
    self._run_once()
  File "C:\Users\DELL\anaconda3\envs\myenv\lib\asyncio\base_events.py", line 1859, in _run_once
    handle._run()
  File "C:\Users\DELL\anaconda3\envs\myenv\lib\asyncio\events.py", line 81, in _run
    self._context.run(self._callback, *self._args)
  File "C:\Users\DELL\AppData\Roaming\Python\Python38\site-packages\openfl\component\director\experiment.py", line 72, in start
    aggregator_grpc_server = self._create_aggregator_grpc_server(
  File "C:\Users\DELL\AppData\Roaming\Python\Python38\site-packages\openfl\component\director\experiment.py", line 99, in _create_aggregator_grpc_server
    aggregator_grpc_server = plan.interactive_api_get_server(
  File "C:\Users\DELL\AppData\Roaming\Python\Python38\site-packages\openfl\federated\plan\plan.py", line 566, in interactive_api_get_server
    server_args['aggregator'] = self.get_aggregator(tensor_dict)
  File "C:\Users\DELL\AppData\Roaming\Python\Python38\site-packages\openfl\federated\plan\plan.py", line 324, in get_aggregator
    defaults[SETTINGS]['assigner'] = self.get_assigner(nn)
  File "C:\Users\DELL\AppData\Roaming\Python\Python38\site-packages\openfl\federated\plan\plan.py", line 261, in get_assigner
    aggregation_functions_by_task = self.restore_object('aggregation_function_obj.pkl')
  File "C:\Users\DELL\AppData\Roaming\Python\Python38\site-packages\openfl\federated\plan\plan.py", line 598, in restore_object
    serializer_plugin = self.get_serializer_plugin()
  File "C:\Users\DELL\AppData\Roaming\Python\Python38\site-packages\openfl\federated\plan\plan.py", line 593, in get_serializer_plugin
    self.serializer_ = Plan.build(serializer_plugin, kwargs)
  File "C:\Users\DELL\AppData\Roaming\Python\Python38\site-packages\openfl\federated\plan\plan.py", line 171, in build
    Plan.logger.info(f'Building [red]\U0001f846[/] Object [red]{class_name}[/] '
  File "C:\Users\DELL\anaconda3\envs\myenv\lib\logging\__init__.py", line 1446, in info
    self._log(INFO, msg, args, **kwargs)
  File "C:\Users\DELL\anaconda3\envs\myenv\lib\logging\__init__.py", line 1589, in _log
    self.handle(record)
  File "C:\Users\DELL\anaconda3\envs\myenv\lib\logging\__init__.py", line 1599, in handle
    self.callHandlers(record)
  File "C:\Users\DELL\anaconda3\envs\myenv\lib\logging\__init__.py", line 1661, in callHandlers
    hdlr.handle(record)
  File "C:\Users\DELL\anaconda3\envs\myenv\lib\logging\__init__.py", line 954, in handle
    self.emit(record)
  File "C:\Users\DELL\AppData\Roaming\Python\Python38\site-packages\rich\logging.py", line 172, in emit
    self.handleError(record)
Message: 'Building [red]\U0001f846[/] Object [red]DillSerializer[/] from [red]openfl.plugins.interface_serializer.dill_serializer[/] Module.'
Arguments: ()
--- Logging error ---
Traceback (most recent call last):
  File "C:\Users\DELL\AppData\Roaming\Python\Python38\site-packages\rich\logging.py", line 170, in emit
    self.console.print(log_renderable)
  File "C:\Users\DELL\AppData\Roaming\Python\Python38\site-packages\rich\console.py", line 1720, in print
    self._buffer.extend(new_segments)
  File "C:\Users\DELL\AppData\Roaming\Python\Python38\site-packages\rich\console.py", line 864, in __exit__
    self._exit_buffer()
  File "C:\Users\DELL\AppData\Roaming\Python\Python38\site-packages\rich\console.py", line 822, in _exit_buffer
    self._check_buffer()
  File "C:\Users\DELL\AppData\Roaming\Python\Python38\site-packages\rich\console.py", line 2027, in _check_buffer
    legacy_windows_render(buffer, LegacyWindowsTerm(self.file))
  File "C:\Users\DELL\AppData\Roaming\Python\Python38\site-packages\rich\_windows_renderer.py", line 19, in legacy_windows_render
    term.write_text(text)
  File "C:\Users\DELL\AppData\Roaming\Python\Python38\site-packages\rich\_win32_console.py", line 403, in write_text
    self.write(text)
  File "C:\Users\DELL\anaconda3\envs\myenv\lib\encodings\cp1252.py", line 19, in encode
    return codecs.charmap_encode(input,self.errors,encoding_table)[0]
UnicodeEncodeError: 'charmap' codec can't encode character '\U0001f9ff' in position 0: character maps to <undefined>
Call stack:
  File "C:\Users\DELL\anaconda3\envs\myenv\lib\runpy.py", line 194, in _run_module_as_main
    return _run_code(code, main_globals, None,
  File "C:\Users\DELL\anaconda3\envs\myenv\lib\runpy.py", line 87, in _run_code
    exec(code, run_globals)
[19:43:03] INFO     [19:43:03] INFO       File "C:\Users\DELL\anaconda3\envs\myenv\Scripts\fx.exe\__main__.py", line 7, in <module>
    sys.exit(entry())
  File "C:\Users\DELL\AppData\Roaming\Python\Python38\site-packages\openfl\interface\cli.py", line 212, in entry
    cli()
  File "C:\Users\DELL\AppData\Roaming\Python\Python38\site-packages\click\core.py", line 1137, in __call__
    return self.main(*args, **kwargs)
  File "C:\Users\DELL\AppData\Roaming\Python\Python38\site-packages\click\core.py", line 1062, in main
    rv = self.invoke(ctx)
  File "C:\Users\DELL\AppData\Roaming\Python\Python38\site-packages\click\core.py", line 1668, in invoke
    return _process_result(sub_ctx.command.invoke(sub_ctx))
  File "C:\Users\DELL\AppData\Roaming\Python\Python38\site-packages\click\core.py", line 1668, in invoke
    return _process_result(sub_ctx.command.invoke(sub_ctx))
  File "C:\Users\DELL\AppData\Roaming\Python\Python38\site-packages\click\core.py", line 1404, in invoke
    return ctx.invoke(self.callback, **ctx.params)
  File "C:\Users\DELL\AppData\Roaming\Python\Python38\site-packages\click\core.py", line 763, in invoke
    return __callback(*args, **kwargs)
  File "C:\Users\DELL\AppData\Roaming\Python\Python38\site-packages\openfl\interface\director.py", line 104, in start
    director_server.start()
  File "C:\Users\DELL\AppData\Roaming\Python\Python38\site-packages\openfl\transport\grpc\director_server.py", line 94, in start
    loop.run_until_complete(self._run_server())
  File "C:\Users\DELL\anaconda3\envs\myenv\lib\asyncio\base_events.py", line 603, in run_until_complete
    self.run_forever()
  File "C:\Users\DELL\anaconda3\envs\myenv\lib\asyncio\windows_events.py", line 316, in run_forever
    super().run_forever()
  File "C:\Users\DELL\anaconda3\envs\myenv\lib\asyncio\base_events.py", line 570, in run_forever
    self._run_once()
  File "C:\Users\DELL\anaconda3\envs\myenv\lib\asyncio\base_events.py", line 1859, in _run_once
    handle._run()
  File "C:\Users\DELL\anaconda3\envs\myenv\lib\asyncio\events.py", line 81, in _run
    self._context.run(self._callback, *self._args)
  File "C:\Users\DELL\AppData\Roaming\Python\Python38\site-packages\openfl\component\director\experiment.py", line 72, in start
    aggregator_grpc_server = self._create_aggregator_grpc_server(
  File "C:\Users\DELL\AppData\Roaming\Python\Python38\site-packages\openfl\component\director\experiment.py", line 99, in _create_aggregator_grpc_server
    aggregator_grpc_server = plan.interactive_api_get_server(
  File "C:\Users\DELL\AppData\Roaming\Python\Python38\site-packages\openfl\federated\plan\plan.py", line 566, in interactive_api_get_server
    server_args['aggregator'] = self.get_aggregator(tensor_dict)
  File "C:\Users\DELL\AppData\Roaming\Python\Python38\site-packages\openfl\federated\plan\plan.py", line 324, in get_aggregator
    defaults[SETTINGS]['assigner'] = self.get_assigner(nn)
  File "C:\Users\DELL\AppData\Roaming\Python\Python38\site-packages\openfl\federated\plan\plan.py", line 288, in get_assigner
    self.assigner_ = Plan.build(**defaults)
  File "C:\Users\DELL\AppData\Roaming\Python\Python38\site-packages\openfl\federated\plan\plan.py", line 171, in build
    Plan.logger.info(f'Building [red]\U0001f846[/] Object [red]{class_name}[/] '
  File "C:\Users\DELL\anaconda3\envs\myenv\lib\logging\__init__.py", line 1446, in info
    self._log(INFO, msg, args, **kwargs)
  File "C:\Users\DELL\anaconda3\envs\myenv\lib\logging\__init__.py", line 1589, in _log
    self.handle(record)
  File "C:\Users\DELL\anaconda3\envs\myenv\lib\logging\__init__.py", line 1599, in handle
    self.callHandlers(record)
  File "C:\Users\DELL\anaconda3\envs\myenv\lib\logging\__init__.py", line 1661, in callHandlers
    hdlr.handle(record)
  File "C:\Users\DELL\anaconda3\envs\myenv\lib\logging\__init__.py", line 954, in handle
    self.emit(record)
  File "C:\Users\DELL\AppData\Roaming\Python\Python38\site-packages\rich\logging.py", line 172, in emit
    self.handleError(record)
Message: 'Building [red]\U0001f846[/] Object [red]AdaBoostAssigner[/] from [red]openfl.component.assigner[/] Module.'
Arguments: ()
--- Logging error ---
Traceback (most recent call last):
  File "C:\Users\DELL\AppData\Roaming\Python\Python38\site-packages\rich\logging.py", line 170, in emit
    self.console.print(log_renderable)
  File "C:\Users\DELL\AppData\Roaming\Python\Python38\site-packages\rich\console.py", line 1720, in print
    self._buffer.extend(new_segments)
  File "C:\Users\DELL\AppData\Roaming\Python\Python38\site-packages\rich\console.py", line 864, in __exit__
    self._exit_buffer()
  File "C:\Users\DELL\AppData\Roaming\Python\Python38\site-packages\rich\console.py", line 822, in _exit_buffer
    self._check_buffer()
  File "C:\Users\DELL\AppData\Roaming\Python\Python38\site-packages\rich\console.py", line 2027, in _check_buffer
    legacy_windows_render(buffer, LegacyWindowsTerm(self.file))
  File "C:\Users\DELL\AppData\Roaming\Python\Python38\site-packages\rich\_windows_renderer.py", line 19, in legacy_windows_render
    term.write_text(text)
  File "C:\Users\DELL\AppData\Roaming\Python\Python38\site-packages\rich\_win32_console.py", line 403, in write_text
    self.write(text)
  File "C:\Users\DELL\anaconda3\envs\myenv\lib\encodings\cp1252.py", line 19, in encode
    return codecs.charmap_encode(input,self.errors,encoding_table)[0]
UnicodeEncodeError: 'charmap' codec can't encode character '\U0001f9ff' in position 0: character maps to <undefined>
Call stack:
  File "C:\Users\DELL\anaconda3\envs\myenv\lib\runpy.py", line 194, in _run_module_as_main
    return _run_code(code, main_globals, None,
  File "C:\Users\DELL\anaconda3\envs\myenv\lib\runpy.py", line 87, in _run_code
    exec(code, run_globals)
  File "C:\Users\DELL\anaconda3\envs\myenv\Scripts\fx.exe\__main__.py", line 7, in <module>
    sys.exit(entry())
  File "C:\Users\DELL\AppData\Roaming\Python\Python38\site-packages\openfl\interface\cli.py", line 212, in entry
    cli()
  File "C:\Users\DELL\AppData\Roaming\Python\Python38\site-packages\click\core.py", line 1137, in __call__
    return self.main(*args, **kwargs)
  File "C:\Users\DELL\AppData\Roaming\Python\Python38\site-packages\click\core.py", line 1062, in main
    rv = self.invoke(ctx)
  File "C:\Users\DELL\AppData\Roaming\Python\Python38\site-packages\click\core.py", line 1668, in invoke
    return _process_result(sub_ctx.command.invoke(sub_ctx))
  File "C:\Users\DELL\AppData\Roaming\Python\Python38\site-packages\click\core.py", line 1668, in invoke
    return _process_result(sub_ctx.command.invoke(sub_ctx))
  File "C:\Users\DELL\AppData\Roaming\Python\Python38\site-packages\click\core.py", line 1404, in invoke
    return ctx.invoke(self.callback, **ctx.params)
  File "C:\Users\DELL\AppData\Roaming\Python\Python38\site-packages\click\core.py", line 763, in invoke
    return __callback(*args, **kwargs)
  File "C:\Users\DELL\AppData\Roaming\Python\Python38\site-packages\openfl\interface\director.py", line 104, in start
    director_server.start()
  File "C:\Users\DELL\AppData\Roaming\Python\Python38\site-packages\openfl\transport\grpc\director_server.py", line 94, in start
    loop.run_until_complete(self._run_server())
  File "C:\Users\DELL\anaconda3\envs\myenv\lib\asyncio\base_events.py", line 603, in run_until_complete
    self.run_forever()
  File "C:\Users\DELL\anaconda3\envs\myenv\lib\asyncio\windows_events.py", line 316, in run_forever
    super().run_forever()
  File "C:\Users\DELL\anaconda3\envs\myenv\lib\asyncio\base_events.py", line 570, in run_forever
    self._run_once()
  File "C:\Users\DELL\anaconda3\envs\myenv\lib\asyncio\base_events.py", line 1859, in _run_once
    handle._run()
  File "C:\Users\DELL\anaconda3\envs\myenv\lib\asyncio\events.py", line 81, in _run
    self._context.run(self._callback, *self._args)
  File "C:\Users\DELL\AppData\Roaming\Python\Python38\site-packages\openfl\component\director\experiment.py", line 72, in start
    aggregator_grpc_server = self._create_aggregator_grpc_server(
[19:43:03] INFO       File "C:\Users\DELL\AppData\Roaming\Python\Python38\site-packages\openfl\component\director\experiment.py", line 99, in _create_aggregator_grpc_server
    aggregator_grpc_server = plan.interactive_api_get_server(
  File "C:\Users\DELL\AppData\Roaming\Python\Python38\site-packages\openfl\federated\plan\plan.py", line 566, in interactive_api_get_server
    server_args['aggregator'] = self.get_aggregator(tensor_dict)
  File "C:\Users\DELL\AppData\Roaming\Python\Python38\site-packages\openfl\federated\plan\plan.py", line 325, in get_aggregator
    defaults[SETTINGS]['compression_pipeline'] = self.get_tensor_pipe()
  File "C:\Users\DELL\AppData\Roaming\Python\Python38\site-packages\openfl\federated\plan\plan.py", line 353, in get_tensor_pipe
    self.pipe_ = Plan.build(**defaults)
  File "C:\Users\DELL\AppData\Roaming\Python\Python38\site-packages\openfl\federated\plan\plan.py", line 171, in build
    Plan.logger.info(f'Building [red]\U0001f846[/] Object [red]{class_name}[/] '
  File "C:\Users\DELL\anaconda3\envs\myenv\lib\logging\__init__.py", line 1446, in info
    self._log(INFO, msg, args, **kwargs)
  File "C:\Users\DELL\anaconda3\envs\myenv\lib\logging\__init__.py", line 1589, in _log
    self.handle(record)
  File "C:\Users\DELL\anaconda3\envs\myenv\lib\logging\__init__.py", line 1599, in handle
    self.callHandlers(record)
  File "C:\Users\DELL\anaconda3\envs\myenv\lib\logging\__init__.py", line 1661, in callHandlers
    hdlr.handle(record)
  File "C:\Users\DELL\anaconda3\envs\myenv\lib\logging\__init__.py", line 954, in handle
    self.emit(record)
  File "C:\Users\DELL\AppData\Roaming\Python\Python38\site-packages\rich\logging.py", line 172, in emit
    self.handleError(record)
Message: 'Building [red]\U0001f846[/] Object [red]GenericPipeline[/] from [red]openfl.pipelines[/] Module.'
Arguments: ()
--- Logging error ---
Traceback (most recent call last):
  File "C:\Users\DELL\AppData\Roaming\Python\Python38\site-packages\rich\logging.py", line 170, in emit
    self.console.print(log_renderable)
  File "C:\Users\DELL\AppData\Roaming\Python\Python38\site-packages\rich\console.py", line 1720, in print
    self._buffer.extend(new_segments)
  File "C:\Users\DELL\AppData\Roaming\Python\Python38\site-packages\rich\console.py", line 864, in __exit__
    self._exit_buffer()
  File "C:\Users\DELL\AppData\Roaming\Python\Python38\site-packages\rich\console.py", line 822, in _exit_buffer
    self._check_buffer()
  File "C:\Users\DELL\AppData\Roaming\Python\Python38\site-packages\rich\console.py", line 2027, in _check_buffer
    legacy_windows_render(buffer, LegacyWindowsTerm(self.file))
  File "C:\Users\DELL\AppData\Roaming\Python\Python38\site-packages\rich\_windows_renderer.py", line 19, in legacy_windows_render
    term.write_text(text)
  File "C:\Users\DELL\AppData\Roaming\Python\Python38\site-packages\rich\_win32_console.py", line 403, in write_text
    self.write(text)
  File "C:\Users\DELL\anaconda3\envs\myenv\lib\encodings\cp1252.py", line 19, in encode
    return codecs.charmap_encode(input,self.errors,encoding_table)[0]
UnicodeEncodeError: 'charmap' codec can't encode character '\U0001f9ff' in position 0: character maps to <undefined>
Call stack:
  File "C:\Users\DELL\anaconda3\envs\myenv\lib\runpy.py", line 194, in _run_module_as_main
    return _run_code(code, main_globals, None,
  File "C:\Users\DELL\anaconda3\envs\myenv\lib\runpy.py", line 87, in _run_code
    exec(code, run_globals)
  File "C:\Users\DELL\anaconda3\envs\myenv\Scripts\fx.exe\__main__.py", line 7, in <module>
    sys.exit(entry())
  File "C:\Users\DELL\AppData\Roaming\Python\Python38\site-packages\openfl\interface\cli.py", line 212, in entry
    cli()
  File "C:\Users\DELL\AppData\Roaming\Python\Python38\site-packages\click\core.py", line 1137, in __call__
    return self.main(*args, **kwargs)
  File "C:\Users\DELL\AppData\Roaming\Python\Python38\site-packages\click\core.py", line 1062, in main
    rv = self.invoke(ctx)
  File "C:\Users\DELL\AppData\Roaming\Python\Python38\site-packages\click\core.py", line 1668, in invoke
    return _process_result(sub_ctx.command.invoke(sub_ctx))
  File "C:\Users\DELL\AppData\Roaming\Python\Python38\site-packages\click\core.py", line 1668, in invoke
    return _process_result(sub_ctx.command.invoke(sub_ctx))
  File "C:\Users\DELL\AppData\Roaming\Python\Python38\site-packages\click\core.py", line 1404, in invoke
    return ctx.invoke(self.callback, **ctx.params)
  File "C:\Users\DELL\AppData\Roaming\Python\Python38\site-packages\click\core.py", line 763, in invoke
    return __callback(*args, **kwargs)
  File "C:\Users\DELL\AppData\Roaming\Python\Python38\site-packages\openfl\interface\director.py", line 104, in start
    director_server.start()
  File "C:\Users\DELL\AppData\Roaming\Python\Python38\site-packages\openfl\transport\grpc\director_server.py", line 94, in start
    loop.run_until_complete(self._run_server())
  File "C:\Users\DELL\anaconda3\envs\myenv\lib\asyncio\base_events.py", line 603, in run_until_complete
    self.run_forever()
  File "C:\Users\DELL\anaconda3\envs\myenv\lib\asyncio\windows_events.py", line 316, in run_forever
    super().run_forever()
  File "C:\Users\DELL\anaconda3\envs\myenv\lib\asyncio\base_events.py", line 570, in run_forever
    self._run_once()
  File "C:\Users\DELL\anaconda3\envs\myenv\lib\asyncio\base_events.py", line 1859, in _run_once
    handle._run()
  File "C:\Users\DELL\anaconda3\envs\myenv\lib\asyncio\events.py", line 81, in _run
    self._context.run(self._callback, *self._args)
  File "C:\Users\DELL\AppData\Roaming\Python\Python38\site-packages\openfl\component\director\experiment.py", line 72, in start
    aggregator_grpc_server = self._create_aggregator_grpc_server(
  File "C:\Users\DELL\AppData\Roaming\Python\Python38\site-packages\openfl\component\director\experiment.py", line 99, in _create_aggregator_grpc_server
    aggregator_grpc_server = plan.interactive_api_get_server(
  File "C:\Users\DELL\AppData\Roaming\Python\Python38\site-packages\openfl\federated\plan\plan.py", line 566, in interactive_api_get_server
    server_args['aggregator'] = self.get_aggregator(tensor_dict)
  File "C:\Users\DELL\AppData\Roaming\Python\Python38\site-packages\openfl\federated\plan\plan.py", line 326, in get_aggregator
    defaults[SETTINGS]['straggler_handling_policy'] = self.get_straggler_handling_policy()
  File "C:\Users\DELL\AppData\Roaming\Python\Python38\site-packages\openfl\federated\plan\plan.py", line 368, in get_straggler_handling_policy
    self.straggler_policy_ = Plan.build(**defaults)
  File "C:\Users\DELL\AppData\Roaming\Python\Python38\site-packages\openfl\federated\plan\plan.py", line 171, in build
    Plan.logger.info(f'Building [red]\U0001f846[/] Object [red]{class_name}[/] '
  File "C:\Users\DELL\anaconda3\envs\myenv\lib\logging\__init__.py", line 1446, in info
    self._log(INFO, msg, args, **kwargs)
  File "C:\Users\DELL\anaconda3\envs\myenv\lib\logging\__init__.py", line 1589, in _log
    self.handle(record)
  File "C:\Users\DELL\anaconda3\envs\myenv\lib\logging\__init__.py", line 1599, in handle
    self.callHandlers(record)
  File "C:\Users\DELL\anaconda3\envs\myenv\lib\logging\__init__.py", line 1661, in callHandlers
    hdlr.handle(record)
  File "C:\Users\DELL\anaconda3\envs\myenv\lib\logging\__init__.py", line 954, in handle
    self.emit(record)
  File "C:\Users\DELL\AppData\Roaming\Python\Python38\site-packages\rich\logging.py", line 172, in emit
    self.handleError(record)
Message: 'Building [red]\U0001f846[/] Object [red]CutoffTimeBasedStragglerHandling[/] from [red]openfl.component.straggler_handling_functions[/] Module.'
Arguments: ()
--- Logging error ---
Traceback (most recent call last):
  File "C:\Users\DELL\AppData\Roaming\Python\Python38\site-packages\rich\logging.py", line 170, in emit
    self.console.print(log_renderable)
  File "C:\Users\DELL\AppData\Roaming\Python\Python38\site-packages\rich\console.py", line 1720, in print
    self._buffer.extend(new_segments)
[19:43:03] INFO     [19:43:03] INFO       File "C:\Users\DELL\AppData\Roaming\Python\Python38\site-packages\rich\console.py", line 864, in __exit__
    self._exit_buffer()
  File "C:\Users\DELL\AppData\Roaming\Python\Python38\site-packages\rich\console.py", line 822, in _exit_buffer
    self._check_buffer()
  File "C:\Users\DELL\AppData\Roaming\Python\Python38\site-packages\rich\console.py", line 2027, in _check_buffer
    legacy_windows_render(buffer, LegacyWindowsTerm(self.file))
  File "C:\Users\DELL\AppData\Roaming\Python\Python38\site-packages\rich\_windows_renderer.py", line 19, in legacy_windows_render
    term.write_text(text)
  File "C:\Users\DELL\AppData\Roaming\Python\Python38\site-packages\rich\_win32_console.py", line 403, in write_text
    self.write(text)
  File "C:\Users\DELL\anaconda3\envs\myenv\lib\encodings\cp1252.py", line 19, in encode
    return codecs.charmap_encode(input,self.errors,encoding_table)[0]
UnicodeEncodeError: 'charmap' codec can't encode character '\U0001f9ff' in position 0: character maps to <undefined>
Call stack:
  File "C:\Users\DELL\anaconda3\envs\myenv\lib\runpy.py", line 194, in _run_module_as_main
    return _run_code(code, main_globals, None,
  File "C:\Users\DELL\anaconda3\envs\myenv\lib\runpy.py", line 87, in _run_code
    exec(code, run_globals)
  File "C:\Users\DELL\anaconda3\envs\myenv\Scripts\fx.exe\__main__.py", line 7, in <module>
    sys.exit(entry())
  File "C:\Users\DELL\AppData\Roaming\Python\Python38\site-packages\openfl\interface\cli.py", line 212, in entry
    cli()
  File "C:\Users\DELL\AppData\Roaming\Python\Python38\site-packages\click\core.py", line 1137, in __call__
    return self.main(*args, **kwargs)
  File "C:\Users\DELL\AppData\Roaming\Python\Python38\site-packages\click\core.py", line 1062, in main
    rv = self.invoke(ctx)
  File "C:\Users\DELL\AppData\Roaming\Python\Python38\site-packages\click\core.py", line 1668, in invoke
    return _process_result(sub_ctx.command.invoke(sub_ctx))
  File "C:\Users\DELL\AppData\Roaming\Python\Python38\site-packages\click\core.py", line 1668, in invoke
    return _process_result(sub_ctx.command.invoke(sub_ctx))
  File "C:\Users\DELL\AppData\Roaming\Python\Python38\site-packages\click\core.py", line 1404, in invoke
    return ctx.invoke(self.callback, **ctx.params)
  File "C:\Users\DELL\AppData\Roaming\Python\Python38\site-packages\click\core.py", line 763, in invoke
    return __callback(*args, **kwargs)
  File "C:\Users\DELL\AppData\Roaming\Python\Python38\site-packages\openfl\interface\director.py", line 104, in start
    director_server.start()
  File "C:\Users\DELL\AppData\Roaming\Python\Python38\site-packages\openfl\transport\grpc\director_server.py", line 94, in start
    loop.run_until_complete(self._run_server())
  File "C:\Users\DELL\anaconda3\envs\myenv\lib\asyncio\base_events.py", line 603, in run_until_complete
    self.run_forever()
  File "C:\Users\DELL\anaconda3\envs\myenv\lib\asyncio\windows_events.py", line 316, in run_forever
    super().run_forever()
  File "C:\Users\DELL\anaconda3\envs\myenv\lib\asyncio\base_events.py", line 570, in run_forever
    self._run_once()
  File "C:\Users\DELL\anaconda3\envs\myenv\lib\asyncio\base_events.py", line 1859, in _run_once
    handle._run()
  File "C:\Users\DELL\anaconda3\envs\myenv\lib\asyncio\events.py", line 81, in _run
    self._context.run(self._callback, *self._args)
  File "C:\Users\DELL\AppData\Roaming\Python\Python38\site-packages\openfl\component\director\experiment.py", line 72, in start
    aggregator_grpc_server = self._create_aggregator_grpc_server(
  File "C:\Users\DELL\AppData\Roaming\Python\Python38\site-packages\openfl\component\director\experiment.py", line 99, in _create_aggregator_grpc_server
    aggregator_grpc_server = plan.interactive_api_get_server(
  File "C:\Users\DELL\AppData\Roaming\Python\Python38\site-packages\openfl\federated\plan\plan.py", line 566, in interactive_api_get_server
    server_args['aggregator'] = self.get_aggregator(tensor_dict)
  File "C:\Users\DELL\AppData\Roaming\Python\Python38\site-packages\openfl\federated\plan\plan.py", line 338, in get_aggregator
    self.aggregator_ = Plan.build(**defaults, initial_tensor_dict=tensor_dict)
  File "C:\Users\DELL\AppData\Roaming\Python\Python38\site-packages\openfl\federated\plan\plan.py", line 171, in build
    Plan.logger.info(f'Building [red]\U0001f846[/] Object [red]{class_name}[/] '
  File "C:\Users\DELL\anaconda3\envs\myenv\lib\logging\__init__.py", line 1446, in info
    self._log(INFO, msg, args, **kwargs)
  File "C:\Users\DELL\anaconda3\envs\myenv\lib\logging\__init__.py", line 1589, in _log
    self.handle(record)
  File "C:\Users\DELL\anaconda3\envs\myenv\lib\logging\__init__.py", line 1599, in handle
    self.callHandlers(record)
  File "C:\Users\DELL\anaconda3\envs\myenv\lib\logging\__init__.py", line 1661, in callHandlers
    hdlr.handle(record)
  File "C:\Users\DELL\anaconda3\envs\myenv\lib\logging\__init__.py", line 954, in handle
    self.emit(record)
  File "C:\Users\DELL\AppData\Roaming\Python\Python38\site-packages\rich\logging.py", line 172, in emit
    self.handleError(record)
Message: 'Building [red]\U0001f846[/] Object [red]Aggregator[/] from [red]openfl.component.aggregator[/] Module.'
Arguments: ()
--- Logging error ---
Traceback (most recent call last):
  File "C:\Users\DELL\AppData\Roaming\Python\Python38\site-packages\rich\logging.py", line 170, in emit
    self.console.print(log_renderable)
  File "C:\Users\DELL\AppData\Roaming\Python\Python38\site-packages\rich\console.py", line 1720, in print
    self._buffer.extend(new_segments)
  File "C:\Users\DELL\AppData\Roaming\Python\Python38\site-packages\rich\console.py", line 864, in __exit__
    self._exit_buffer()
  File "C:\Users\DELL\AppData\Roaming\Python\Python38\site-packages\rich\console.py", line 822, in _exit_buffer
    self._check_buffer()
  File "C:\Users\DELL\AppData\Roaming\Python\Python38\site-packages\rich\console.py", line 2027, in _check_buffer
    legacy_windows_render(buffer, LegacyWindowsTerm(self.file))
  File "C:\Users\DELL\AppData\Roaming\Python\Python38\site-packages\rich\_windows_renderer.py", line 19, in legacy_windows_render
    term.write_text(text)
  File "C:\Users\DELL\AppData\Roaming\Python\Python38\site-packages\rich\_win32_console.py", line 403, in write_text
    self.write(text)
  File "C:\Users\DELL\anaconda3\envs\myenv\lib\encodings\cp1252.py", line 19, in encode
    return codecs.charmap_encode(input,self.errors,encoding_table)[0]
UnicodeEncodeError: 'charmap' codec can't encode character '\U0001f9ff' in position 0: character maps to <undefined>
Call stack:
  File "C:\Users\DELL\anaconda3\envs\myenv\lib\runpy.py", line 194, in _run_module_as_main
    return _run_code(code, main_globals, None,
  File "C:\Users\DELL\anaconda3\envs\myenv\lib\runpy.py", line 87, in _run_code
    exec(code, run_globals)
  File "C:\Users\DELL\anaconda3\envs\myenv\Scripts\fx.exe\__main__.py", line 7, in <module>
    sys.exit(entry())
  File "C:\Users\DELL\AppData\Roaming\Python\Python38\site-packages\openfl\interface\cli.py", line 212, in entry
    cli()
  File "C:\Users\DELL\AppData\Roaming\Python\Python38\site-packages\click\core.py", line 1137, in __call__
    return self.main(*args, **kwargs)
  File "C:\Users\DELL\AppData\Roaming\Python\Python38\site-packages\click\core.py", line 1062, in main
    rv = self.invoke(ctx)
  File "C:\Users\DELL\AppData\Roaming\Python\Python38\site-packages\click\core.py", line 1668, in invoke
    return _process_result(sub_ctx.command.invoke(sub_ctx))
  File "C:\Users\DELL\AppData\Roaming\Python\Python38\site-packages\click\core.py", line 1668, in invoke
    return _process_result(sub_ctx.command.invoke(sub_ctx))
  File "C:\Users\DELL\AppData\Roaming\Python\Python38\site-packages\click\core.py", line 1404, in invoke
    return ctx.invoke(self.callback, **ctx.params)
  File "C:\Users\DELL\AppData\Roaming\Python\Python38\site-packages\click\core.py", line 763, in invoke
    return __callback(*args, **kwargs)
[19:43:03] INFO       File "C:\Users\DELL\AppData\Roaming\Python\Python38\site-packages\openfl\interface\director.py", line 104, in start
    director_server.start()
  File "C:\Users\DELL\AppData\Roaming\Python\Python38\site-packages\openfl\transport\grpc\director_server.py", line 94, in start
    loop.run_until_complete(self._run_server())
  File "C:\Users\DELL\anaconda3\envs\myenv\lib\asyncio\base_events.py", line 603, in run_until_complete
    self.run_forever()
  File "C:\Users\DELL\anaconda3\envs\myenv\lib\asyncio\windows_events.py", line 316, in run_forever
    super().run_forever()
  File "C:\Users\DELL\anaconda3\envs\myenv\lib\asyncio\base_events.py", line 570, in run_forever
    self._run_once()
  File "C:\Users\DELL\anaconda3\envs\myenv\lib\asyncio\base_events.py", line 1859, in _run_once
    handle._run()
  File "C:\Users\DELL\anaconda3\envs\myenv\lib\asyncio\events.py", line 81, in _run
    self._context.run(self._callback, *self._args)
  File "C:\Users\DELL\AppData\Roaming\Python\Python38\site-packages\openfl\component\director\experiment.py", line 79, in start
    await self._run_aggregator_grpc_server(
  File "C:\Users\DELL\AppData\Roaming\Python\Python38\site-packages\openfl\component\director\experiment.py", line 111, in _run_aggregator_grpc_server
    logger.info('\U0001f9ff Starting the Aggregator Service.')
  File "C:\Users\DELL\anaconda3\envs\myenv\lib\logging\__init__.py", line 1446, in info
    self._log(INFO, msg, args, **kwargs)
  File "C:\Users\DELL\anaconda3\envs\myenv\lib\logging\__init__.py", line 1589, in _log
    self.handle(record)
  File "C:\Users\DELL\anaconda3\envs\myenv\lib\logging\__init__.py", line 1599, in handle
    self.callHandlers(record)
  File "C:\Users\DELL\anaconda3\envs\myenv\lib\logging\__init__.py", line 1661, in callHandlers
    hdlr.handle(record)
  File "C:\Users\DELL\anaconda3\envs\myenv\lib\logging\__init__.py", line 954, in handle
    self.emit(record)
  File "C:\Users\DELL\AppData\Roaming\Python\Python38\site-packages\rich\logging.py", line 172, in emit
    self.handleError(record)
Message: '\U0001f9ff Starting the Aggregator Service.'
Arguments: ()
--- Logging error ---
Traceback (most recent call last):
  File "C:\Users\DELL\AppData\Roaming\Python\Python38\site-packages\rich\logging.py", line 170, in emit
    self.console.print(log_renderable)
  File "C:\Users\DELL\AppData\Roaming\Python\Python38\site-packages\rich\console.py", line 1720, in print
    self._buffer.extend(new_segments)
  File "C:\Users\DELL\AppData\Roaming\Python\Python38\site-packages\rich\console.py", line 864, in __exit__
    self._exit_buffer()
  File "C:\Users\DELL\AppData\Roaming\Python\Python38\site-packages\rich\console.py", line 822, in _exit_buffer
    self._check_buffer()
  File "C:\Users\DELL\AppData\Roaming\Python\Python38\site-packages\rich\console.py", line 2027, in _check_buffer
    legacy_windows_render(buffer, LegacyWindowsTerm(self.file))
  File "C:\Users\DELL\AppData\Roaming\Python\Python38\site-packages\rich\_windows_renderer.py", line 19, in legacy_windows_render
    term.write_text(text)
  File "C:\Users\DELL\AppData\Roaming\Python\Python38\site-packages\rich\_win32_console.py", line 403, in write_text
    self.write(text)
  File "C:\Users\DELL\anaconda3\envs\myenv\lib\encodings\cp1252.py", line 19, in encode
    return codecs.charmap_encode(input,self.errors,encoding_table)[0]
UnicodeEncodeError: 'charmap' codec can't encode character '\U0001f9ff' in position 0: character maps to <undefined>
Call stack:
  File "C:\Users\DELL\anaconda3\envs\myenv\lib\runpy.py", line 194, in _run_module_as_main
    return _run_code(code, main_globals, None,
  File "C:\Users\DELL\anaconda3\envs\myenv\lib\runpy.py", line 87, in _run_code
    exec(code, run_globals)
  File "C:\Users\DELL\anaconda3\envs\myenv\Scripts\fx.exe\__main__.py", line 7, in <module>
    sys.exit(entry())
  File "C:\Users\DELL\AppData\Roaming\Python\Python38\site-packages\openfl\interface\cli.py", line 212, in entry
    cli()
  File "C:\Users\DELL\AppData\Roaming\Python\Python38\site-packages\click\core.py", line 1137, in __call__
    return self.main(*args, **kwargs)
  File "C:\Users\DELL\AppData\Roaming\Python\Python38\site-packages\click\core.py", line 1062, in main
    rv = self.invoke(ctx)
  File "C:\Users\DELL\AppData\Roaming\Python\Python38\site-packages\click\core.py", line 1668, in invoke
    return _process_result(sub_ctx.command.invoke(sub_ctx))
  File "C:\Users\DELL\AppData\Roaming\Python\Python38\site-packages\click\core.py", line 1668, in invoke
    return _process_result(sub_ctx.command.invoke(sub_ctx))
  File "C:\Users\DELL\AppData\Roaming\Python\Python38\site-packages\click\core.py", line 1404, in invoke
    return ctx.invoke(self.callback, **ctx.params)
  File "C:\Users\DELL\AppData\Roaming\Python\Python38\site-packages\click\core.py", line 763, in invoke
    return __callback(*args, **kwargs)
  File "C:\Users\DELL\AppData\Roaming\Python\Python38\site-packages\openfl\interface\director.py", line 104, in start
    director_server.start()
  File "C:\Users\DELL\AppData\Roaming\Python\Python38\site-packages\openfl\transport\grpc\director_server.py", line 94, in start
    loop.run_until_complete(self._run_server())
  File "C:\Users\DELL\anaconda3\envs\myenv\lib\asyncio\base_events.py", line 603, in run_until_complete
    self.run_forever()
  File "C:\Users\DELL\anaconda3\envs\myenv\lib\asyncio\windows_events.py", line 316, in run_forever
    super().run_forever()
  File "C:\Users\DELL\anaconda3\envs\myenv\lib\asyncio\base_events.py", line 570, in run_forever
    self._run_once()
  File "C:\Users\DELL\anaconda3\envs\myenv\lib\asyncio\base_events.py", line 1859, in _run_once
    handle._run()
  File "C:\Users\DELL\anaconda3\envs\myenv\lib\asyncio\events.py", line 81, in _run
    self._context.run(self._callback, *self._args)
  File "C:\Users\DELL\AppData\Roaming\Python\Python38\site-packages\openfl\component\director\experiment.py", line 79, in start
    await self._run_aggregator_grpc_server(
  File "C:\Users\DELL\AppData\Roaming\Python\Python38\site-packages\openfl\component\director\experiment.py", line 112, in _run_aggregator_grpc_server
    grpc_server = aggregator_grpc_server.get_server()
  File "C:\Users\DELL\AppData\Roaming\Python\Python38\site-packages\openfl\transport\grpc\aggregator_server.py", line 258, in get_server
    self.logger.warn(
  File "C:\Users\DELL\anaconda3\envs\myenv\lib\logging\__init__.py", line 1463, in warn
    self.warning(msg, *args, **kwargs)
  File "C:\Users\DELL\anaconda3\envs\myenv\lib\logging\__init__.py", line 1458, in warning
    self._log(WARNING, msg, args, **kwargs)
  File "C:\Users\DELL\anaconda3\envs\myenv\lib\logging\__init__.py", line 1589, in _log
    self.handle(record)
  File "C:\Users\DELL\anaconda3\envs\myenv\lib\logging\__init__.py", line 1599, in handle
    self.callHandlers(record)
  File "C:\Users\DELL\anaconda3\envs\myenv\lib\logging\__init__.py", line 1661, in callHandlers
    hdlr.handle(record)
  File "C:\Users\DELL\anaconda3\envs\myenv\lib\logging\__init__.py", line 954, in handle
    self.emit(record)
  File "C:\Users\DELL\AppData\Roaming\Python\Python38\site-packages\rich\logging.py", line 172, in emit
    self.handleError(record)
Message: 'gRPC is running on insecure channel with TLS disabled.'
Arguments: ()
--- Logging error ---
Traceback (most recent call last):
  File "C:\Users\DELL\AppData\Roaming\Python\Python38\site-packages\rich\logging.py", line 170, in emit
    self.console.print(log_renderable)
  File "C:\Users\DELL\AppData\Roaming\Python\Python38\site-packages\rich\console.py", line 1720, in print
    self._buffer.extend(new_segments)
  File "C:\Users\DELL\AppData\Roaming\Python\Python38\site-packages\rich\console.py", line 864, in __exit__
    self._exit_buffer()
  File "C:\Users\DELL\AppData\Roaming\Python\Python38\site-packages\rich\console.py", line 822, in _exit_buffer
    self._check_buffer()
[19:43:03] INFO     [19:43:42] INFO     Sending tasks to collaborator envoy_1 for round 0                                                                          aggregator.py:334
[19:43:03] INFO       File "C:\Users\DELL\AppData\Roaming\Python\Python38\site-packages\rich\console.py", line 2027, in _check_buffer
    legacy_windows_render(buffer, LegacyWindowsTerm(self.file))
  File "C:\Users\DELL\AppData\Roaming\Python\Python38\site-packages\rich\_windows_renderer.py", line 19, in legacy_windows_render
    term.write_text(text)
  File "C:\Users\DELL\AppData\Roaming\Python\Python38\site-packages\rich\_win32_console.py", line 403, in write_text
    self.write(text)
  File "C:\Users\DELL\anaconda3\envs\myenv\lib\encodings\cp1252.py", line 19, in encode
    return codecs.charmap_encode(input,self.errors,encoding_table)[0]
UnicodeEncodeError: 'charmap' codec can't encode character '\U0001f9ff' in position 0: character maps to <undefined>
Call stack:
  File "C:\Users\DELL\anaconda3\envs\myenv\lib\runpy.py", line 194, in _run_module_as_main
    return _run_code(code, main_globals, None,
  File "C:\Users\DELL\anaconda3\envs\myenv\lib\runpy.py", line 87, in _run_code
    exec(code, run_globals)
  File "C:\Users\DELL\anaconda3\envs\myenv\Scripts\fx.exe\__main__.py", line 7, in <module>
    sys.exit(entry())
  File "C:\Users\DELL\AppData\Roaming\Python\Python38\site-packages\openfl\interface\cli.py", line 212, in entry
    cli()
  File "C:\Users\DELL\AppData\Roaming\Python\Python38\site-packages\click\core.py", line 1137, in __call__
    return self.main(*args, **kwargs)
  File "C:\Users\DELL\AppData\Roaming\Python\Python38\site-packages\click\core.py", line 1062, in main
    rv = self.invoke(ctx)
  File "C:\Users\DELL\AppData\Roaming\Python\Python38\site-packages\click\core.py", line 1668, in invoke
    return _process_result(sub_ctx.command.invoke(sub_ctx))
  File "C:\Users\DELL\AppData\Roaming\Python\Python38\site-packages\click\core.py", line 1668, in invoke
    return _process_result(sub_ctx.command.invoke(sub_ctx))
  File "C:\Users\DELL\AppData\Roaming\Python\Python38\site-packages\click\core.py", line 1404, in invoke
    return ctx.invoke(self.callback, **ctx.params)
  File "C:\Users\DELL\AppData\Roaming\Python\Python38\site-packages\click\core.py", line 763, in invoke
    return __callback(*args, **kwargs)
  File "C:\Users\DELL\AppData\Roaming\Python\Python38\site-packages\openfl\interface\director.py", line 104, in start
    director_server.start()
  File "C:\Users\DELL\AppData\Roaming\Python\Python38\site-packages\openfl\transport\grpc\director_server.py", line 94, in start
    loop.run_until_complete(self._run_server())
  File "C:\Users\DELL\anaconda3\envs\myenv\lib\asyncio\base_events.py", line 603, in run_until_complete
    self.run_forever()
  File "C:\Users\DELL\anaconda3\envs\myenv\lib\asyncio\windows_events.py", line 316, in run_forever
    super().run_forever()
  File "C:\Users\DELL\anaconda3\envs\myenv\lib\asyncio\base_events.py", line 570, in run_forever
    self._run_once()
  File "C:\Users\DELL\anaconda3\envs\myenv\lib\asyncio\base_events.py", line 1859, in _run_once
    handle._run()
  File "C:\Users\DELL\anaconda3\envs\myenv\lib\asyncio\events.py", line 81, in _run
    self._context.run(self._callback, *self._args)
  File "C:\Users\DELL\AppData\Roaming\Python\Python38\site-packages\openfl\component\director\experiment.py", line 79, in start
    await self._run_aggregator_grpc_server(
  File "C:\Users\DELL\AppData\Roaming\Python\Python38\site-packages\openfl\component\director\experiment.py", line 112, in _run_aggregator_grpc_server
    grpc_server = aggregator_grpc_server.get_server()
  File "C:\Users\DELL\AppData\Roaming\Python\Python38\site-packages\openfl\transport\grpc\aggregator_server.py", line 261, in get_server
    self.logger.info(f'Insecure port: {port}')
  File "C:\Users\DELL\anaconda3\envs\myenv\lib\logging\__init__.py", line 1446, in info
    self._log(INFO, msg, args, **kwargs)
  File "C:\Users\DELL\anaconda3\envs\myenv\lib\logging\__init__.py", line 1589, in _log
    self.handle(record)
  File "C:\Users\DELL\anaconda3\envs\myenv\lib\logging\__init__.py", line 1599, in handle
    self.callHandlers(record)
  File "C:\Users\DELL\anaconda3\envs\myenv\lib\logging\__init__.py", line 1661, in callHandlers
    hdlr.handle(record)
  File "C:\Users\DELL\anaconda3\envs\myenv\lib\logging\__init__.py", line 954, in handle
    self.emit(record)
  File "C:\Users\DELL\AppData\Roaming\Python\Python38\site-packages\rich\logging.py", line 172, in emit
    self.handleError(record)
Message: 'Insecure port: 53234'
Arguments: ()
--- Logging error ---
Traceback (most recent call last):
  File "C:\Users\DELL\AppData\Roaming\Python\Python38\site-packages\rich\logging.py", line 170, in emit
    self.console.print(log_renderable)
  File "C:\Users\DELL\AppData\Roaming\Python\Python38\site-packages\rich\console.py", line 1720, in print
    self._buffer.extend(new_segments)
  File "C:\Users\DELL\AppData\Roaming\Python\Python38\site-packages\rich\console.py", line 864, in __exit__
    self._exit_buffer()
  File "C:\Users\DELL\AppData\Roaming\Python\Python38\site-packages\rich\console.py", line 822, in _exit_buffer
    self._check_buffer()
  File "C:\Users\DELL\AppData\Roaming\Python\Python38\site-packages\rich\console.py", line 2027, in _check_buffer
    legacy_windows_render(buffer, LegacyWindowsTerm(self.file))
  File "C:\Users\DELL\AppData\Roaming\Python\Python38\site-packages\rich\_windows_renderer.py", line 19, in legacy_windows_render
    term.write_text(text)
  File "C:\Users\DELL\AppData\Roaming\Python\Python38\site-packages\rich\_win32_console.py", line 403, in write_text
    self.write(text)
  File "C:\Users\DELL\anaconda3\envs\myenv\lib\encodings\cp1252.py", line 19, in encode
    return codecs.charmap_encode(input,self.errors,encoding_table)[0]
UnicodeEncodeError: 'charmap' codec can't encode character '\U0001f9ff' in position 0: character maps to <undefined>
Call stack:
  File "C:\Users\DELL\anaconda3\envs\myenv\lib\runpy.py", line 194, in _run_module_as_main
    return _run_code(code, main_globals, None,
  File "C:\Users\DELL\anaconda3\envs\myenv\lib\runpy.py", line 87, in _run_code
    exec(code, run_globals)
  File "C:\Users\DELL\anaconda3\envs\myenv\Scripts\fx.exe\__main__.py", line 7, in <module>
    sys.exit(entry())
  File "C:\Users\DELL\AppData\Roaming\Python\Python38\site-packages\openfl\interface\cli.py", line 212, in entry
    cli()
  File "C:\Users\DELL\AppData\Roaming\Python\Python38\site-packages\click\core.py", line 1137, in __call__
    return self.main(*args, **kwargs)
  File "C:\Users\DELL\AppData\Roaming\Python\Python38\site-packages\click\core.py", line 1062, in main
    rv = self.invoke(ctx)
  File "C:\Users\DELL\AppData\Roaming\Python\Python38\site-packages\click\core.py", line 1668, in invoke
    return _process_result(sub_ctx.command.invoke(sub_ctx))
  File "C:\Users\DELL\AppData\Roaming\Python\Python38\site-packages\click\core.py", line 1668, in invoke
    return _process_result(sub_ctx.command.invoke(sub_ctx))
  File "C:\Users\DELL\AppData\Roaming\Python\Python38\site-packages\click\core.py", line 1404, in invoke
    return ctx.invoke(self.callback, **ctx.params)
  File "C:\Users\DELL\AppData\Roaming\Python\Python38\site-packages\click\core.py", line 763, in invoke
    return __callback(*args, **kwargs)
  File "C:\Users\DELL\AppData\Roaming\Python\Python38\site-packages\openfl\interface\director.py", line 104, in start
    director_server.start()
  File "C:\Users\DELL\AppData\Roaming\Python\Python38\site-packages\openfl\transport\grpc\director_server.py", line 94, in start
    loop.run_until_complete(self._run_server())
  File "C:\Users\DELL\anaconda3\envs\myenv\lib\asyncio\base_events.py", line 603, in run_until_complete
    self.run_forever()
  File "C:\Users\DELL\anaconda3\envs\myenv\lib\asyncio\windows_events.py", line 316, in run_forever
    super().run_forever()
  File "C:\Users\DELL\anaconda3\envs\myenv\lib\asyncio\base_events.py", line 570, in run_forever
    self._run_once()
  File "C:\Users\DELL\anaconda3\envs\myenv\lib\asyncio\base_events.py", line 1859, in _run_once
    handle._run()
[19:43:03] INFO       File "C:\Users\DELL\anaconda3\envs\myenv\lib\asyncio\events.py", line 81, in _run
    self._context.run(self._callback, *self._args)
  File "C:\Users\DELL\AppData\Roaming\Python\Python38\site-packages\openfl\component\director\experiment.py", line 79, in start
    await self._run_aggregator_grpc_server(
  File "C:\Users\DELL\AppData\Roaming\Python\Python38\site-packages\openfl\component\director\experiment.py", line 114, in _run_aggregator_grpc_server
    logger.info('Starting Aggregator gRPC Server')
  File "C:\Users\DELL\anaconda3\envs\myenv\lib\logging\__init__.py", line 1446, in info
    self._log(INFO, msg, args, **kwargs)
  File "C:\Users\DELL\anaconda3\envs\myenv\lib\logging\__init__.py", line 1589, in _log
    self.handle(record)
  File "C:\Users\DELL\anaconda3\envs\myenv\lib\logging\__init__.py", line 1599, in handle
    self.callHandlers(record)
  File "C:\Users\DELL\anaconda3\envs\myenv\lib\logging\__init__.py", line 1661, in callHandlers
    hdlr.handle(record)
  File "C:\Users\DELL\anaconda3\envs\myenv\lib\logging\__init__.py", line 954, in handle
    self.emit(record)
  File "C:\Users\DELL\AppData\Roaming\Python\Python38\site-packages\rich\logging.py", line 172, in emit
    self.handleError(record)
Message: 'Starting Aggregator gRPC Server'
Arguments: ()
--- Logging error ---
Traceback (most recent call last):
  File "C:\Users\DELL\AppData\Roaming\Python\Python38\site-packages\rich\logging.py", line 170, in emit
    self.console.print(log_renderable)
  File "C:\Users\DELL\AppData\Roaming\Python\Python38\site-packages\rich\console.py", line 1720, in print
    self._buffer.extend(new_segments)
  File "C:\Users\DELL\AppData\Roaming\Python\Python38\site-packages\rich\console.py", line 864, in __exit__
    self._exit_buffer()
  File "C:\Users\DELL\AppData\Roaming\Python\Python38\site-packages\rich\console.py", line 822, in _exit_buffer
    self._check_buffer()
  File "C:\Users\DELL\AppData\Roaming\Python\Python38\site-packages\rich\console.py", line 2027, in _check_buffer
    legacy_windows_render(buffer, LegacyWindowsTerm(self.file))
  File "C:\Users\DELL\AppData\Roaming\Python\Python38\site-packages\rich\_windows_renderer.py", line 19, in legacy_windows_render
    term.write_text(text)
  File "C:\Users\DELL\AppData\Roaming\Python\Python38\site-packages\rich\_win32_console.py", line 403, in write_text
    self.write(text)
  File "C:\Users\DELL\anaconda3\envs\myenv\lib\encodings\cp1252.py", line 19, in encode
    return codecs.charmap_encode(input,self.errors,encoding_table)[0]
UnicodeEncodeError: 'charmap' codec can't encode character '\U0001f9ff' in position 0: character maps to <undefined>
Call stack:
  File "C:\Users\DELL\anaconda3\envs\myenv\lib\runpy.py", line 194, in _run_module_as_main
    return _run_code(code, main_globals, None,
  File "C:\Users\DELL\anaconda3\envs\myenv\lib\runpy.py", line 87, in _run_code
    exec(code, run_globals)
  File "C:\Users\DELL\anaconda3\envs\myenv\Scripts\fx.exe\__main__.py", line 7, in <module>
    sys.exit(entry())
  File "C:\Users\DELL\AppData\Roaming\Python\Python38\site-packages\openfl\interface\cli.py", line 212, in entry
    cli()
  File "C:\Users\DELL\AppData\Roaming\Python\Python38\site-packages\click\core.py", line 1137, in __call__
    return self.main(*args, **kwargs)
  File "C:\Users\DELL\AppData\Roaming\Python\Python38\site-packages\click\core.py", line 1062, in main
    rv = self.invoke(ctx)
  File "C:\Users\DELL\AppData\Roaming\Python\Python38\site-packages\click\core.py", line 1668, in invoke
    return _process_result(sub_ctx.command.invoke(sub_ctx))
  File "C:\Users\DELL\AppData\Roaming\Python\Python38\site-packages\click\core.py", line 1668, in invoke
    return _process_result(sub_ctx.command.invoke(sub_ctx))
  File "C:\Users\DELL\AppData\Roaming\Python\Python38\site-packages\click\core.py", line 1404, in invoke
    return ctx.invoke(self.callback, **ctx.params)
  File "C:\Users\DELL\AppData\Roaming\Python\Python38\site-packages\click\core.py", line 763, in invoke
    return __callback(*args, **kwargs)
  File "C:\Users\DELL\AppData\Roaming\Python\Python38\site-packages\openfl\interface\director.py", line 104, in start
    director_server.start()
  File "C:\Users\DELL\AppData\Roaming\Python\Python38\site-packages\openfl\transport\grpc\director_server.py", line 94, in start
    loop.run_until_complete(self._run_server())
  File "C:\Users\DELL\anaconda3\envs\myenv\lib\asyncio\base_events.py", line 603, in run_until_complete
    self.run_forever()
  File "C:\Users\DELL\anaconda3\envs\myenv\lib\asyncio\windows_events.py", line 316, in run_forever
    super().run_forever()
  File "C:\Users\DELL\anaconda3\envs\myenv\lib\asyncio\base_events.py", line 570, in run_forever
    self._run_once()
  File "C:\Users\DELL\anaconda3\envs\myenv\lib\asyncio\base_events.py", line 1859, in _run_once
    handle._run()
  File "C:\Users\DELL\anaconda3\envs\myenv\lib\asyncio\events.py", line 81, in _run
    self._context.run(self._callback, *self._args)
  File "C:\Users\DELL\AppData\Roaming\Python\Python38\site-packages\openfl\transport\grpc\director_server.py", line 208, in WaitExperiment
    logger.info(f'Experiment {experiment_name} was prepared')
  File "C:\Users\DELL\anaconda3\envs\myenv\lib\logging\__init__.py", line 1446, in info
    self._log(INFO, msg, args, **kwargs)
  File "C:\Users\DELL\anaconda3\envs\myenv\lib\logging\__init__.py", line 1589, in _log
    self.handle(record)
  File "C:\Users\DELL\anaconda3\envs\myenv\lib\logging\__init__.py", line 1599, in handle
    self.callHandlers(record)
  File "C:\Users\DELL\anaconda3\envs\myenv\lib\logging\__init__.py", line 1661, in callHandlers
    hdlr.handle(record)
  File "C:\Users\DELL\anaconda3\envs\myenv\lib\logging\__init__.py", line 954, in handle
    self.emit(record)
  File "C:\Users\DELL\AppData\Roaming\Python\Python38\site-packages\rich\logging.py", line 172, in emit
    self.handleError(record)
Message: 'Experiment AdaboostF_Fl_Chain was prepared'
Arguments: ()
--- Logging error ---
Traceback (most recent call last):
  File "C:\Users\DELL\AppData\Roaming\Python\Python38\site-packages\rich\logging.py", line 170, in emit
    self.console.print(log_renderable)
  File "C:\Users\DELL\AppData\Roaming\Python\Python38\site-packages\rich\console.py", line 1720, in print
    self._buffer.extend(new_segments)
  File "C:\Users\DELL\AppData\Roaming\Python\Python38\site-packages\rich\console.py", line 864, in __exit__
    self._exit_buffer()
  File "C:\Users\DELL\AppData\Roaming\Python\Python38\site-packages\rich\console.py", line 822, in _exit_buffer
    self._check_buffer()
  File "C:\Users\DELL\AppData\Roaming\Python\Python38\site-packages\rich\console.py", line 2027, in _check_buffer
    legacy_windows_render(buffer, LegacyWindowsTerm(self.file))
  File "C:\Users\DELL\AppData\Roaming\Python\Python38\site-packages\rich\_windows_renderer.py", line 19, in legacy_windows_render
    term.write_text(text)
  File "C:\Users\DELL\AppData\Roaming\Python\Python38\site-packages\rich\_win32_console.py", line 403, in write_text
    self.write(text)
  File "C:\Users\DELL\anaconda3\envs\myenv\lib\encodings\cp1252.py", line 19, in encode
    return codecs.charmap_encode(input,self.errors,encoding_table)[0]
UnicodeEncodeError: 'charmap' codec can't encode character '\U0001f9ff' in position 0: character maps to <undefined>
Call stack:
  File "C:\Users\DELL\anaconda3\envs\myenv\lib\runpy.py", line 194, in _run_module_as_main
    return _run_code(code, main_globals, None,
  File "C:\Users\DELL\anaconda3\envs\myenv\lib\runpy.py", line 87, in _run_code
    exec(code, run_globals)
  File "C:\Users\DELL\anaconda3\envs\myenv\Scripts\fx.exe\__main__.py", line 7, in <module>
    sys.exit(entry())
  File "C:\Users\DELL\AppData\Roaming\Python\Python38\site-packages\openfl\interface\cli.py", line 212, in entry
    cli()
  File "C:\Users\DELL\AppData\Roaming\Python\Python38\site-packages\click\core.py", line 1137, in __call__
    return self.main(*args, **kwargs)
[19:43:03] INFO     [19:43:03] INFO       File "C:\Users\DELL\AppData\Roaming\Python\Python38\site-packages\click\core.py", line 1062, in main
    rv = self.invoke(ctx)
  File "C:\Users\DELL\AppData\Roaming\Python\Python38\site-packages\click\core.py", line 1668, in invoke
    return _process_result(sub_ctx.command.invoke(sub_ctx))
  File "C:\Users\DELL\AppData\Roaming\Python\Python38\site-packages\click\core.py", line 1668, in invoke
    return _process_result(sub_ctx.command.invoke(sub_ctx))
  File "C:\Users\DELL\AppData\Roaming\Python\Python38\site-packages\click\core.py", line 1404, in invoke
    return ctx.invoke(self.callback, **ctx.params)
  File "C:\Users\DELL\AppData\Roaming\Python\Python38\site-packages\click\core.py", line 763, in invoke
    return __callback(*args, **kwargs)
  File "C:\Users\DELL\AppData\Roaming\Python\Python38\site-packages\openfl\interface\director.py", line 104, in start
    director_server.start()
  File "C:\Users\DELL\AppData\Roaming\Python\Python38\site-packages\openfl\transport\grpc\director_server.py", line 94, in start
    loop.run_until_complete(self._run_server())
  File "C:\Users\DELL\anaconda3\envs\myenv\lib\asyncio\base_events.py", line 603, in run_until_complete
    self.run_forever()
  File "C:\Users\DELL\anaconda3\envs\myenv\lib\asyncio\windows_events.py", line 316, in run_forever
    super().run_forever()
  File "C:\Users\DELL\anaconda3\envs\myenv\lib\asyncio\base_events.py", line 570, in run_forever
    self._run_once()
  File "C:\Users\DELL\anaconda3\envs\myenv\lib\asyncio\base_events.py", line 1859, in _run_once
    handle._run()
  File "C:\Users\DELL\anaconda3\envs\myenv\lib\asyncio\events.py", line 81, in _run
    self._context.run(self._callback, *self._args)
  File "C:\Users\DELL\AppData\Roaming\Python\Python38\site-packages\openfl\transport\grpc\director_server.py", line 254, in SetExperimentFailed
    logger.error(f'Collaborator {request.collaborator_name} was failed with error code:'
  File "C:\Users\DELL\anaconda3\envs\myenv\lib\logging\__init__.py", line 1475, in error
    self._log(ERROR, msg, args, **kwargs)
  File "C:\Users\DELL\anaconda3\envs\myenv\lib\logging\__init__.py", line 1589, in _log
    self.handle(record)
  File "C:\Users\DELL\anaconda3\envs\myenv\lib\logging\__init__.py", line 1599, in handle
    self.callHandlers(record)
  File "C:\Users\DELL\anaconda3\envs\myenv\lib\logging\__init__.py", line 1661, in callHandlers
    hdlr.handle(record)
  File "C:\Users\DELL\anaconda3\envs\myenv\lib\logging\__init__.py", line 954, in handle
    self.emit(record)
  File "C:\Users\DELL\AppData\Roaming\Python\Python38\site-packages\rich\logging.py", line 172, in emit
    self.handleError(record)
Message: 'Collaborator envoy_1 was failed with error code: 1, error_description: Traceback (most recent call last):\n  File "C:\\Users\\DELL\\AppData\\Roaming\\Python\\Python38\\site-packages\\openfl\\component\\envoy\\envoy.py", line 91, in run\n    self._run_collaborator()\n  File "C:\\Users\\DELL\\AppData\\Roaming\\Python\\Python38\\site-packages\\openfl\\component\\envoy\\envoy.py", line 164, in _run_collaborator\n    col.run()\n  File "C:\\Users\\DELL\\AppData\\Roaming\\Python\\Python38\\site-packages\\openfl\\component\\collaborator\\collaborator.py", line 174, in run\n    self.do_task(task, round_number)\n  File "C:\\Users\\DELL\\AppData\\Roaming\\Python\\Python38\\site-packages\\openfl\\component\\collaborator\\collaborator.py", line 300, in do_task\n    global_output_tensor_dict, local_output_tensor_dict, optional = func(\n  File "C:\\Users\\DELL\\AppData\\Roaming\\Python\\Python38\\site-packages\\openfl\\federated\\task\\runner_generic.py", line 47, in collaborator_adapted_task\n    loader = self.data_loader.get_train_loader()\n  File "C:\\Users\\DELL\\Downloads\\FederatedLearning\\OpenFL-extended\\openfl-tutorials\\boosting-examples\\CoxPH\\AdaBoostF_FL_Chain\\envoy_1/envoy_1_AdaboostF_Fl_Chain\\Fl_Chain_Dataset.py", line 35, in get_train_loader\n  File "C:\\Users\\DELL\\Downloads\\FederatedLearning\\OpenFL-extended\\openfl-tutorials\\boosting-examples\\CoxPH\\AdaBoostF_FL_Chain\\envoy_1\\Fl_Chain_shard_descriptor.py", line 44, in get_data\n    return self.x, self.y\nAttributeError: \'Fl_Chain_ShardDataset\' object has no attribute \'y\'\nStopping experiment.'
Arguments: ()
--- Logging error ---
Traceback (most recent call last):
  File "C:\Users\DELL\AppData\Roaming\Python\Python38\site-packages\rich\logging.py", line 170, in emit
    self.console.print(log_renderable)
  File "C:\Users\DELL\AppData\Roaming\Python\Python38\site-packages\rich\console.py", line 1720, in print
    self._buffer.extend(new_segments)
  File "C:\Users\DELL\AppData\Roaming\Python\Python38\site-packages\rich\console.py", line 864, in __exit__
    self._exit_buffer()
  File "C:\Users\DELL\AppData\Roaming\Python\Python38\site-packages\rich\console.py", line 822, in _exit_buffer
    self._check_buffer()
  File "C:\Users\DELL\AppData\Roaming\Python\Python38\site-packages\rich\console.py", line 2027, in _check_buffer
    legacy_windows_render(buffer, LegacyWindowsTerm(self.file))
  File "C:\Users\DELL\AppData\Roaming\Python\Python38\site-packages\rich\_windows_renderer.py", line 19, in legacy_windows_render
    term.write_text(text)
  File "C:\Users\DELL\AppData\Roaming\Python\Python38\site-packages\rich\_win32_console.py", line 403, in write_text
    self.write(text)
  File "C:\Users\DELL\anaconda3\envs\myenv\lib\encodings\cp1252.py", line 19, in encode
    return codecs.charmap_encode(input,self.errors,encoding_table)[0]
UnicodeEncodeError: 'charmap' codec can't encode character '\U0001f9ff' in position 0: character maps to <undefined>
Call stack:
  File "C:\Users\DELL\anaconda3\envs\myenv\lib\runpy.py", line 194, in _run_module_as_main
    return _run_code(code, main_globals, None,
  File "C:\Users\DELL\anaconda3\envs\myenv\lib\runpy.py", line 87, in _run_code
    exec(code, run_globals)
  File "C:\Users\DELL\anaconda3\envs\myenv\Scripts\fx.exe\__main__.py", line 7, in <module>
    sys.exit(entry())
  File "C:\Users\DELL\AppData\Roaming\Python\Python38\site-packages\openfl\interface\cli.py", line 212, in entry
    cli()
  File "C:\Users\DELL\AppData\Roaming\Python\Python38\site-packages\click\core.py", line 1137, in __call__
    return self.main(*args, **kwargs)
  File "C:\Users\DELL\AppData\Roaming\Python\Python38\site-packages\click\core.py", line 1062, in main
    rv = self.invoke(ctx)
  File "C:\Users\DELL\AppData\Roaming\Python\Python38\site-packages\click\core.py", line 1668, in invoke
    return _process_result(sub_ctx.command.invoke(sub_ctx))
  File "C:\Users\DELL\AppData\Roaming\Python\Python38\site-packages\click\core.py", line 1668, in invoke
    return _process_result(sub_ctx.command.invoke(sub_ctx))
  File "C:\Users\DELL\AppData\Roaming\Python\Python38\site-packages\click\core.py", line 1404, in invoke
    return ctx.invoke(self.callback, **ctx.params)
  File "C:\Users\DELL\AppData\Roaming\Python\Python38\site-packages\click\core.py", line 763, in invoke
    return __callback(*args, **kwargs)
  File "C:\Users\DELL\AppData\Roaming\Python\Python38\site-packages\openfl\interface\director.py", line 104, in start
    director_server.start()
  File "C:\Users\DELL\AppData\Roaming\Python\Python38\site-packages\openfl\transport\grpc\director_server.py", line 94, in start
    loop.run_until_complete(self._run_server())
  File "C:\Users\DELL\anaconda3\envs\myenv\lib\asyncio\base_events.py", line 603, in run_until_complete
    self.run_forever()
  File "C:\Users\DELL\anaconda3\envs\myenv\lib\asyncio\windows_events.py", line 316, in run_forever
    super().run_forever()
  File "C:\Users\DELL\anaconda3\envs\myenv\lib\asyncio\base_events.py", line 570, in run_forever
    self._run_once()
  File "C:\Users\DELL\anaconda3\envs\myenv\lib\asyncio\base_events.py", line 1859, in _run_once
    handle._run()
  File "C:\Users\DELL\anaconda3\envs\myenv\lib\asyncio\events.py", line 81, in _run
    self._context.run(self._callback, *self._args)
forrtl: error (200): program aborting due to window-CLOSE event
Image              PC                Routine            Line        Source             
libifcoremd.dll    00007FFB4BACDF54  Unknown               Unknown  Unknown
KERNELBASE.dll     00007FFB994829E3  Unknown               Unknown  Unknown
KERNEL32.DLL       00007FFB99E17614  Unknown               Unknown  Unknown
ntdll.dll          00007FFB9B9426B1  Unknown               Unknown  Unknown
